2025-05-06 04:58:09,850 - flask-app - ERROR - [debt_routes.py:16] - Cache operation failed: 'Flask' object has no attribute 'cache'
2025-05-06 14:40:39,067 - flask-app - INFO - [__init__.py:22] - Starting Flask application...
2025-05-06 15:02:37,529 - flask-app - INFO - [__init__.py:22] - Starting Flask application...
2025-05-06 16:09:07,404 - flask-app - INFO - [__init__.py:22] - Starting Flask application...
2025-05-06 16:09:10,803 - app - ERROR - [__init__.py:47] - Unhandled exception: 404 Not Found: The requested URL was not found on the server. If you entered the URL manually please check your spelling and try again.
Traceback (most recent call last):
  File "/Users/guggarisathvik/groundnut_mill/.venv/lib/python3.9/site-packages/flask/app.py", line 917, in full_dispatch_request
    rv = self.dispatch_request()
  File "/Users/guggarisathvik/groundnut_mill/.venv/lib/python3.9/site-packages/flask/app.py", line 902, in dispatch_request
    return self.ensure_sync(self.view_functions[rule.endpoint])(**view_args)  # type: ignore[no-any-return]
  File "/Users/guggarisathvik/groundnut_mill/.venv/lib/python3.9/site-packages/flask/app.py", line 278, in <lambda>
    view_func=lambda **kw: self_ref().send_static_file(**kw),  # type: ignore # noqa: B950
  File "/Users/guggarisathvik/groundnut_mill/.venv/lib/python3.9/site-packages/flask/app.py", line 326, in send_static_file
    return send_from_directory(
  File "/Users/guggarisathvik/groundnut_mill/.venv/lib/python3.9/site-packages/flask/helpers.py", line 565, in send_from_directory
    return werkzeug.utils.send_from_directory(  # type: ignore[return-value]
  File "/Users/guggarisathvik/groundnut_mill/.venv/lib/python3.9/site-packages/werkzeug/utils.py", line 575, in send_from_directory
    raise NotFound()
werkzeug.exceptions.NotFound: 404 Not Found: The requested URL was not found on the server. If you entered the URL manually please check your spelling and try again.
2025-05-06 16:09:10,916 - app - ERROR - [__init__.py:47] - Unhandled exception: 404 Not Found: The requested URL was not found on the server. If you entered the URL manually please check your spelling and try again.
Traceback (most recent call last):
  File "/Users/guggarisathvik/groundnut_mill/.venv/lib/python3.9/site-packages/flask/app.py", line 917, in full_dispatch_request
    rv = self.dispatch_request()
  File "/Users/guggarisathvik/groundnut_mill/.venv/lib/python3.9/site-packages/flask/app.py", line 902, in dispatch_request
    return self.ensure_sync(self.view_functions[rule.endpoint])(**view_args)  # type: ignore[no-any-return]
  File "/Users/guggarisathvik/groundnut_mill/.venv/lib/python3.9/site-packages/flask/app.py", line 278, in <lambda>
    view_func=lambda **kw: self_ref().send_static_file(**kw),  # type: ignore # noqa: B950
  File "/Users/guggarisathvik/groundnut_mill/.venv/lib/python3.9/site-packages/flask/app.py", line 326, in send_static_file
    return send_from_directory(
  File "/Users/guggarisathvik/groundnut_mill/.venv/lib/python3.9/site-packages/flask/helpers.py", line 565, in send_from_directory
    return werkzeug.utils.send_from_directory(  # type: ignore[return-value]
  File "/Users/guggarisathvik/groundnut_mill/.venv/lib/python3.9/site-packages/werkzeug/utils.py", line 575, in send_from_directory
    raise NotFound()
werkzeug.exceptions.NotFound: 404 Not Found: The requested URL was not found on the server. If you entered the URL manually please check your spelling and try again.
2025-05-06 16:09:12,358 - app - ERROR - [__init__.py:47] - Unhandled exception: 404 Not Found: The requested URL was not found on the server. If you entered the URL manually please check your spelling and try again.
Traceback (most recent call last):
  File "/Users/guggarisathvik/groundnut_mill/.venv/lib/python3.9/site-packages/flask/app.py", line 917, in full_dispatch_request
    rv = self.dispatch_request()
  File "/Users/guggarisathvik/groundnut_mill/.venv/lib/python3.9/site-packages/flask/app.py", line 902, in dispatch_request
    return self.ensure_sync(self.view_functions[rule.endpoint])(**view_args)  # type: ignore[no-any-return]
  File "/Users/guggarisathvik/groundnut_mill/.venv/lib/python3.9/site-packages/flask/app.py", line 278, in <lambda>
    view_func=lambda **kw: self_ref().send_static_file(**kw),  # type: ignore # noqa: B950
  File "/Users/guggarisathvik/groundnut_mill/.venv/lib/python3.9/site-packages/flask/app.py", line 326, in send_static_file
    return send_from_directory(
  File "/Users/guggarisathvik/groundnut_mill/.venv/lib/python3.9/site-packages/flask/helpers.py", line 565, in send_from_directory
    return werkzeug.utils.send_from_directory(  # type: ignore[return-value]
  File "/Users/guggarisathvik/groundnut_mill/.venv/lib/python3.9/site-packages/werkzeug/utils.py", line 575, in send_from_directory
    raise NotFound()
werkzeug.exceptions.NotFound: 404 Not Found: The requested URL was not found on the server. If you entered the URL manually please check your spelling and try again.
2025-05-06 16:09:12,405 - app - ERROR - [__init__.py:47] - Unhandled exception: 404 Not Found: The requested URL was not found on the server. If you entered the URL manually please check your spelling and try again.
Traceback (most recent call last):
  File "/Users/guggarisathvik/groundnut_mill/.venv/lib/python3.9/site-packages/flask/app.py", line 917, in full_dispatch_request
    rv = self.dispatch_request()
  File "/Users/guggarisathvik/groundnut_mill/.venv/lib/python3.9/site-packages/flask/app.py", line 902, in dispatch_request
    return self.ensure_sync(self.view_functions[rule.endpoint])(**view_args)  # type: ignore[no-any-return]
  File "/Users/guggarisathvik/groundnut_mill/.venv/lib/python3.9/site-packages/flask/app.py", line 278, in <lambda>
    view_func=lambda **kw: self_ref().send_static_file(**kw),  # type: ignore # noqa: B950
  File "/Users/guggarisathvik/groundnut_mill/.venv/lib/python3.9/site-packages/flask/app.py", line 326, in send_static_file
    return send_from_directory(
  File "/Users/guggarisathvik/groundnut_mill/.venv/lib/python3.9/site-packages/flask/helpers.py", line 565, in send_from_directory
    return werkzeug.utils.send_from_directory(  # type: ignore[return-value]
  File "/Users/guggarisathvik/groundnut_mill/.venv/lib/python3.9/site-packages/werkzeug/utils.py", line 575, in send_from_directory
    raise NotFound()
werkzeug.exceptions.NotFound: 404 Not Found: The requested URL was not found on the server. If you entered the URL manually please check your spelling and try again.
2025-05-06 16:09:13,807 - app - ERROR - [__init__.py:47] - Unhandled exception: 404 Not Found: The requested URL was not found on the server. If you entered the URL manually please check your spelling and try again.
Traceback (most recent call last):
  File "/Users/guggarisathvik/groundnut_mill/.venv/lib/python3.9/site-packages/flask/app.py", line 917, in full_dispatch_request
    rv = self.dispatch_request()
  File "/Users/guggarisathvik/groundnut_mill/.venv/lib/python3.9/site-packages/flask/app.py", line 902, in dispatch_request
    return self.ensure_sync(self.view_functions[rule.endpoint])(**view_args)  # type: ignore[no-any-return]
  File "/Users/guggarisathvik/groundnut_mill/.venv/lib/python3.9/site-packages/flask/app.py", line 278, in <lambda>
    view_func=lambda **kw: self_ref().send_static_file(**kw),  # type: ignore # noqa: B950
  File "/Users/guggarisathvik/groundnut_mill/.venv/lib/python3.9/site-packages/flask/app.py", line 326, in send_static_file
    return send_from_directory(
  File "/Users/guggarisathvik/groundnut_mill/.venv/lib/python3.9/site-packages/flask/helpers.py", line 565, in send_from_directory
    return werkzeug.utils.send_from_directory(  # type: ignore[return-value]
  File "/Users/guggarisathvik/groundnut_mill/.venv/lib/python3.9/site-packages/werkzeug/utils.py", line 575, in send_from_directory
    raise NotFound()
werkzeug.exceptions.NotFound: 404 Not Found: The requested URL was not found on the server. If you entered the URL manually please check your spelling and try again.
2025-05-06 16:09:14,188 - app - ERROR - [__init__.py:47] - Unhandled exception: 404 Not Found: The requested URL was not found on the server. If you entered the URL manually please check your spelling and try again.
Traceback (most recent call last):
  File "/Users/guggarisathvik/groundnut_mill/.venv/lib/python3.9/site-packages/flask/app.py", line 917, in full_dispatch_request
    rv = self.dispatch_request()
  File "/Users/guggarisathvik/groundnut_mill/.venv/lib/python3.9/site-packages/flask/app.py", line 902, in dispatch_request
    return self.ensure_sync(self.view_functions[rule.endpoint])(**view_args)  # type: ignore[no-any-return]
  File "/Users/guggarisathvik/groundnut_mill/.venv/lib/python3.9/site-packages/flask/app.py", line 278, in <lambda>
    view_func=lambda **kw: self_ref().send_static_file(**kw),  # type: ignore # noqa: B950
  File "/Users/guggarisathvik/groundnut_mill/.venv/lib/python3.9/site-packages/flask/app.py", line 326, in send_static_file
    return send_from_directory(
  File "/Users/guggarisathvik/groundnut_mill/.venv/lib/python3.9/site-packages/flask/helpers.py", line 565, in send_from_directory
    return werkzeug.utils.send_from_directory(  # type: ignore[return-value]
  File "/Users/guggarisathvik/groundnut_mill/.venv/lib/python3.9/site-packages/werkzeug/utils.py", line 575, in send_from_directory
    raise NotFound()
werkzeug.exceptions.NotFound: 404 Not Found: The requested URL was not found on the server. If you entered the URL manually please check your spelling and try again.
2025-05-06 16:09:14,671 - app - ERROR - [__init__.py:47] - Unhandled exception: 404 Not Found: The requested URL was not found on the server. If you entered the URL manually please check your spelling and try again.
Traceback (most recent call last):
  File "/Users/guggarisathvik/groundnut_mill/.venv/lib/python3.9/site-packages/flask/app.py", line 917, in full_dispatch_request
    rv = self.dispatch_request()
  File "/Users/guggarisathvik/groundnut_mill/.venv/lib/python3.9/site-packages/flask/app.py", line 902, in dispatch_request
    return self.ensure_sync(self.view_functions[rule.endpoint])(**view_args)  # type: ignore[no-any-return]
  File "/Users/guggarisathvik/groundnut_mill/.venv/lib/python3.9/site-packages/flask/app.py", line 278, in <lambda>
    view_func=lambda **kw: self_ref().send_static_file(**kw),  # type: ignore # noqa: B950
  File "/Users/guggarisathvik/groundnut_mill/.venv/lib/python3.9/site-packages/flask/app.py", line 326, in send_static_file
    return send_from_directory(
  File "/Users/guggarisathvik/groundnut_mill/.venv/lib/python3.9/site-packages/flask/helpers.py", line 565, in send_from_directory
    return werkzeug.utils.send_from_directory(  # type: ignore[return-value]
  File "/Users/guggarisathvik/groundnut_mill/.venv/lib/python3.9/site-packages/werkzeug/utils.py", line 575, in send_from_directory
    raise NotFound()
werkzeug.exceptions.NotFound: 404 Not Found: The requested URL was not found on the server. If you entered the URL manually please check your spelling and try again.
2025-05-06 16:09:14,722 - app - ERROR - [__init__.py:47] - Unhandled exception: 404 Not Found: The requested URL was not found on the server. If you entered the URL manually please check your spelling and try again.
Traceback (most recent call last):
  File "/Users/guggarisathvik/groundnut_mill/.venv/lib/python3.9/site-packages/flask/app.py", line 917, in full_dispatch_request
    rv = self.dispatch_request()
  File "/Users/guggarisathvik/groundnut_mill/.venv/lib/python3.9/site-packages/flask/app.py", line 902, in dispatch_request
    return self.ensure_sync(self.view_functions[rule.endpoint])(**view_args)  # type: ignore[no-any-return]
  File "/Users/guggarisathvik/groundnut_mill/.venv/lib/python3.9/site-packages/flask/app.py", line 278, in <lambda>
    view_func=lambda **kw: self_ref().send_static_file(**kw),  # type: ignore # noqa: B950
  File "/Users/guggarisathvik/groundnut_mill/.venv/lib/python3.9/site-packages/flask/app.py", line 326, in send_static_file
    return send_from_directory(
  File "/Users/guggarisathvik/groundnut_mill/.venv/lib/python3.9/site-packages/flask/helpers.py", line 565, in send_from_directory
    return werkzeug.utils.send_from_directory(  # type: ignore[return-value]
  File "/Users/guggarisathvik/groundnut_mill/.venv/lib/python3.9/site-packages/werkzeug/utils.py", line 575, in send_from_directory
    raise NotFound()
werkzeug.exceptions.NotFound: 404 Not Found: The requested URL was not found on the server. If you entered the URL manually please check your spelling and try again.
2025-05-06 16:09:15,715 - app - ERROR - [__init__.py:47] - Unhandled exception: 404 Not Found: The requested URL was not found on the server. If you entered the URL manually please check your spelling and try again.
Traceback (most recent call last):
  File "/Users/guggarisathvik/groundnut_mill/.venv/lib/python3.9/site-packages/flask/app.py", line 917, in full_dispatch_request
    rv = self.dispatch_request()
  File "/Users/guggarisathvik/groundnut_mill/.venv/lib/python3.9/site-packages/flask/app.py", line 902, in dispatch_request
    return self.ensure_sync(self.view_functions[rule.endpoint])(**view_args)  # type: ignore[no-any-return]
  File "/Users/guggarisathvik/groundnut_mill/.venv/lib/python3.9/site-packages/flask/app.py", line 278, in <lambda>
    view_func=lambda **kw: self_ref().send_static_file(**kw),  # type: ignore # noqa: B950
  File "/Users/guggarisathvik/groundnut_mill/.venv/lib/python3.9/site-packages/flask/app.py", line 326, in send_static_file
    return send_from_directory(
  File "/Users/guggarisathvik/groundnut_mill/.venv/lib/python3.9/site-packages/flask/helpers.py", line 565, in send_from_directory
    return werkzeug.utils.send_from_directory(  # type: ignore[return-value]
  File "/Users/guggarisathvik/groundnut_mill/.venv/lib/python3.9/site-packages/werkzeug/utils.py", line 575, in send_from_directory
    raise NotFound()
werkzeug.exceptions.NotFound: 404 Not Found: The requested URL was not found on the server. If you entered the URL manually please check your spelling and try again.
2025-05-06 16:09:15,771 - app - ERROR - [__init__.py:47] - Unhandled exception: 404 Not Found: The requested URL was not found on the server. If you entered the URL manually please check your spelling and try again.
Traceback (most recent call last):
  File "/Users/guggarisathvik/groundnut_mill/.venv/lib/python3.9/site-packages/flask/app.py", line 917, in full_dispatch_request
    rv = self.dispatch_request()
  File "/Users/guggarisathvik/groundnut_mill/.venv/lib/python3.9/site-packages/flask/app.py", line 902, in dispatch_request
    return self.ensure_sync(self.view_functions[rule.endpoint])(**view_args)  # type: ignore[no-any-return]
  File "/Users/guggarisathvik/groundnut_mill/.venv/lib/python3.9/site-packages/flask/app.py", line 278, in <lambda>
    view_func=lambda **kw: self_ref().send_static_file(**kw),  # type: ignore # noqa: B950
  File "/Users/guggarisathvik/groundnut_mill/.venv/lib/python3.9/site-packages/flask/app.py", line 326, in send_static_file
    return send_from_directory(
  File "/Users/guggarisathvik/groundnut_mill/.venv/lib/python3.9/site-packages/flask/helpers.py", line 565, in send_from_directory
    return werkzeug.utils.send_from_directory(  # type: ignore[return-value]
  File "/Users/guggarisathvik/groundnut_mill/.venv/lib/python3.9/site-packages/werkzeug/utils.py", line 575, in send_from_directory
    raise NotFound()
werkzeug.exceptions.NotFound: 404 Not Found: The requested URL was not found on the server. If you entered the URL manually please check your spelling and try again.
2025-05-06 16:09:16,549 - app - ERROR - [__init__.py:47] - Unhandled exception: 404 Not Found: The requested URL was not found on the server. If you entered the URL manually please check your spelling and try again.
Traceback (most recent call last):
  File "/Users/guggarisathvik/groundnut_mill/.venv/lib/python3.9/site-packages/flask/app.py", line 917, in full_dispatch_request
    rv = self.dispatch_request()
  File "/Users/guggarisathvik/groundnut_mill/.venv/lib/python3.9/site-packages/flask/app.py", line 902, in dispatch_request
    return self.ensure_sync(self.view_functions[rule.endpoint])(**view_args)  # type: ignore[no-any-return]
  File "/Users/guggarisathvik/groundnut_mill/.venv/lib/python3.9/site-packages/flask/app.py", line 278, in <lambda>
    view_func=lambda **kw: self_ref().send_static_file(**kw),  # type: ignore # noqa: B950
  File "/Users/guggarisathvik/groundnut_mill/.venv/lib/python3.9/site-packages/flask/app.py", line 326, in send_static_file
    return send_from_directory(
  File "/Users/guggarisathvik/groundnut_mill/.venv/lib/python3.9/site-packages/flask/helpers.py", line 565, in send_from_directory
    return werkzeug.utils.send_from_directory(  # type: ignore[return-value]
  File "/Users/guggarisathvik/groundnut_mill/.venv/lib/python3.9/site-packages/werkzeug/utils.py", line 575, in send_from_directory
    raise NotFound()
werkzeug.exceptions.NotFound: 404 Not Found: The requested URL was not found on the server. If you entered the URL manually please check your spelling and try again.
2025-05-06 16:09:16,596 - app - ERROR - [__init__.py:47] - Unhandled exception: 404 Not Found: The requested URL was not found on the server. If you entered the URL manually please check your spelling and try again.
Traceback (most recent call last):
  File "/Users/guggarisathvik/groundnut_mill/.venv/lib/python3.9/site-packages/flask/app.py", line 917, in full_dispatch_request
    rv = self.dispatch_request()
  File "/Users/guggarisathvik/groundnut_mill/.venv/lib/python3.9/site-packages/flask/app.py", line 902, in dispatch_request
    return self.ensure_sync(self.view_functions[rule.endpoint])(**view_args)  # type: ignore[no-any-return]
  File "/Users/guggarisathvik/groundnut_mill/.venv/lib/python3.9/site-packages/flask/app.py", line 278, in <lambda>
    view_func=lambda **kw: self_ref().send_static_file(**kw),  # type: ignore # noqa: B950
  File "/Users/guggarisathvik/groundnut_mill/.venv/lib/python3.9/site-packages/flask/app.py", line 326, in send_static_file
    return send_from_directory(
  File "/Users/guggarisathvik/groundnut_mill/.venv/lib/python3.9/site-packages/flask/helpers.py", line 565, in send_from_directory
    return werkzeug.utils.send_from_directory(  # type: ignore[return-value]
  File "/Users/guggarisathvik/groundnut_mill/.venv/lib/python3.9/site-packages/werkzeug/utils.py", line 575, in send_from_directory
    raise NotFound()
werkzeug.exceptions.NotFound: 404 Not Found: The requested URL was not found on the server. If you entered the URL manually please check your spelling and try again.
2025-05-06 16:09:17,279 - app - ERROR - [debt_routes.py:16] - Cache operation failed: 'Flask' object has no attribute 'cache'
2025-05-06 16:09:17,295 - app - ERROR - [__init__.py:47] - Unhandled exception: 404 Not Found: The requested URL was not found on the server. If you entered the URL manually please check your spelling and try again.
Traceback (most recent call last):
  File "/Users/guggarisathvik/groundnut_mill/.venv/lib/python3.9/site-packages/flask/app.py", line 917, in full_dispatch_request
    rv = self.dispatch_request()
  File "/Users/guggarisathvik/groundnut_mill/.venv/lib/python3.9/site-packages/flask/app.py", line 902, in dispatch_request
    return self.ensure_sync(self.view_functions[rule.endpoint])(**view_args)  # type: ignore[no-any-return]
  File "/Users/guggarisathvik/groundnut_mill/.venv/lib/python3.9/site-packages/flask/app.py", line 278, in <lambda>
    view_func=lambda **kw: self_ref().send_static_file(**kw),  # type: ignore # noqa: B950
  File "/Users/guggarisathvik/groundnut_mill/.venv/lib/python3.9/site-packages/flask/app.py", line 326, in send_static_file
    return send_from_directory(
  File "/Users/guggarisathvik/groundnut_mill/.venv/lib/python3.9/site-packages/flask/helpers.py", line 565, in send_from_directory
    return werkzeug.utils.send_from_directory(  # type: ignore[return-value]
  File "/Users/guggarisathvik/groundnut_mill/.venv/lib/python3.9/site-packages/werkzeug/utils.py", line 575, in send_from_directory
    raise NotFound()
werkzeug.exceptions.NotFound: 404 Not Found: The requested URL was not found on the server. If you entered the URL manually please check your spelling and try again.
2025-05-06 16:09:17,344 - app - ERROR - [__init__.py:47] - Unhandled exception: 404 Not Found: The requested URL was not found on the server. If you entered the URL manually please check your spelling and try again.
Traceback (most recent call last):
  File "/Users/guggarisathvik/groundnut_mill/.venv/lib/python3.9/site-packages/flask/app.py", line 917, in full_dispatch_request
    rv = self.dispatch_request()
  File "/Users/guggarisathvik/groundnut_mill/.venv/lib/python3.9/site-packages/flask/app.py", line 902, in dispatch_request
    return self.ensure_sync(self.view_functions[rule.endpoint])(**view_args)  # type: ignore[no-any-return]
  File "/Users/guggarisathvik/groundnut_mill/.venv/lib/python3.9/site-packages/flask/app.py", line 278, in <lambda>
    view_func=lambda **kw: self_ref().send_static_file(**kw),  # type: ignore # noqa: B950
  File "/Users/guggarisathvik/groundnut_mill/.venv/lib/python3.9/site-packages/flask/app.py", line 326, in send_static_file
    return send_from_directory(
  File "/Users/guggarisathvik/groundnut_mill/.venv/lib/python3.9/site-packages/flask/helpers.py", line 565, in send_from_directory
    return werkzeug.utils.send_from_directory(  # type: ignore[return-value]
  File "/Users/guggarisathvik/groundnut_mill/.venv/lib/python3.9/site-packages/werkzeug/utils.py", line 575, in send_from_directory
    raise NotFound()
werkzeug.exceptions.NotFound: 404 Not Found: The requested URL was not found on the server. If you entered the URL manually please check your spelling and try again.
2025-05-06 16:09:18,291 - app - ERROR - [sale_routes.py:26] - Error retrieving sales: type object 'Sale' has no attribute 'created_at'
2025-05-06 16:09:18,301 - app - ERROR - [__init__.py:47] - Unhandled exception: 404 Not Found: The requested URL was not found on the server. If you entered the URL manually please check your spelling and try again.
Traceback (most recent call last):
  File "/Users/guggarisathvik/groundnut_mill/.venv/lib/python3.9/site-packages/flask/app.py", line 917, in full_dispatch_request
    rv = self.dispatch_request()
  File "/Users/guggarisathvik/groundnut_mill/.venv/lib/python3.9/site-packages/flask/app.py", line 902, in dispatch_request
    return self.ensure_sync(self.view_functions[rule.endpoint])(**view_args)  # type: ignore[no-any-return]
  File "/Users/guggarisathvik/groundnut_mill/.venv/lib/python3.9/site-packages/flask/app.py", line 278, in <lambda>
    view_func=lambda **kw: self_ref().send_static_file(**kw),  # type: ignore # noqa: B950
  File "/Users/guggarisathvik/groundnut_mill/.venv/lib/python3.9/site-packages/flask/app.py", line 326, in send_static_file
    return send_from_directory(
  File "/Users/guggarisathvik/groundnut_mill/.venv/lib/python3.9/site-packages/flask/helpers.py", line 565, in send_from_directory
    return werkzeug.utils.send_from_directory(  # type: ignore[return-value]
  File "/Users/guggarisathvik/groundnut_mill/.venv/lib/python3.9/site-packages/werkzeug/utils.py", line 575, in send_from_directory
    raise NotFound()
werkzeug.exceptions.NotFound: 404 Not Found: The requested URL was not found on the server. If you entered the URL manually please check your spelling and try again.
2025-05-06 16:09:18,379 - app - ERROR - [__init__.py:47] - Unhandled exception: 404 Not Found: The requested URL was not found on the server. If you entered the URL manually please check your spelling and try again.
Traceback (most recent call last):
  File "/Users/guggarisathvik/groundnut_mill/.venv/lib/python3.9/site-packages/flask/app.py", line 917, in full_dispatch_request
    rv = self.dispatch_request()
  File "/Users/guggarisathvik/groundnut_mill/.venv/lib/python3.9/site-packages/flask/app.py", line 902, in dispatch_request
    return self.ensure_sync(self.view_functions[rule.endpoint])(**view_args)  # type: ignore[no-any-return]
  File "/Users/guggarisathvik/groundnut_mill/.venv/lib/python3.9/site-packages/flask/app.py", line 278, in <lambda>
    view_func=lambda **kw: self_ref().send_static_file(**kw),  # type: ignore # noqa: B950
  File "/Users/guggarisathvik/groundnut_mill/.venv/lib/python3.9/site-packages/flask/app.py", line 326, in send_static_file
    return send_from_directory(
  File "/Users/guggarisathvik/groundnut_mill/.venv/lib/python3.9/site-packages/flask/helpers.py", line 565, in send_from_directory
    return werkzeug.utils.send_from_directory(  # type: ignore[return-value]
  File "/Users/guggarisathvik/groundnut_mill/.venv/lib/python3.9/site-packages/werkzeug/utils.py", line 575, in send_from_directory
    raise NotFound()
werkzeug.exceptions.NotFound: 404 Not Found: The requested URL was not found on the server. If you entered the URL manually please check your spelling and try again.
2025-05-06 16:09:19,703 - app - ERROR - [__init__.py:47] - Unhandled exception: 404 Not Found: The requested URL was not found on the server. If you entered the URL manually please check your spelling and try again.
Traceback (most recent call last):
  File "/Users/guggarisathvik/groundnut_mill/.venv/lib/python3.9/site-packages/flask/app.py", line 917, in full_dispatch_request
    rv = self.dispatch_request()
  File "/Users/guggarisathvik/groundnut_mill/.venv/lib/python3.9/site-packages/flask/app.py", line 902, in dispatch_request
    return self.ensure_sync(self.view_functions[rule.endpoint])(**view_args)  # type: ignore[no-any-return]
  File "/Users/guggarisathvik/groundnut_mill/.venv/lib/python3.9/site-packages/flask/app.py", line 278, in <lambda>
    view_func=lambda **kw: self_ref().send_static_file(**kw),  # type: ignore # noqa: B950
  File "/Users/guggarisathvik/groundnut_mill/.venv/lib/python3.9/site-packages/flask/app.py", line 326, in send_static_file
    return send_from_directory(
  File "/Users/guggarisathvik/groundnut_mill/.venv/lib/python3.9/site-packages/flask/helpers.py", line 565, in send_from_directory
    return werkzeug.utils.send_from_directory(  # type: ignore[return-value]
  File "/Users/guggarisathvik/groundnut_mill/.venv/lib/python3.9/site-packages/werkzeug/utils.py", line 575, in send_from_directory
    raise NotFound()
werkzeug.exceptions.NotFound: 404 Not Found: The requested URL was not found on the server. If you entered the URL manually please check your spelling and try again.
2025-05-06 16:09:19,753 - app - ERROR - [__init__.py:47] - Unhandled exception: 404 Not Found: The requested URL was not found on the server. If you entered the URL manually please check your spelling and try again.
Traceback (most recent call last):
  File "/Users/guggarisathvik/groundnut_mill/.venv/lib/python3.9/site-packages/flask/app.py", line 917, in full_dispatch_request
    rv = self.dispatch_request()
  File "/Users/guggarisathvik/groundnut_mill/.venv/lib/python3.9/site-packages/flask/app.py", line 902, in dispatch_request
    return self.ensure_sync(self.view_functions[rule.endpoint])(**view_args)  # type: ignore[no-any-return]
  File "/Users/guggarisathvik/groundnut_mill/.venv/lib/python3.9/site-packages/flask/app.py", line 278, in <lambda>
    view_func=lambda **kw: self_ref().send_static_file(**kw),  # type: ignore # noqa: B950
  File "/Users/guggarisathvik/groundnut_mill/.venv/lib/python3.9/site-packages/flask/app.py", line 326, in send_static_file
    return send_from_directory(
  File "/Users/guggarisathvik/groundnut_mill/.venv/lib/python3.9/site-packages/flask/helpers.py", line 565, in send_from_directory
    return werkzeug.utils.send_from_directory(  # type: ignore[return-value]
  File "/Users/guggarisathvik/groundnut_mill/.venv/lib/python3.9/site-packages/werkzeug/utils.py", line 575, in send_from_directory
    raise NotFound()
werkzeug.exceptions.NotFound: 404 Not Found: The requested URL was not found on the server. If you entered the URL manually please check your spelling and try again.
2025-05-06 16:09:21,906 - app - ERROR - [sale_routes.py:26] - Error retrieving sales: type object 'Sale' has no attribute 'created_at'
2025-05-06 16:09:21,910 - app - ERROR - [__init__.py:47] - Unhandled exception: 404 Not Found: The requested URL was not found on the server. If you entered the URL manually please check your spelling and try again.
Traceback (most recent call last):
  File "/Users/guggarisathvik/groundnut_mill/.venv/lib/python3.9/site-packages/flask/app.py", line 917, in full_dispatch_request
    rv = self.dispatch_request()
  File "/Users/guggarisathvik/groundnut_mill/.venv/lib/python3.9/site-packages/flask/app.py", line 902, in dispatch_request
    return self.ensure_sync(self.view_functions[rule.endpoint])(**view_args)  # type: ignore[no-any-return]
  File "/Users/guggarisathvik/groundnut_mill/.venv/lib/python3.9/site-packages/flask/app.py", line 278, in <lambda>
    view_func=lambda **kw: self_ref().send_static_file(**kw),  # type: ignore # noqa: B950
  File "/Users/guggarisathvik/groundnut_mill/.venv/lib/python3.9/site-packages/flask/app.py", line 326, in send_static_file
    return send_from_directory(
  File "/Users/guggarisathvik/groundnut_mill/.venv/lib/python3.9/site-packages/flask/helpers.py", line 565, in send_from_directory
    return werkzeug.utils.send_from_directory(  # type: ignore[return-value]
  File "/Users/guggarisathvik/groundnut_mill/.venv/lib/python3.9/site-packages/werkzeug/utils.py", line 575, in send_from_directory
    raise NotFound()
werkzeug.exceptions.NotFound: 404 Not Found: The requested URL was not found on the server. If you entered the URL manually please check your spelling and try again.
2025-05-06 16:09:21,960 - app - ERROR - [__init__.py:47] - Unhandled exception: 404 Not Found: The requested URL was not found on the server. If you entered the URL manually please check your spelling and try again.
Traceback (most recent call last):
  File "/Users/guggarisathvik/groundnut_mill/.venv/lib/python3.9/site-packages/flask/app.py", line 917, in full_dispatch_request
    rv = self.dispatch_request()
  File "/Users/guggarisathvik/groundnut_mill/.venv/lib/python3.9/site-packages/flask/app.py", line 902, in dispatch_request
    return self.ensure_sync(self.view_functions[rule.endpoint])(**view_args)  # type: ignore[no-any-return]
  File "/Users/guggarisathvik/groundnut_mill/.venv/lib/python3.9/site-packages/flask/app.py", line 278, in <lambda>
    view_func=lambda **kw: self_ref().send_static_file(**kw),  # type: ignore # noqa: B950
  File "/Users/guggarisathvik/groundnut_mill/.venv/lib/python3.9/site-packages/flask/app.py", line 326, in send_static_file
    return send_from_directory(
  File "/Users/guggarisathvik/groundnut_mill/.venv/lib/python3.9/site-packages/flask/helpers.py", line 565, in send_from_directory
    return werkzeug.utils.send_from_directory(  # type: ignore[return-value]
  File "/Users/guggarisathvik/groundnut_mill/.venv/lib/python3.9/site-packages/werkzeug/utils.py", line 575, in send_from_directory
    raise NotFound()
werkzeug.exceptions.NotFound: 404 Not Found: The requested URL was not found on the server. If you entered the URL manually please check your spelling and try again.
2025-05-06 16:09:24,270 - app - ERROR - [__init__.py:47] - Unhandled exception: 404 Not Found: The requested URL was not found on the server. If you entered the URL manually please check your spelling and try again.
Traceback (most recent call last):
  File "/Users/guggarisathvik/groundnut_mill/.venv/lib/python3.9/site-packages/flask/app.py", line 917, in full_dispatch_request
    rv = self.dispatch_request()
  File "/Users/guggarisathvik/groundnut_mill/.venv/lib/python3.9/site-packages/flask/app.py", line 902, in dispatch_request
    return self.ensure_sync(self.view_functions[rule.endpoint])(**view_args)  # type: ignore[no-any-return]
  File "/Users/guggarisathvik/groundnut_mill/.venv/lib/python3.9/site-packages/flask/app.py", line 278, in <lambda>
    view_func=lambda **kw: self_ref().send_static_file(**kw),  # type: ignore # noqa: B950
  File "/Users/guggarisathvik/groundnut_mill/.venv/lib/python3.9/site-packages/flask/app.py", line 326, in send_static_file
    return send_from_directory(
  File "/Users/guggarisathvik/groundnut_mill/.venv/lib/python3.9/site-packages/flask/helpers.py", line 565, in send_from_directory
    return werkzeug.utils.send_from_directory(  # type: ignore[return-value]
  File "/Users/guggarisathvik/groundnut_mill/.venv/lib/python3.9/site-packages/werkzeug/utils.py", line 575, in send_from_directory
    raise NotFound()
werkzeug.exceptions.NotFound: 404 Not Found: The requested URL was not found on the server. If you entered the URL manually please check your spelling and try again.
2025-05-06 16:09:24,324 - app - ERROR - [__init__.py:47] - Unhandled exception: 404 Not Found: The requested URL was not found on the server. If you entered the URL manually please check your spelling and try again.
Traceback (most recent call last):
  File "/Users/guggarisathvik/groundnut_mill/.venv/lib/python3.9/site-packages/flask/app.py", line 917, in full_dispatch_request
    rv = self.dispatch_request()
  File "/Users/guggarisathvik/groundnut_mill/.venv/lib/python3.9/site-packages/flask/app.py", line 902, in dispatch_request
    return self.ensure_sync(self.view_functions[rule.endpoint])(**view_args)  # type: ignore[no-any-return]
  File "/Users/guggarisathvik/groundnut_mill/.venv/lib/python3.9/site-packages/flask/app.py", line 278, in <lambda>
    view_func=lambda **kw: self_ref().send_static_file(**kw),  # type: ignore # noqa: B950
  File "/Users/guggarisathvik/groundnut_mill/.venv/lib/python3.9/site-packages/flask/app.py", line 326, in send_static_file
    return send_from_directory(
  File "/Users/guggarisathvik/groundnut_mill/.venv/lib/python3.9/site-packages/flask/helpers.py", line 565, in send_from_directory
    return werkzeug.utils.send_from_directory(  # type: ignore[return-value]
  File "/Users/guggarisathvik/groundnut_mill/.venv/lib/python3.9/site-packages/werkzeug/utils.py", line 575, in send_from_directory
    raise NotFound()
werkzeug.exceptions.NotFound: 404 Not Found: The requested URL was not found on the server. If you entered the URL manually please check your spelling and try again.
2025-05-06 16:09:26,774 - app - ERROR - [sale_routes.py:26] - Error retrieving sales: type object 'Sale' has no attribute 'created_at'
2025-05-06 16:09:26,778 - app - ERROR - [__init__.py:47] - Unhandled exception: 404 Not Found: The requested URL was not found on the server. If you entered the URL manually please check your spelling and try again.
Traceback (most recent call last):
  File "/Users/guggarisathvik/groundnut_mill/.venv/lib/python3.9/site-packages/flask/app.py", line 917, in full_dispatch_request
    rv = self.dispatch_request()
  File "/Users/guggarisathvik/groundnut_mill/.venv/lib/python3.9/site-packages/flask/app.py", line 902, in dispatch_request
    return self.ensure_sync(self.view_functions[rule.endpoint])(**view_args)  # type: ignore[no-any-return]
  File "/Users/guggarisathvik/groundnut_mill/.venv/lib/python3.9/site-packages/flask/app.py", line 278, in <lambda>
    view_func=lambda **kw: self_ref().send_static_file(**kw),  # type: ignore # noqa: B950
  File "/Users/guggarisathvik/groundnut_mill/.venv/lib/python3.9/site-packages/flask/app.py", line 326, in send_static_file
    return send_from_directory(
  File "/Users/guggarisathvik/groundnut_mill/.venv/lib/python3.9/site-packages/flask/helpers.py", line 565, in send_from_directory
    return werkzeug.utils.send_from_directory(  # type: ignore[return-value]
  File "/Users/guggarisathvik/groundnut_mill/.venv/lib/python3.9/site-packages/werkzeug/utils.py", line 575, in send_from_directory
    raise NotFound()
werkzeug.exceptions.NotFound: 404 Not Found: The requested URL was not found on the server. If you entered the URL manually please check your spelling and try again.
2025-05-06 16:09:26,840 - app - ERROR - [__init__.py:47] - Unhandled exception: 404 Not Found: The requested URL was not found on the server. If you entered the URL manually please check your spelling and try again.
Traceback (most recent call last):
  File "/Users/guggarisathvik/groundnut_mill/.venv/lib/python3.9/site-packages/flask/app.py", line 917, in full_dispatch_request
    rv = self.dispatch_request()
  File "/Users/guggarisathvik/groundnut_mill/.venv/lib/python3.9/site-packages/flask/app.py", line 902, in dispatch_request
    return self.ensure_sync(self.view_functions[rule.endpoint])(**view_args)  # type: ignore[no-any-return]
  File "/Users/guggarisathvik/groundnut_mill/.venv/lib/python3.9/site-packages/flask/app.py", line 278, in <lambda>
    view_func=lambda **kw: self_ref().send_static_file(**kw),  # type: ignore # noqa: B950
  File "/Users/guggarisathvik/groundnut_mill/.venv/lib/python3.9/site-packages/flask/app.py", line 326, in send_static_file
    return send_from_directory(
  File "/Users/guggarisathvik/groundnut_mill/.venv/lib/python3.9/site-packages/flask/helpers.py", line 565, in send_from_directory
    return werkzeug.utils.send_from_directory(  # type: ignore[return-value]
  File "/Users/guggarisathvik/groundnut_mill/.venv/lib/python3.9/site-packages/werkzeug/utils.py", line 575, in send_from_directory
    raise NotFound()
werkzeug.exceptions.NotFound: 404 Not Found: The requested URL was not found on the server. If you entered the URL manually please check your spelling and try again.
2025-05-06 16:09:29,369 - app - ERROR - [__init__.py:47] - Unhandled exception: 404 Not Found: The requested URL was not found on the server. If you entered the URL manually please check your spelling and try again.
Traceback (most recent call last):
  File "/Users/guggarisathvik/groundnut_mill/.venv/lib/python3.9/site-packages/flask/app.py", line 917, in full_dispatch_request
    rv = self.dispatch_request()
  File "/Users/guggarisathvik/groundnut_mill/.venv/lib/python3.9/site-packages/flask/app.py", line 902, in dispatch_request
    return self.ensure_sync(self.view_functions[rule.endpoint])(**view_args)  # type: ignore[no-any-return]
  File "/Users/guggarisathvik/groundnut_mill/.venv/lib/python3.9/site-packages/flask/app.py", line 278, in <lambda>
    view_func=lambda **kw: self_ref().send_static_file(**kw),  # type: ignore # noqa: B950
  File "/Users/guggarisathvik/groundnut_mill/.venv/lib/python3.9/site-packages/flask/app.py", line 326, in send_static_file
    return send_from_directory(
  File "/Users/guggarisathvik/groundnut_mill/.venv/lib/python3.9/site-packages/flask/helpers.py", line 565, in send_from_directory
    return werkzeug.utils.send_from_directory(  # type: ignore[return-value]
  File "/Users/guggarisathvik/groundnut_mill/.venv/lib/python3.9/site-packages/werkzeug/utils.py", line 575, in send_from_directory
    raise NotFound()
werkzeug.exceptions.NotFound: 404 Not Found: The requested URL was not found on the server. If you entered the URL manually please check your spelling and try again.
2025-05-06 16:09:29,426 - app - ERROR - [__init__.py:47] - Unhandled exception: 404 Not Found: The requested URL was not found on the server. If you entered the URL manually please check your spelling and try again.
Traceback (most recent call last):
  File "/Users/guggarisathvik/groundnut_mill/.venv/lib/python3.9/site-packages/flask/app.py", line 917, in full_dispatch_request
    rv = self.dispatch_request()
  File "/Users/guggarisathvik/groundnut_mill/.venv/lib/python3.9/site-packages/flask/app.py", line 902, in dispatch_request
    return self.ensure_sync(self.view_functions[rule.endpoint])(**view_args)  # type: ignore[no-any-return]
  File "/Users/guggarisathvik/groundnut_mill/.venv/lib/python3.9/site-packages/flask/app.py", line 278, in <lambda>
    view_func=lambda **kw: self_ref().send_static_file(**kw),  # type: ignore # noqa: B950
  File "/Users/guggarisathvik/groundnut_mill/.venv/lib/python3.9/site-packages/flask/app.py", line 326, in send_static_file
    return send_from_directory(
  File "/Users/guggarisathvik/groundnut_mill/.venv/lib/python3.9/site-packages/flask/helpers.py", line 565, in send_from_directory
    return werkzeug.utils.send_from_directory(  # type: ignore[return-value]
  File "/Users/guggarisathvik/groundnut_mill/.venv/lib/python3.9/site-packages/werkzeug/utils.py", line 575, in send_from_directory
    raise NotFound()
werkzeug.exceptions.NotFound: 404 Not Found: The requested URL was not found on the server. If you entered the URL manually please check your spelling and try again.
2025-05-06 16:10:08,387 - app - ERROR - [sale_routes.py:26] - Error retrieving sales: type object 'Sale' has no attribute 'created_at'
2025-05-06 16:10:08,391 - app - ERROR - [__init__.py:47] - Unhandled exception: 404 Not Found: The requested URL was not found on the server. If you entered the URL manually please check your spelling and try again.
Traceback (most recent call last):
  File "/Users/guggarisathvik/groundnut_mill/.venv/lib/python3.9/site-packages/flask/app.py", line 917, in full_dispatch_request
    rv = self.dispatch_request()
  File "/Users/guggarisathvik/groundnut_mill/.venv/lib/python3.9/site-packages/flask/app.py", line 902, in dispatch_request
    return self.ensure_sync(self.view_functions[rule.endpoint])(**view_args)  # type: ignore[no-any-return]
  File "/Users/guggarisathvik/groundnut_mill/.venv/lib/python3.9/site-packages/flask/app.py", line 278, in <lambda>
    view_func=lambda **kw: self_ref().send_static_file(**kw),  # type: ignore # noqa: B950
  File "/Users/guggarisathvik/groundnut_mill/.venv/lib/python3.9/site-packages/flask/app.py", line 326, in send_static_file
    return send_from_directory(
  File "/Users/guggarisathvik/groundnut_mill/.venv/lib/python3.9/site-packages/flask/helpers.py", line 565, in send_from_directory
    return werkzeug.utils.send_from_directory(  # type: ignore[return-value]
  File "/Users/guggarisathvik/groundnut_mill/.venv/lib/python3.9/site-packages/werkzeug/utils.py", line 575, in send_from_directory
    raise NotFound()
werkzeug.exceptions.NotFound: 404 Not Found: The requested URL was not found on the server. If you entered the URL manually please check your spelling and try again.
2025-05-06 16:10:08,437 - app - ERROR - [__init__.py:47] - Unhandled exception: 404 Not Found: The requested URL was not found on the server. If you entered the URL manually please check your spelling and try again.
Traceback (most recent call last):
  File "/Users/guggarisathvik/groundnut_mill/.venv/lib/python3.9/site-packages/flask/app.py", line 917, in full_dispatch_request
    rv = self.dispatch_request()
  File "/Users/guggarisathvik/groundnut_mill/.venv/lib/python3.9/site-packages/flask/app.py", line 902, in dispatch_request
    return self.ensure_sync(self.view_functions[rule.endpoint])(**view_args)  # type: ignore[no-any-return]
  File "/Users/guggarisathvik/groundnut_mill/.venv/lib/python3.9/site-packages/flask/app.py", line 278, in <lambda>
    view_func=lambda **kw: self_ref().send_static_file(**kw),  # type: ignore # noqa: B950
  File "/Users/guggarisathvik/groundnut_mill/.venv/lib/python3.9/site-packages/flask/app.py", line 326, in send_static_file
    return send_from_directory(
  File "/Users/guggarisathvik/groundnut_mill/.venv/lib/python3.9/site-packages/flask/helpers.py", line 565, in send_from_directory
    return werkzeug.utils.send_from_directory(  # type: ignore[return-value]
  File "/Users/guggarisathvik/groundnut_mill/.venv/lib/python3.9/site-packages/werkzeug/utils.py", line 575, in send_from_directory
    raise NotFound()
werkzeug.exceptions.NotFound: 404 Not Found: The requested URL was not found on the server. If you entered the URL manually please check your spelling and try again.
2025-05-06 16:10:09,652 - app - ERROR - [__init__.py:47] - Unhandled exception: 404 Not Found: The requested URL was not found on the server. If you entered the URL manually please check your spelling and try again.
Traceback (most recent call last):
  File "/Users/guggarisathvik/groundnut_mill/.venv/lib/python3.9/site-packages/flask/app.py", line 917, in full_dispatch_request
    rv = self.dispatch_request()
  File "/Users/guggarisathvik/groundnut_mill/.venv/lib/python3.9/site-packages/flask/app.py", line 902, in dispatch_request
    return self.ensure_sync(self.view_functions[rule.endpoint])(**view_args)  # type: ignore[no-any-return]
  File "/Users/guggarisathvik/groundnut_mill/.venv/lib/python3.9/site-packages/flask/app.py", line 278, in <lambda>
    view_func=lambda **kw: self_ref().send_static_file(**kw),  # type: ignore # noqa: B950
  File "/Users/guggarisathvik/groundnut_mill/.venv/lib/python3.9/site-packages/flask/app.py", line 326, in send_static_file
    return send_from_directory(
  File "/Users/guggarisathvik/groundnut_mill/.venv/lib/python3.9/site-packages/flask/helpers.py", line 565, in send_from_directory
    return werkzeug.utils.send_from_directory(  # type: ignore[return-value]
  File "/Users/guggarisathvik/groundnut_mill/.venv/lib/python3.9/site-packages/werkzeug/utils.py", line 575, in send_from_directory
    raise NotFound()
werkzeug.exceptions.NotFound: 404 Not Found: The requested URL was not found on the server. If you entered the URL manually please check your spelling and try again.
2025-05-06 16:10:17,400 - app - ERROR - [sale_routes.py:26] - Error retrieving sales: type object 'Sale' has no attribute 'created_at'
2025-05-06 16:10:17,404 - app - ERROR - [__init__.py:47] - Unhandled exception: 404 Not Found: The requested URL was not found on the server. If you entered the URL manually please check your spelling and try again.
Traceback (most recent call last):
  File "/Users/guggarisathvik/groundnut_mill/.venv/lib/python3.9/site-packages/flask/app.py", line 917, in full_dispatch_request
    rv = self.dispatch_request()
  File "/Users/guggarisathvik/groundnut_mill/.venv/lib/python3.9/site-packages/flask/app.py", line 902, in dispatch_request
    return self.ensure_sync(self.view_functions[rule.endpoint])(**view_args)  # type: ignore[no-any-return]
  File "/Users/guggarisathvik/groundnut_mill/.venv/lib/python3.9/site-packages/flask/app.py", line 278, in <lambda>
    view_func=lambda **kw: self_ref().send_static_file(**kw),  # type: ignore # noqa: B950
  File "/Users/guggarisathvik/groundnut_mill/.venv/lib/python3.9/site-packages/flask/app.py", line 326, in send_static_file
    return send_from_directory(
  File "/Users/guggarisathvik/groundnut_mill/.venv/lib/python3.9/site-packages/flask/helpers.py", line 565, in send_from_directory
    return werkzeug.utils.send_from_directory(  # type: ignore[return-value]
  File "/Users/guggarisathvik/groundnut_mill/.venv/lib/python3.9/site-packages/werkzeug/utils.py", line 575, in send_from_directory
    raise NotFound()
werkzeug.exceptions.NotFound: 404 Not Found: The requested URL was not found on the server. If you entered the URL manually please check your spelling and try again.
2025-05-06 16:10:17,451 - app - ERROR - [__init__.py:47] - Unhandled exception: 404 Not Found: The requested URL was not found on the server. If you entered the URL manually please check your spelling and try again.
Traceback (most recent call last):
  File "/Users/guggarisathvik/groundnut_mill/.venv/lib/python3.9/site-packages/flask/app.py", line 917, in full_dispatch_request
    rv = self.dispatch_request()
  File "/Users/guggarisathvik/groundnut_mill/.venv/lib/python3.9/site-packages/flask/app.py", line 902, in dispatch_request
    return self.ensure_sync(self.view_functions[rule.endpoint])(**view_args)  # type: ignore[no-any-return]
  File "/Users/guggarisathvik/groundnut_mill/.venv/lib/python3.9/site-packages/flask/app.py", line 278, in <lambda>
    view_func=lambda **kw: self_ref().send_static_file(**kw),  # type: ignore # noqa: B950
  File "/Users/guggarisathvik/groundnut_mill/.venv/lib/python3.9/site-packages/flask/app.py", line 326, in send_static_file
    return send_from_directory(
  File "/Users/guggarisathvik/groundnut_mill/.venv/lib/python3.9/site-packages/flask/helpers.py", line 565, in send_from_directory
    return werkzeug.utils.send_from_directory(  # type: ignore[return-value]
  File "/Users/guggarisathvik/groundnut_mill/.venv/lib/python3.9/site-packages/werkzeug/utils.py", line 575, in send_from_directory
    raise NotFound()
werkzeug.exceptions.NotFound: 404 Not Found: The requested URL was not found on the server. If you entered the URL manually please check your spelling and try again.
2025-05-06 16:10:54,392 - app - ERROR - [sale_routes.py:26] - Error retrieving sales: type object 'Sale' has no attribute 'created_at'
2025-05-06 16:10:54,397 - app - ERROR - [__init__.py:47] - Unhandled exception: 404 Not Found: The requested URL was not found on the server. If you entered the URL manually please check your spelling and try again.
Traceback (most recent call last):
  File "/Users/guggarisathvik/groundnut_mill/.venv/lib/python3.9/site-packages/flask/app.py", line 917, in full_dispatch_request
    rv = self.dispatch_request()
  File "/Users/guggarisathvik/groundnut_mill/.venv/lib/python3.9/site-packages/flask/app.py", line 902, in dispatch_request
    return self.ensure_sync(self.view_functions[rule.endpoint])(**view_args)  # type: ignore[no-any-return]
  File "/Users/guggarisathvik/groundnut_mill/.venv/lib/python3.9/site-packages/flask/app.py", line 278, in <lambda>
    view_func=lambda **kw: self_ref().send_static_file(**kw),  # type: ignore # noqa: B950
  File "/Users/guggarisathvik/groundnut_mill/.venv/lib/python3.9/site-packages/flask/app.py", line 326, in send_static_file
    return send_from_directory(
  File "/Users/guggarisathvik/groundnut_mill/.venv/lib/python3.9/site-packages/flask/helpers.py", line 565, in send_from_directory
    return werkzeug.utils.send_from_directory(  # type: ignore[return-value]
  File "/Users/guggarisathvik/groundnut_mill/.venv/lib/python3.9/site-packages/werkzeug/utils.py", line 575, in send_from_directory
    raise NotFound()
werkzeug.exceptions.NotFound: 404 Not Found: The requested URL was not found on the server. If you entered the URL manually please check your spelling and try again.
2025-05-06 16:10:54,439 - app - ERROR - [__init__.py:47] - Unhandled exception: 404 Not Found: The requested URL was not found on the server. If you entered the URL manually please check your spelling and try again.
Traceback (most recent call last):
  File "/Users/guggarisathvik/groundnut_mill/.venv/lib/python3.9/site-packages/flask/app.py", line 917, in full_dispatch_request
    rv = self.dispatch_request()
  File "/Users/guggarisathvik/groundnut_mill/.venv/lib/python3.9/site-packages/flask/app.py", line 902, in dispatch_request
    return self.ensure_sync(self.view_functions[rule.endpoint])(**view_args)  # type: ignore[no-any-return]
  File "/Users/guggarisathvik/groundnut_mill/.venv/lib/python3.9/site-packages/flask/app.py", line 278, in <lambda>
    view_func=lambda **kw: self_ref().send_static_file(**kw),  # type: ignore # noqa: B950
  File "/Users/guggarisathvik/groundnut_mill/.venv/lib/python3.9/site-packages/flask/app.py", line 326, in send_static_file
    return send_from_directory(
  File "/Users/guggarisathvik/groundnut_mill/.venv/lib/python3.9/site-packages/flask/helpers.py", line 565, in send_from_directory
    return werkzeug.utils.send_from_directory(  # type: ignore[return-value]
  File "/Users/guggarisathvik/groundnut_mill/.venv/lib/python3.9/site-packages/werkzeug/utils.py", line 575, in send_from_directory
    raise NotFound()
werkzeug.exceptions.NotFound: 404 Not Found: The requested URL was not found on the server. If you entered the URL manually please check your spelling and try again.
2025-05-06 16:13:02,635 - flask-app - INFO - [__init__.py:22] - Starting Flask application...
2025-05-06 16:13:05,234 - app - ERROR - [sale_routes.py:26] - Error retrieving sales: name 'sales' is not defined
2025-05-06 16:13:05,305 - app - ERROR - [__init__.py:47] - Unhandled exception: 404 Not Found: The requested URL was not found on the server. If you entered the URL manually please check your spelling and try again.
Traceback (most recent call last):
  File "/Users/guggarisathvik/groundnut_mill/.venv/lib/python3.9/site-packages/flask/app.py", line 917, in full_dispatch_request
    rv = self.dispatch_request()
  File "/Users/guggarisathvik/groundnut_mill/.venv/lib/python3.9/site-packages/flask/app.py", line 902, in dispatch_request
    return self.ensure_sync(self.view_functions[rule.endpoint])(**view_args)  # type: ignore[no-any-return]
  File "/Users/guggarisathvik/groundnut_mill/.venv/lib/python3.9/site-packages/flask/app.py", line 278, in <lambda>
    view_func=lambda **kw: self_ref().send_static_file(**kw),  # type: ignore # noqa: B950
  File "/Users/guggarisathvik/groundnut_mill/.venv/lib/python3.9/site-packages/flask/app.py", line 326, in send_static_file
    return send_from_directory(
  File "/Users/guggarisathvik/groundnut_mill/.venv/lib/python3.9/site-packages/flask/helpers.py", line 565, in send_from_directory
    return werkzeug.utils.send_from_directory(  # type: ignore[return-value]
  File "/Users/guggarisathvik/groundnut_mill/.venv/lib/python3.9/site-packages/werkzeug/utils.py", line 575, in send_from_directory
    raise NotFound()
werkzeug.exceptions.NotFound: 404 Not Found: The requested URL was not found on the server. If you entered the URL manually please check your spelling and try again.
2025-05-06 16:13:07,499 - app - ERROR - [sale_routes.py:26] - Error retrieving sales: name 'sales' is not defined
2025-05-06 16:13:07,548 - app - ERROR - [__init__.py:47] - Unhandled exception: 404 Not Found: The requested URL was not found on the server. If you entered the URL manually please check your spelling and try again.
Traceback (most recent call last):
  File "/Users/guggarisathvik/groundnut_mill/.venv/lib/python3.9/site-packages/flask/app.py", line 917, in full_dispatch_request
    rv = self.dispatch_request()
  File "/Users/guggarisathvik/groundnut_mill/.venv/lib/python3.9/site-packages/flask/app.py", line 902, in dispatch_request
    return self.ensure_sync(self.view_functions[rule.endpoint])(**view_args)  # type: ignore[no-any-return]
  File "/Users/guggarisathvik/groundnut_mill/.venv/lib/python3.9/site-packages/flask/app.py", line 278, in <lambda>
    view_func=lambda **kw: self_ref().send_static_file(**kw),  # type: ignore # noqa: B950
  File "/Users/guggarisathvik/groundnut_mill/.venv/lib/python3.9/site-packages/flask/app.py", line 326, in send_static_file
    return send_from_directory(
  File "/Users/guggarisathvik/groundnut_mill/.venv/lib/python3.9/site-packages/flask/helpers.py", line 565, in send_from_directory
    return werkzeug.utils.send_from_directory(  # type: ignore[return-value]
  File "/Users/guggarisathvik/groundnut_mill/.venv/lib/python3.9/site-packages/werkzeug/utils.py", line 575, in send_from_directory
    raise NotFound()
werkzeug.exceptions.NotFound: 404 Not Found: The requested URL was not found on the server. If you entered the URL manually please check your spelling and try again.
2025-05-06 16:13:41,782 - flask-app - INFO - [__init__.py:22] - Starting Flask application...
2025-05-06 16:13:45,318 - app - ERROR - [__init__.py:47] - Unhandled exception: 404 Not Found: The requested URL was not found on the server. If you entered the URL manually please check your spelling and try again.
Traceback (most recent call last):
  File "/Users/guggarisathvik/groundnut_mill/.venv/lib/python3.9/site-packages/flask/app.py", line 917, in full_dispatch_request
    rv = self.dispatch_request()
  File "/Users/guggarisathvik/groundnut_mill/.venv/lib/python3.9/site-packages/flask/app.py", line 902, in dispatch_request
    return self.ensure_sync(self.view_functions[rule.endpoint])(**view_args)  # type: ignore[no-any-return]
  File "/Users/guggarisathvik/groundnut_mill/.venv/lib/python3.9/site-packages/flask/app.py", line 278, in <lambda>
    view_func=lambda **kw: self_ref().send_static_file(**kw),  # type: ignore # noqa: B950
  File "/Users/guggarisathvik/groundnut_mill/.venv/lib/python3.9/site-packages/flask/app.py", line 326, in send_static_file
    return send_from_directory(
  File "/Users/guggarisathvik/groundnut_mill/.venv/lib/python3.9/site-packages/flask/helpers.py", line 565, in send_from_directory
    return werkzeug.utils.send_from_directory(  # type: ignore[return-value]
  File "/Users/guggarisathvik/groundnut_mill/.venv/lib/python3.9/site-packages/werkzeug/utils.py", line 575, in send_from_directory
    raise NotFound()
werkzeug.exceptions.NotFound: 404 Not Found: The requested URL was not found on the server. If you entered the URL manually please check your spelling and try again.
2025-05-06 16:14:17,846 - flask-app - INFO - [__init__.py:22] - Starting Flask application...
2025-05-06 16:14:47,919 - flask-app - INFO - [__init__.py:22] - Starting Flask application...
