2025-05-06 04:58:09,850 - flask-app - ERROR - [debt_routes.py:16] - Cache operation failed: 'Flask' object has no attribute 'cache'
2025-05-06 14:40:39,067 - flask-app - INFO - [__init__.py:22] - Starting Flask application...
2025-05-06 15:02:37,529 - flask-app - INFO - [__init__.py:22] - Starting Flask application...
2025-05-06 16:09:07,404 - flask-app - INFO - [__init__.py:22] - Starting Flask application...
2025-05-06 16:09:10,803 - app - ERROR - [__init__.py:47] - Unhandled exception: 404 Not Found: The requested URL was not found on the server. If you entered the URL manually please check your spelling and try again.
Traceback (most recent call last):
  File "/Users/guggarisathvik/groundnut_mill/.venv/lib/python3.9/site-packages/flask/app.py", line 917, in full_dispatch_request
    rv = self.dispatch_request()
  File "/Users/guggarisathvik/groundnut_mill/.venv/lib/python3.9/site-packages/flask/app.py", line 902, in dispatch_request
    return self.ensure_sync(self.view_functions[rule.endpoint])(**view_args)  # type: ignore[no-any-return]
  File "/Users/guggarisathvik/groundnut_mill/.venv/lib/python3.9/site-packages/flask/app.py", line 278, in <lambda>
    view_func=lambda **kw: self_ref().send_static_file(**kw),  # type: ignore # noqa: B950
  File "/Users/guggarisathvik/groundnut_mill/.venv/lib/python3.9/site-packages/flask/app.py", line 326, in send_static_file
    return send_from_directory(
  File "/Users/guggarisathvik/groundnut_mill/.venv/lib/python3.9/site-packages/flask/helpers.py", line 565, in send_from_directory
    return werkzeug.utils.send_from_directory(  # type: ignore[return-value]
  File "/Users/guggarisathvik/groundnut_mill/.venv/lib/python3.9/site-packages/werkzeug/utils.py", line 575, in send_from_directory
    raise NotFound()
werkzeug.exceptions.NotFound: 404 Not Found: The requested URL was not found on the server. If you entered the URL manually please check your spelling and try again.
2025-05-06 16:09:10,916 - app - ERROR - [__init__.py:47] - Unhandled exception: 404 Not Found: The requested URL was not found on the server. If you entered the URL manually please check your spelling and try again.
Traceback (most recent call last):
  File "/Users/guggarisathvik/groundnut_mill/.venv/lib/python3.9/site-packages/flask/app.py", line 917, in full_dispatch_request
    rv = self.dispatch_request()
  File "/Users/guggarisathvik/groundnut_mill/.venv/lib/python3.9/site-packages/flask/app.py", line 902, in dispatch_request
    return self.ensure_sync(self.view_functions[rule.endpoint])(**view_args)  # type: ignore[no-any-return]
  File "/Users/guggarisathvik/groundnut_mill/.venv/lib/python3.9/site-packages/flask/app.py", line 278, in <lambda>
    view_func=lambda **kw: self_ref().send_static_file(**kw),  # type: ignore # noqa: B950
  File "/Users/guggarisathvik/groundnut_mill/.venv/lib/python3.9/site-packages/flask/app.py", line 326, in send_static_file
    return send_from_directory(
  File "/Users/guggarisathvik/groundnut_mill/.venv/lib/python3.9/site-packages/flask/helpers.py", line 565, in send_from_directory
    return werkzeug.utils.send_from_directory(  # type: ignore[return-value]
  File "/Users/guggarisathvik/groundnut_mill/.venv/lib/python3.9/site-packages/werkzeug/utils.py", line 575, in send_from_directory
    raise NotFound()
werkzeug.exceptions.NotFound: 404 Not Found: The requested URL was not found on the server. If you entered the URL manually please check your spelling and try again.
2025-05-06 16:09:12,358 - app - ERROR - [__init__.py:47] - Unhandled exception: 404 Not Found: The requested URL was not found on the server. If you entered the URL manually please check your spelling and try again.
Traceback (most recent call last):
  File "/Users/guggarisathvik/groundnut_mill/.venv/lib/python3.9/site-packages/flask/app.py", line 917, in full_dispatch_request
    rv = self.dispatch_request()
  File "/Users/guggarisathvik/groundnut_mill/.venv/lib/python3.9/site-packages/flask/app.py", line 902, in dispatch_request
    return self.ensure_sync(self.view_functions[rule.endpoint])(**view_args)  # type: ignore[no-any-return]
  File "/Users/guggarisathvik/groundnut_mill/.venv/lib/python3.9/site-packages/flask/app.py", line 278, in <lambda>
    view_func=lambda **kw: self_ref().send_static_file(**kw),  # type: ignore # noqa: B950
  File "/Users/guggarisathvik/groundnut_mill/.venv/lib/python3.9/site-packages/flask/app.py", line 326, in send_static_file
    return send_from_directory(
  File "/Users/guggarisathvik/groundnut_mill/.venv/lib/python3.9/site-packages/flask/helpers.py", line 565, in send_from_directory
    return werkzeug.utils.send_from_directory(  # type: ignore[return-value]
  File "/Users/guggarisathvik/groundnut_mill/.venv/lib/python3.9/site-packages/werkzeug/utils.py", line 575, in send_from_directory
    raise NotFound()
werkzeug.exceptions.NotFound: 404 Not Found: The requested URL was not found on the server. If you entered the URL manually please check your spelling and try again.
2025-05-06 16:09:12,405 - app - ERROR - [__init__.py:47] - Unhandled exception: 404 Not Found: The requested URL was not found on the server. If you entered the URL manually please check your spelling and try again.
Traceback (most recent call last):
  File "/Users/guggarisathvik/groundnut_mill/.venv/lib/python3.9/site-packages/flask/app.py", line 917, in full_dispatch_request
    rv = self.dispatch_request()
  File "/Users/guggarisathvik/groundnut_mill/.venv/lib/python3.9/site-packages/flask/app.py", line 902, in dispatch_request
    return self.ensure_sync(self.view_functions[rule.endpoint])(**view_args)  # type: ignore[no-any-return]
  File "/Users/guggarisathvik/groundnut_mill/.venv/lib/python3.9/site-packages/flask/app.py", line 278, in <lambda>
    view_func=lambda **kw: self_ref().send_static_file(**kw),  # type: ignore # noqa: B950
  File "/Users/guggarisathvik/groundnut_mill/.venv/lib/python3.9/site-packages/flask/app.py", line 326, in send_static_file
    return send_from_directory(
  File "/Users/guggarisathvik/groundnut_mill/.venv/lib/python3.9/site-packages/flask/helpers.py", line 565, in send_from_directory
    return werkzeug.utils.send_from_directory(  # type: ignore[return-value]
  File "/Users/guggarisathvik/groundnut_mill/.venv/lib/python3.9/site-packages/werkzeug/utils.py", line 575, in send_from_directory
    raise NotFound()
werkzeug.exceptions.NotFound: 404 Not Found: The requested URL was not found on the server. If you entered the URL manually please check your spelling and try again.
2025-05-06 16:09:13,807 - app - ERROR - [__init__.py:47] - Unhandled exception: 404 Not Found: The requested URL was not found on the server. If you entered the URL manually please check your spelling and try again.
Traceback (most recent call last):
  File "/Users/guggarisathvik/groundnut_mill/.venv/lib/python3.9/site-packages/flask/app.py", line 917, in full_dispatch_request
    rv = self.dispatch_request()
  File "/Users/guggarisathvik/groundnut_mill/.venv/lib/python3.9/site-packages/flask/app.py", line 902, in dispatch_request
    return self.ensure_sync(self.view_functions[rule.endpoint])(**view_args)  # type: ignore[no-any-return]
  File "/Users/guggarisathvik/groundnut_mill/.venv/lib/python3.9/site-packages/flask/app.py", line 278, in <lambda>
    view_func=lambda **kw: self_ref().send_static_file(**kw),  # type: ignore # noqa: B950
  File "/Users/guggarisathvik/groundnut_mill/.venv/lib/python3.9/site-packages/flask/app.py", line 326, in send_static_file
    return send_from_directory(
  File "/Users/guggarisathvik/groundnut_mill/.venv/lib/python3.9/site-packages/flask/helpers.py", line 565, in send_from_directory
    return werkzeug.utils.send_from_directory(  # type: ignore[return-value]
  File "/Users/guggarisathvik/groundnut_mill/.venv/lib/python3.9/site-packages/werkzeug/utils.py", line 575, in send_from_directory
    raise NotFound()
werkzeug.exceptions.NotFound: 404 Not Found: The requested URL was not found on the server. If you entered the URL manually please check your spelling and try again.
2025-05-06 16:09:14,188 - app - ERROR - [__init__.py:47] - Unhandled exception: 404 Not Found: The requested URL was not found on the server. If you entered the URL manually please check your spelling and try again.
Traceback (most recent call last):
  File "/Users/guggarisathvik/groundnut_mill/.venv/lib/python3.9/site-packages/flask/app.py", line 917, in full_dispatch_request
    rv = self.dispatch_request()
  File "/Users/guggarisathvik/groundnut_mill/.venv/lib/python3.9/site-packages/flask/app.py", line 902, in dispatch_request
    return self.ensure_sync(self.view_functions[rule.endpoint])(**view_args)  # type: ignore[no-any-return]
  File "/Users/guggarisathvik/groundnut_mill/.venv/lib/python3.9/site-packages/flask/app.py", line 278, in <lambda>
    view_func=lambda **kw: self_ref().send_static_file(**kw),  # type: ignore # noqa: B950
  File "/Users/guggarisathvik/groundnut_mill/.venv/lib/python3.9/site-packages/flask/app.py", line 326, in send_static_file
    return send_from_directory(
  File "/Users/guggarisathvik/groundnut_mill/.venv/lib/python3.9/site-packages/flask/helpers.py", line 565, in send_from_directory
    return werkzeug.utils.send_from_directory(  # type: ignore[return-value]
  File "/Users/guggarisathvik/groundnut_mill/.venv/lib/python3.9/site-packages/werkzeug/utils.py", line 575, in send_from_directory
    raise NotFound()
werkzeug.exceptions.NotFound: 404 Not Found: The requested URL was not found on the server. If you entered the URL manually please check your spelling and try again.
2025-05-06 16:09:14,671 - app - ERROR - [__init__.py:47] - Unhandled exception: 404 Not Found: The requested URL was not found on the server. If you entered the URL manually please check your spelling and try again.
Traceback (most recent call last):
  File "/Users/guggarisathvik/groundnut_mill/.venv/lib/python3.9/site-packages/flask/app.py", line 917, in full_dispatch_request
    rv = self.dispatch_request()
  File "/Users/guggarisathvik/groundnut_mill/.venv/lib/python3.9/site-packages/flask/app.py", line 902, in dispatch_request
    return self.ensure_sync(self.view_functions[rule.endpoint])(**view_args)  # type: ignore[no-any-return]
  File "/Users/guggarisathvik/groundnut_mill/.venv/lib/python3.9/site-packages/flask/app.py", line 278, in <lambda>
    view_func=lambda **kw: self_ref().send_static_file(**kw),  # type: ignore # noqa: B950
  File "/Users/guggarisathvik/groundnut_mill/.venv/lib/python3.9/site-packages/flask/app.py", line 326, in send_static_file
    return send_from_directory(
  File "/Users/guggarisathvik/groundnut_mill/.venv/lib/python3.9/site-packages/flask/helpers.py", line 565, in send_from_directory
    return werkzeug.utils.send_from_directory(  # type: ignore[return-value]
  File "/Users/guggarisathvik/groundnut_mill/.venv/lib/python3.9/site-packages/werkzeug/utils.py", line 575, in send_from_directory
    raise NotFound()
werkzeug.exceptions.NotFound: 404 Not Found: The requested URL was not found on the server. If you entered the URL manually please check your spelling and try again.
2025-05-06 16:09:14,722 - app - ERROR - [__init__.py:47] - Unhandled exception: 404 Not Found: The requested URL was not found on the server. If you entered the URL manually please check your spelling and try again.
Traceback (most recent call last):
  File "/Users/guggarisathvik/groundnut_mill/.venv/lib/python3.9/site-packages/flask/app.py", line 917, in full_dispatch_request
    rv = self.dispatch_request()
  File "/Users/guggarisathvik/groundnut_mill/.venv/lib/python3.9/site-packages/flask/app.py", line 902, in dispatch_request
    return self.ensure_sync(self.view_functions[rule.endpoint])(**view_args)  # type: ignore[no-any-return]
  File "/Users/guggarisathvik/groundnut_mill/.venv/lib/python3.9/site-packages/flask/app.py", line 278, in <lambda>
    view_func=lambda **kw: self_ref().send_static_file(**kw),  # type: ignore # noqa: B950
  File "/Users/guggarisathvik/groundnut_mill/.venv/lib/python3.9/site-packages/flask/app.py", line 326, in send_static_file
    return send_from_directory(
  File "/Users/guggarisathvik/groundnut_mill/.venv/lib/python3.9/site-packages/flask/helpers.py", line 565, in send_from_directory
    return werkzeug.utils.send_from_directory(  # type: ignore[return-value]
  File "/Users/guggarisathvik/groundnut_mill/.venv/lib/python3.9/site-packages/werkzeug/utils.py", line 575, in send_from_directory
    raise NotFound()
werkzeug.exceptions.NotFound: 404 Not Found: The requested URL was not found on the server. If you entered the URL manually please check your spelling and try again.
2025-05-06 16:09:15,715 - app - ERROR - [__init__.py:47] - Unhandled exception: 404 Not Found: The requested URL was not found on the server. If you entered the URL manually please check your spelling and try again.
Traceback (most recent call last):
  File "/Users/guggarisathvik/groundnut_mill/.venv/lib/python3.9/site-packages/flask/app.py", line 917, in full_dispatch_request
    rv = self.dispatch_request()
  File "/Users/guggarisathvik/groundnut_mill/.venv/lib/python3.9/site-packages/flask/app.py", line 902, in dispatch_request
    return self.ensure_sync(self.view_functions[rule.endpoint])(**view_args)  # type: ignore[no-any-return]
  File "/Users/guggarisathvik/groundnut_mill/.venv/lib/python3.9/site-packages/flask/app.py", line 278, in <lambda>
    view_func=lambda **kw: self_ref().send_static_file(**kw),  # type: ignore # noqa: B950
  File "/Users/guggarisathvik/groundnut_mill/.venv/lib/python3.9/site-packages/flask/app.py", line 326, in send_static_file
    return send_from_directory(
  File "/Users/guggarisathvik/groundnut_mill/.venv/lib/python3.9/site-packages/flask/helpers.py", line 565, in send_from_directory
    return werkzeug.utils.send_from_directory(  # type: ignore[return-value]
  File "/Users/guggarisathvik/groundnut_mill/.venv/lib/python3.9/site-packages/werkzeug/utils.py", line 575, in send_from_directory
    raise NotFound()
werkzeug.exceptions.NotFound: 404 Not Found: The requested URL was not found on the server. If you entered the URL manually please check your spelling and try again.
2025-05-06 16:09:15,771 - app - ERROR - [__init__.py:47] - Unhandled exception: 404 Not Found: The requested URL was not found on the server. If you entered the URL manually please check your spelling and try again.
Traceback (most recent call last):
  File "/Users/guggarisathvik/groundnut_mill/.venv/lib/python3.9/site-packages/flask/app.py", line 917, in full_dispatch_request
    rv = self.dispatch_request()
  File "/Users/guggarisathvik/groundnut_mill/.venv/lib/python3.9/site-packages/flask/app.py", line 902, in dispatch_request
    return self.ensure_sync(self.view_functions[rule.endpoint])(**view_args)  # type: ignore[no-any-return]
  File "/Users/guggarisathvik/groundnut_mill/.venv/lib/python3.9/site-packages/flask/app.py", line 278, in <lambda>
    view_func=lambda **kw: self_ref().send_static_file(**kw),  # type: ignore # noqa: B950
  File "/Users/guggarisathvik/groundnut_mill/.venv/lib/python3.9/site-packages/flask/app.py", line 326, in send_static_file
    return send_from_directory(
  File "/Users/guggarisathvik/groundnut_mill/.venv/lib/python3.9/site-packages/flask/helpers.py", line 565, in send_from_directory
    return werkzeug.utils.send_from_directory(  # type: ignore[return-value]
  File "/Users/guggarisathvik/groundnut_mill/.venv/lib/python3.9/site-packages/werkzeug/utils.py", line 575, in send_from_directory
    raise NotFound()
werkzeug.exceptions.NotFound: 404 Not Found: The requested URL was not found on the server. If you entered the URL manually please check your spelling and try again.
2025-05-06 16:09:16,549 - app - ERROR - [__init__.py:47] - Unhandled exception: 404 Not Found: The requested URL was not found on the server. If you entered the URL manually please check your spelling and try again.
Traceback (most recent call last):
  File "/Users/guggarisathvik/groundnut_mill/.venv/lib/python3.9/site-packages/flask/app.py", line 917, in full_dispatch_request
    rv = self.dispatch_request()
  File "/Users/guggarisathvik/groundnut_mill/.venv/lib/python3.9/site-packages/flask/app.py", line 902, in dispatch_request
    return self.ensure_sync(self.view_functions[rule.endpoint])(**view_args)  # type: ignore[no-any-return]
  File "/Users/guggarisathvik/groundnut_mill/.venv/lib/python3.9/site-packages/flask/app.py", line 278, in <lambda>
    view_func=lambda **kw: self_ref().send_static_file(**kw),  # type: ignore # noqa: B950
  File "/Users/guggarisathvik/groundnut_mill/.venv/lib/python3.9/site-packages/flask/app.py", line 326, in send_static_file
    return send_from_directory(
  File "/Users/guggarisathvik/groundnut_mill/.venv/lib/python3.9/site-packages/flask/helpers.py", line 565, in send_from_directory
    return werkzeug.utils.send_from_directory(  # type: ignore[return-value]
  File "/Users/guggarisathvik/groundnut_mill/.venv/lib/python3.9/site-packages/werkzeug/utils.py", line 575, in send_from_directory
    raise NotFound()
werkzeug.exceptions.NotFound: 404 Not Found: The requested URL was not found on the server. If you entered the URL manually please check your spelling and try again.
2025-05-06 16:09:16,596 - app - ERROR - [__init__.py:47] - Unhandled exception: 404 Not Found: The requested URL was not found on the server. If you entered the URL manually please check your spelling and try again.
Traceback (most recent call last):
  File "/Users/guggarisathvik/groundnut_mill/.venv/lib/python3.9/site-packages/flask/app.py", line 917, in full_dispatch_request
    rv = self.dispatch_request()
  File "/Users/guggarisathvik/groundnut_mill/.venv/lib/python3.9/site-packages/flask/app.py", line 902, in dispatch_request
    return self.ensure_sync(self.view_functions[rule.endpoint])(**view_args)  # type: ignore[no-any-return]
  File "/Users/guggarisathvik/groundnut_mill/.venv/lib/python3.9/site-packages/flask/app.py", line 278, in <lambda>
    view_func=lambda **kw: self_ref().send_static_file(**kw),  # type: ignore # noqa: B950
  File "/Users/guggarisathvik/groundnut_mill/.venv/lib/python3.9/site-packages/flask/app.py", line 326, in send_static_file
    return send_from_directory(
  File "/Users/guggarisathvik/groundnut_mill/.venv/lib/python3.9/site-packages/flask/helpers.py", line 565, in send_from_directory
    return werkzeug.utils.send_from_directory(  # type: ignore[return-value]
  File "/Users/guggarisathvik/groundnut_mill/.venv/lib/python3.9/site-packages/werkzeug/utils.py", line 575, in send_from_directory
    raise NotFound()
werkzeug.exceptions.NotFound: 404 Not Found: The requested URL was not found on the server. If you entered the URL manually please check your spelling and try again.
2025-05-06 16:09:17,279 - app - ERROR - [debt_routes.py:16] - Cache operation failed: 'Flask' object has no attribute 'cache'
2025-05-06 16:09:17,295 - app - ERROR - [__init__.py:47] - Unhandled exception: 404 Not Found: The requested URL was not found on the server. If you entered the URL manually please check your spelling and try again.
Traceback (most recent call last):
  File "/Users/guggarisathvik/groundnut_mill/.venv/lib/python3.9/site-packages/flask/app.py", line 917, in full_dispatch_request
    rv = self.dispatch_request()
  File "/Users/guggarisathvik/groundnut_mill/.venv/lib/python3.9/site-packages/flask/app.py", line 902, in dispatch_request
    return self.ensure_sync(self.view_functions[rule.endpoint])(**view_args)  # type: ignore[no-any-return]
  File "/Users/guggarisathvik/groundnut_mill/.venv/lib/python3.9/site-packages/flask/app.py", line 278, in <lambda>
    view_func=lambda **kw: self_ref().send_static_file(**kw),  # type: ignore # noqa: B950
  File "/Users/guggarisathvik/groundnut_mill/.venv/lib/python3.9/site-packages/flask/app.py", line 326, in send_static_file
    return send_from_directory(
  File "/Users/guggarisathvik/groundnut_mill/.venv/lib/python3.9/site-packages/flask/helpers.py", line 565, in send_from_directory
    return werkzeug.utils.send_from_directory(  # type: ignore[return-value]
  File "/Users/guggarisathvik/groundnut_mill/.venv/lib/python3.9/site-packages/werkzeug/utils.py", line 575, in send_from_directory
    raise NotFound()
werkzeug.exceptions.NotFound: 404 Not Found: The requested URL was not found on the server. If you entered the URL manually please check your spelling and try again.
2025-05-06 16:09:17,344 - app - ERROR - [__init__.py:47] - Unhandled exception: 404 Not Found: The requested URL was not found on the server. If you entered the URL manually please check your spelling and try again.
Traceback (most recent call last):
  File "/Users/guggarisathvik/groundnut_mill/.venv/lib/python3.9/site-packages/flask/app.py", line 917, in full_dispatch_request
    rv = self.dispatch_request()
  File "/Users/guggarisathvik/groundnut_mill/.venv/lib/python3.9/site-packages/flask/app.py", line 902, in dispatch_request
    return self.ensure_sync(self.view_functions[rule.endpoint])(**view_args)  # type: ignore[no-any-return]
  File "/Users/guggarisathvik/groundnut_mill/.venv/lib/python3.9/site-packages/flask/app.py", line 278, in <lambda>
    view_func=lambda **kw: self_ref().send_static_file(**kw),  # type: ignore # noqa: B950
  File "/Users/guggarisathvik/groundnut_mill/.venv/lib/python3.9/site-packages/flask/app.py", line 326, in send_static_file
    return send_from_directory(
  File "/Users/guggarisathvik/groundnut_mill/.venv/lib/python3.9/site-packages/flask/helpers.py", line 565, in send_from_directory
    return werkzeug.utils.send_from_directory(  # type: ignore[return-value]
  File "/Users/guggarisathvik/groundnut_mill/.venv/lib/python3.9/site-packages/werkzeug/utils.py", line 575, in send_from_directory
    raise NotFound()
werkzeug.exceptions.NotFound: 404 Not Found: The requested URL was not found on the server. If you entered the URL manually please check your spelling and try again.
2025-05-06 16:09:18,291 - app - ERROR - [sale_routes.py:26] - Error retrieving sales: type object 'Sale' has no attribute 'created_at'
2025-05-06 16:09:18,301 - app - ERROR - [__init__.py:47] - Unhandled exception: 404 Not Found: The requested URL was not found on the server. If you entered the URL manually please check your spelling and try again.
Traceback (most recent call last):
  File "/Users/guggarisathvik/groundnut_mill/.venv/lib/python3.9/site-packages/flask/app.py", line 917, in full_dispatch_request
    rv = self.dispatch_request()
  File "/Users/guggarisathvik/groundnut_mill/.venv/lib/python3.9/site-packages/flask/app.py", line 902, in dispatch_request
    return self.ensure_sync(self.view_functions[rule.endpoint])(**view_args)  # type: ignore[no-any-return]
  File "/Users/guggarisathvik/groundnut_mill/.venv/lib/python3.9/site-packages/flask/app.py", line 278, in <lambda>
    view_func=lambda **kw: self_ref().send_static_file(**kw),  # type: ignore # noqa: B950
  File "/Users/guggarisathvik/groundnut_mill/.venv/lib/python3.9/site-packages/flask/app.py", line 326, in send_static_file
    return send_from_directory(
  File "/Users/guggarisathvik/groundnut_mill/.venv/lib/python3.9/site-packages/flask/helpers.py", line 565, in send_from_directory
    return werkzeug.utils.send_from_directory(  # type: ignore[return-value]
  File "/Users/guggarisathvik/groundnut_mill/.venv/lib/python3.9/site-packages/werkzeug/utils.py", line 575, in send_from_directory
    raise NotFound()
werkzeug.exceptions.NotFound: 404 Not Found: The requested URL was not found on the server. If you entered the URL manually please check your spelling and try again.
2025-05-06 16:09:18,379 - app - ERROR - [__init__.py:47] - Unhandled exception: 404 Not Found: The requested URL was not found on the server. If you entered the URL manually please check your spelling and try again.
Traceback (most recent call last):
  File "/Users/guggarisathvik/groundnut_mill/.venv/lib/python3.9/site-packages/flask/app.py", line 917, in full_dispatch_request
    rv = self.dispatch_request()
  File "/Users/guggarisathvik/groundnut_mill/.venv/lib/python3.9/site-packages/flask/app.py", line 902, in dispatch_request
    return self.ensure_sync(self.view_functions[rule.endpoint])(**view_args)  # type: ignore[no-any-return]
  File "/Users/guggarisathvik/groundnut_mill/.venv/lib/python3.9/site-packages/flask/app.py", line 278, in <lambda>
    view_func=lambda **kw: self_ref().send_static_file(**kw),  # type: ignore # noqa: B950
  File "/Users/guggarisathvik/groundnut_mill/.venv/lib/python3.9/site-packages/flask/app.py", line 326, in send_static_file
    return send_from_directory(
  File "/Users/guggarisathvik/groundnut_mill/.venv/lib/python3.9/site-packages/flask/helpers.py", line 565, in send_from_directory
    return werkzeug.utils.send_from_directory(  # type: ignore[return-value]
  File "/Users/guggarisathvik/groundnut_mill/.venv/lib/python3.9/site-packages/werkzeug/utils.py", line 575, in send_from_directory
    raise NotFound()
werkzeug.exceptions.NotFound: 404 Not Found: The requested URL was not found on the server. If you entered the URL manually please check your spelling and try again.
2025-05-06 16:09:19,703 - app - ERROR - [__init__.py:47] - Unhandled exception: 404 Not Found: The requested URL was not found on the server. If you entered the URL manually please check your spelling and try again.
Traceback (most recent call last):
  File "/Users/guggarisathvik/groundnut_mill/.venv/lib/python3.9/site-packages/flask/app.py", line 917, in full_dispatch_request
    rv = self.dispatch_request()
  File "/Users/guggarisathvik/groundnut_mill/.venv/lib/python3.9/site-packages/flask/app.py", line 902, in dispatch_request
    return self.ensure_sync(self.view_functions[rule.endpoint])(**view_args)  # type: ignore[no-any-return]
  File "/Users/guggarisathvik/groundnut_mill/.venv/lib/python3.9/site-packages/flask/app.py", line 278, in <lambda>
    view_func=lambda **kw: self_ref().send_static_file(**kw),  # type: ignore # noqa: B950
  File "/Users/guggarisathvik/groundnut_mill/.venv/lib/python3.9/site-packages/flask/app.py", line 326, in send_static_file
    return send_from_directory(
  File "/Users/guggarisathvik/groundnut_mill/.venv/lib/python3.9/site-packages/flask/helpers.py", line 565, in send_from_directory
    return werkzeug.utils.send_from_directory(  # type: ignore[return-value]
  File "/Users/guggarisathvik/groundnut_mill/.venv/lib/python3.9/site-packages/werkzeug/utils.py", line 575, in send_from_directory
    raise NotFound()
werkzeug.exceptions.NotFound: 404 Not Found: The requested URL was not found on the server. If you entered the URL manually please check your spelling and try again.
2025-05-06 16:09:19,753 - app - ERROR - [__init__.py:47] - Unhandled exception: 404 Not Found: The requested URL was not found on the server. If you entered the URL manually please check your spelling and try again.
Traceback (most recent call last):
  File "/Users/guggarisathvik/groundnut_mill/.venv/lib/python3.9/site-packages/flask/app.py", line 917, in full_dispatch_request
    rv = self.dispatch_request()
  File "/Users/guggarisathvik/groundnut_mill/.venv/lib/python3.9/site-packages/flask/app.py", line 902, in dispatch_request
    return self.ensure_sync(self.view_functions[rule.endpoint])(**view_args)  # type: ignore[no-any-return]
  File "/Users/guggarisathvik/groundnut_mill/.venv/lib/python3.9/site-packages/flask/app.py", line 278, in <lambda>
    view_func=lambda **kw: self_ref().send_static_file(**kw),  # type: ignore # noqa: B950
  File "/Users/guggarisathvik/groundnut_mill/.venv/lib/python3.9/site-packages/flask/app.py", line 326, in send_static_file
    return send_from_directory(
  File "/Users/guggarisathvik/groundnut_mill/.venv/lib/python3.9/site-packages/flask/helpers.py", line 565, in send_from_directory
    return werkzeug.utils.send_from_directory(  # type: ignore[return-value]
  File "/Users/guggarisathvik/groundnut_mill/.venv/lib/python3.9/site-packages/werkzeug/utils.py", line 575, in send_from_directory
    raise NotFound()
werkzeug.exceptions.NotFound: 404 Not Found: The requested URL was not found on the server. If you entered the URL manually please check your spelling and try again.
2025-05-06 16:09:21,906 - app - ERROR - [sale_routes.py:26] - Error retrieving sales: type object 'Sale' has no attribute 'created_at'
2025-05-06 16:09:21,910 - app - ERROR - [__init__.py:47] - Unhandled exception: 404 Not Found: The requested URL was not found on the server. If you entered the URL manually please check your spelling and try again.
Traceback (most recent call last):
  File "/Users/guggarisathvik/groundnut_mill/.venv/lib/python3.9/site-packages/flask/app.py", line 917, in full_dispatch_request
    rv = self.dispatch_request()
  File "/Users/guggarisathvik/groundnut_mill/.venv/lib/python3.9/site-packages/flask/app.py", line 902, in dispatch_request
    return self.ensure_sync(self.view_functions[rule.endpoint])(**view_args)  # type: ignore[no-any-return]
  File "/Users/guggarisathvik/groundnut_mill/.venv/lib/python3.9/site-packages/flask/app.py", line 278, in <lambda>
    view_func=lambda **kw: self_ref().send_static_file(**kw),  # type: ignore # noqa: B950
  File "/Users/guggarisathvik/groundnut_mill/.venv/lib/python3.9/site-packages/flask/app.py", line 326, in send_static_file
    return send_from_directory(
  File "/Users/guggarisathvik/groundnut_mill/.venv/lib/python3.9/site-packages/flask/helpers.py", line 565, in send_from_directory
    return werkzeug.utils.send_from_directory(  # type: ignore[return-value]
  File "/Users/guggarisathvik/groundnut_mill/.venv/lib/python3.9/site-packages/werkzeug/utils.py", line 575, in send_from_directory
    raise NotFound()
werkzeug.exceptions.NotFound: 404 Not Found: The requested URL was not found on the server. If you entered the URL manually please check your spelling and try again.
2025-05-06 16:09:21,960 - app - ERROR - [__init__.py:47] - Unhandled exception: 404 Not Found: The requested URL was not found on the server. If you entered the URL manually please check your spelling and try again.
Traceback (most recent call last):
  File "/Users/guggarisathvik/groundnut_mill/.venv/lib/python3.9/site-packages/flask/app.py", line 917, in full_dispatch_request
    rv = self.dispatch_request()
  File "/Users/guggarisathvik/groundnut_mill/.venv/lib/python3.9/site-packages/flask/app.py", line 902, in dispatch_request
    return self.ensure_sync(self.view_functions[rule.endpoint])(**view_args)  # type: ignore[no-any-return]
  File "/Users/guggarisathvik/groundnut_mill/.venv/lib/python3.9/site-packages/flask/app.py", line 278, in <lambda>
    view_func=lambda **kw: self_ref().send_static_file(**kw),  # type: ignore # noqa: B950
  File "/Users/guggarisathvik/groundnut_mill/.venv/lib/python3.9/site-packages/flask/app.py", line 326, in send_static_file
    return send_from_directory(
  File "/Users/guggarisathvik/groundnut_mill/.venv/lib/python3.9/site-packages/flask/helpers.py", line 565, in send_from_directory
    return werkzeug.utils.send_from_directory(  # type: ignore[return-value]
  File "/Users/guggarisathvik/groundnut_mill/.venv/lib/python3.9/site-packages/werkzeug/utils.py", line 575, in send_from_directory
    raise NotFound()
werkzeug.exceptions.NotFound: 404 Not Found: The requested URL was not found on the server. If you entered the URL manually please check your spelling and try again.
2025-05-06 16:09:24,270 - app - ERROR - [__init__.py:47] - Unhandled exception: 404 Not Found: The requested URL was not found on the server. If you entered the URL manually please check your spelling and try again.
Traceback (most recent call last):
  File "/Users/guggarisathvik/groundnut_mill/.venv/lib/python3.9/site-packages/flask/app.py", line 917, in full_dispatch_request
    rv = self.dispatch_request()
  File "/Users/guggarisathvik/groundnut_mill/.venv/lib/python3.9/site-packages/flask/app.py", line 902, in dispatch_request
    return self.ensure_sync(self.view_functions[rule.endpoint])(**view_args)  # type: ignore[no-any-return]
  File "/Users/guggarisathvik/groundnut_mill/.venv/lib/python3.9/site-packages/flask/app.py", line 278, in <lambda>
    view_func=lambda **kw: self_ref().send_static_file(**kw),  # type: ignore # noqa: B950
  File "/Users/guggarisathvik/groundnut_mill/.venv/lib/python3.9/site-packages/flask/app.py", line 326, in send_static_file
    return send_from_directory(
  File "/Users/guggarisathvik/groundnut_mill/.venv/lib/python3.9/site-packages/flask/helpers.py", line 565, in send_from_directory
    return werkzeug.utils.send_from_directory(  # type: ignore[return-value]
  File "/Users/guggarisathvik/groundnut_mill/.venv/lib/python3.9/site-packages/werkzeug/utils.py", line 575, in send_from_directory
    raise NotFound()
werkzeug.exceptions.NotFound: 404 Not Found: The requested URL was not found on the server. If you entered the URL manually please check your spelling and try again.
2025-05-06 16:09:24,324 - app - ERROR - [__init__.py:47] - Unhandled exception: 404 Not Found: The requested URL was not found on the server. If you entered the URL manually please check your spelling and try again.
Traceback (most recent call last):
  File "/Users/guggarisathvik/groundnut_mill/.venv/lib/python3.9/site-packages/flask/app.py", line 917, in full_dispatch_request
    rv = self.dispatch_request()
  File "/Users/guggarisathvik/groundnut_mill/.venv/lib/python3.9/site-packages/flask/app.py", line 902, in dispatch_request
    return self.ensure_sync(self.view_functions[rule.endpoint])(**view_args)  # type: ignore[no-any-return]
  File "/Users/guggarisathvik/groundnut_mill/.venv/lib/python3.9/site-packages/flask/app.py", line 278, in <lambda>
    view_func=lambda **kw: self_ref().send_static_file(**kw),  # type: ignore # noqa: B950
  File "/Users/guggarisathvik/groundnut_mill/.venv/lib/python3.9/site-packages/flask/app.py", line 326, in send_static_file
    return send_from_directory(
  File "/Users/guggarisathvik/groundnut_mill/.venv/lib/python3.9/site-packages/flask/helpers.py", line 565, in send_from_directory
    return werkzeug.utils.send_from_directory(  # type: ignore[return-value]
  File "/Users/guggarisathvik/groundnut_mill/.venv/lib/python3.9/site-packages/werkzeug/utils.py", line 575, in send_from_directory
    raise NotFound()
werkzeug.exceptions.NotFound: 404 Not Found: The requested URL was not found on the server. If you entered the URL manually please check your spelling and try again.
2025-05-06 16:09:26,774 - app - ERROR - [sale_routes.py:26] - Error retrieving sales: type object 'Sale' has no attribute 'created_at'
2025-05-06 16:09:26,778 - app - ERROR - [__init__.py:47] - Unhandled exception: 404 Not Found: The requested URL was not found on the server. If you entered the URL manually please check your spelling and try again.
Traceback (most recent call last):
  File "/Users/guggarisathvik/groundnut_mill/.venv/lib/python3.9/site-packages/flask/app.py", line 917, in full_dispatch_request
    rv = self.dispatch_request()
  File "/Users/guggarisathvik/groundnut_mill/.venv/lib/python3.9/site-packages/flask/app.py", line 902, in dispatch_request
    return self.ensure_sync(self.view_functions[rule.endpoint])(**view_args)  # type: ignore[no-any-return]
  File "/Users/guggarisathvik/groundnut_mill/.venv/lib/python3.9/site-packages/flask/app.py", line 278, in <lambda>
    view_func=lambda **kw: self_ref().send_static_file(**kw),  # type: ignore # noqa: B950
  File "/Users/guggarisathvik/groundnut_mill/.venv/lib/python3.9/site-packages/flask/app.py", line 326, in send_static_file
    return send_from_directory(
  File "/Users/guggarisathvik/groundnut_mill/.venv/lib/python3.9/site-packages/flask/helpers.py", line 565, in send_from_directory
    return werkzeug.utils.send_from_directory(  # type: ignore[return-value]
  File "/Users/guggarisathvik/groundnut_mill/.venv/lib/python3.9/site-packages/werkzeug/utils.py", line 575, in send_from_directory
    raise NotFound()
werkzeug.exceptions.NotFound: 404 Not Found: The requested URL was not found on the server. If you entered the URL manually please check your spelling and try again.
2025-05-06 16:09:26,840 - app - ERROR - [__init__.py:47] - Unhandled exception: 404 Not Found: The requested URL was not found on the server. If you entered the URL manually please check your spelling and try again.
Traceback (most recent call last):
  File "/Users/guggarisathvik/groundnut_mill/.venv/lib/python3.9/site-packages/flask/app.py", line 917, in full_dispatch_request
    rv = self.dispatch_request()
  File "/Users/guggarisathvik/groundnut_mill/.venv/lib/python3.9/site-packages/flask/app.py", line 902, in dispatch_request
    return self.ensure_sync(self.view_functions[rule.endpoint])(**view_args)  # type: ignore[no-any-return]
  File "/Users/guggarisathvik/groundnut_mill/.venv/lib/python3.9/site-packages/flask/app.py", line 278, in <lambda>
    view_func=lambda **kw: self_ref().send_static_file(**kw),  # type: ignore # noqa: B950
  File "/Users/guggarisathvik/groundnut_mill/.venv/lib/python3.9/site-packages/flask/app.py", line 326, in send_static_file
    return send_from_directory(
  File "/Users/guggarisathvik/groundnut_mill/.venv/lib/python3.9/site-packages/flask/helpers.py", line 565, in send_from_directory
    return werkzeug.utils.send_from_directory(  # type: ignore[return-value]
  File "/Users/guggarisathvik/groundnut_mill/.venv/lib/python3.9/site-packages/werkzeug/utils.py", line 575, in send_from_directory
    raise NotFound()
werkzeug.exceptions.NotFound: 404 Not Found: The requested URL was not found on the server. If you entered the URL manually please check your spelling and try again.
2025-05-06 16:09:29,369 - app - ERROR - [__init__.py:47] - Unhandled exception: 404 Not Found: The requested URL was not found on the server. If you entered the URL manually please check your spelling and try again.
Traceback (most recent call last):
  File "/Users/guggarisathvik/groundnut_mill/.venv/lib/python3.9/site-packages/flask/app.py", line 917, in full_dispatch_request
    rv = self.dispatch_request()
  File "/Users/guggarisathvik/groundnut_mill/.venv/lib/python3.9/site-packages/flask/app.py", line 902, in dispatch_request
    return self.ensure_sync(self.view_functions[rule.endpoint])(**view_args)  # type: ignore[no-any-return]
  File "/Users/guggarisathvik/groundnut_mill/.venv/lib/python3.9/site-packages/flask/app.py", line 278, in <lambda>
    view_func=lambda **kw: self_ref().send_static_file(**kw),  # type: ignore # noqa: B950
  File "/Users/guggarisathvik/groundnut_mill/.venv/lib/python3.9/site-packages/flask/app.py", line 326, in send_static_file
    return send_from_directory(
  File "/Users/guggarisathvik/groundnut_mill/.venv/lib/python3.9/site-packages/flask/helpers.py", line 565, in send_from_directory
    return werkzeug.utils.send_from_directory(  # type: ignore[return-value]
  File "/Users/guggarisathvik/groundnut_mill/.venv/lib/python3.9/site-packages/werkzeug/utils.py", line 575, in send_from_directory
    raise NotFound()
werkzeug.exceptions.NotFound: 404 Not Found: The requested URL was not found on the server. If you entered the URL manually please check your spelling and try again.
2025-05-06 16:09:29,426 - app - ERROR - [__init__.py:47] - Unhandled exception: 404 Not Found: The requested URL was not found on the server. If you entered the URL manually please check your spelling and try again.
Traceback (most recent call last):
  File "/Users/guggarisathvik/groundnut_mill/.venv/lib/python3.9/site-packages/flask/app.py", line 917, in full_dispatch_request
    rv = self.dispatch_request()
  File "/Users/guggarisathvik/groundnut_mill/.venv/lib/python3.9/site-packages/flask/app.py", line 902, in dispatch_request
    return self.ensure_sync(self.view_functions[rule.endpoint])(**view_args)  # type: ignore[no-any-return]
  File "/Users/guggarisathvik/groundnut_mill/.venv/lib/python3.9/site-packages/flask/app.py", line 278, in <lambda>
    view_func=lambda **kw: self_ref().send_static_file(**kw),  # type: ignore # noqa: B950
  File "/Users/guggarisathvik/groundnut_mill/.venv/lib/python3.9/site-packages/flask/app.py", line 326, in send_static_file
    return send_from_directory(
  File "/Users/guggarisathvik/groundnut_mill/.venv/lib/python3.9/site-packages/flask/helpers.py", line 565, in send_from_directory
    return werkzeug.utils.send_from_directory(  # type: ignore[return-value]
  File "/Users/guggarisathvik/groundnut_mill/.venv/lib/python3.9/site-packages/werkzeug/utils.py", line 575, in send_from_directory
    raise NotFound()
werkzeug.exceptions.NotFound: 404 Not Found: The requested URL was not found on the server. If you entered the URL manually please check your spelling and try again.
2025-05-06 16:10:08,387 - app - ERROR - [sale_routes.py:26] - Error retrieving sales: type object 'Sale' has no attribute 'created_at'
2025-05-06 16:10:08,391 - app - ERROR - [__init__.py:47] - Unhandled exception: 404 Not Found: The requested URL was not found on the server. If you entered the URL manually please check your spelling and try again.
Traceback (most recent call last):
  File "/Users/guggarisathvik/groundnut_mill/.venv/lib/python3.9/site-packages/flask/app.py", line 917, in full_dispatch_request
    rv = self.dispatch_request()
  File "/Users/guggarisathvik/groundnut_mill/.venv/lib/python3.9/site-packages/flask/app.py", line 902, in dispatch_request
    return self.ensure_sync(self.view_functions[rule.endpoint])(**view_args)  # type: ignore[no-any-return]
  File "/Users/guggarisathvik/groundnut_mill/.venv/lib/python3.9/site-packages/flask/app.py", line 278, in <lambda>
    view_func=lambda **kw: self_ref().send_static_file(**kw),  # type: ignore # noqa: B950
  File "/Users/guggarisathvik/groundnut_mill/.venv/lib/python3.9/site-packages/flask/app.py", line 326, in send_static_file
    return send_from_directory(
  File "/Users/guggarisathvik/groundnut_mill/.venv/lib/python3.9/site-packages/flask/helpers.py", line 565, in send_from_directory
    return werkzeug.utils.send_from_directory(  # type: ignore[return-value]
  File "/Users/guggarisathvik/groundnut_mill/.venv/lib/python3.9/site-packages/werkzeug/utils.py", line 575, in send_from_directory
    raise NotFound()
werkzeug.exceptions.NotFound: 404 Not Found: The requested URL was not found on the server. If you entered the URL manually please check your spelling and try again.
2025-05-06 16:10:08,437 - app - ERROR - [__init__.py:47] - Unhandled exception: 404 Not Found: The requested URL was not found on the server. If you entered the URL manually please check your spelling and try again.
Traceback (most recent call last):
  File "/Users/guggarisathvik/groundnut_mill/.venv/lib/python3.9/site-packages/flask/app.py", line 917, in full_dispatch_request
    rv = self.dispatch_request()
  File "/Users/guggarisathvik/groundnut_mill/.venv/lib/python3.9/site-packages/flask/app.py", line 902, in dispatch_request
    return self.ensure_sync(self.view_functions[rule.endpoint])(**view_args)  # type: ignore[no-any-return]
  File "/Users/guggarisathvik/groundnut_mill/.venv/lib/python3.9/site-packages/flask/app.py", line 278, in <lambda>
    view_func=lambda **kw: self_ref().send_static_file(**kw),  # type: ignore # noqa: B950
  File "/Users/guggarisathvik/groundnut_mill/.venv/lib/python3.9/site-packages/flask/app.py", line 326, in send_static_file
    return send_from_directory(
  File "/Users/guggarisathvik/groundnut_mill/.venv/lib/python3.9/site-packages/flask/helpers.py", line 565, in send_from_directory
    return werkzeug.utils.send_from_directory(  # type: ignore[return-value]
  File "/Users/guggarisathvik/groundnut_mill/.venv/lib/python3.9/site-packages/werkzeug/utils.py", line 575, in send_from_directory
    raise NotFound()
werkzeug.exceptions.NotFound: 404 Not Found: The requested URL was not found on the server. If you entered the URL manually please check your spelling and try again.
2025-05-06 16:10:09,652 - app - ERROR - [__init__.py:47] - Unhandled exception: 404 Not Found: The requested URL was not found on the server. If you entered the URL manually please check your spelling and try again.
Traceback (most recent call last):
  File "/Users/guggarisathvik/groundnut_mill/.venv/lib/python3.9/site-packages/flask/app.py", line 917, in full_dispatch_request
    rv = self.dispatch_request()
  File "/Users/guggarisathvik/groundnut_mill/.venv/lib/python3.9/site-packages/flask/app.py", line 902, in dispatch_request
    return self.ensure_sync(self.view_functions[rule.endpoint])(**view_args)  # type: ignore[no-any-return]
  File "/Users/guggarisathvik/groundnut_mill/.venv/lib/python3.9/site-packages/flask/app.py", line 278, in <lambda>
    view_func=lambda **kw: self_ref().send_static_file(**kw),  # type: ignore # noqa: B950
  File "/Users/guggarisathvik/groundnut_mill/.venv/lib/python3.9/site-packages/flask/app.py", line 326, in send_static_file
    return send_from_directory(
  File "/Users/guggarisathvik/groundnut_mill/.venv/lib/python3.9/site-packages/flask/helpers.py", line 565, in send_from_directory
    return werkzeug.utils.send_from_directory(  # type: ignore[return-value]
  File "/Users/guggarisathvik/groundnut_mill/.venv/lib/python3.9/site-packages/werkzeug/utils.py", line 575, in send_from_directory
    raise NotFound()
werkzeug.exceptions.NotFound: 404 Not Found: The requested URL was not found on the server. If you entered the URL manually please check your spelling and try again.
2025-05-06 16:10:17,400 - app - ERROR - [sale_routes.py:26] - Error retrieving sales: type object 'Sale' has no attribute 'created_at'
2025-05-06 16:10:17,404 - app - ERROR - [__init__.py:47] - Unhandled exception: 404 Not Found: The requested URL was not found on the server. If you entered the URL manually please check your spelling and try again.
Traceback (most recent call last):
  File "/Users/guggarisathvik/groundnut_mill/.venv/lib/python3.9/site-packages/flask/app.py", line 917, in full_dispatch_request
    rv = self.dispatch_request()
  File "/Users/guggarisathvik/groundnut_mill/.venv/lib/python3.9/site-packages/flask/app.py", line 902, in dispatch_request
    return self.ensure_sync(self.view_functions[rule.endpoint])(**view_args)  # type: ignore[no-any-return]
  File "/Users/guggarisathvik/groundnut_mill/.venv/lib/python3.9/site-packages/flask/app.py", line 278, in <lambda>
    view_func=lambda **kw: self_ref().send_static_file(**kw),  # type: ignore # noqa: B950
  File "/Users/guggarisathvik/groundnut_mill/.venv/lib/python3.9/site-packages/flask/app.py", line 326, in send_static_file
    return send_from_directory(
  File "/Users/guggarisathvik/groundnut_mill/.venv/lib/python3.9/site-packages/flask/helpers.py", line 565, in send_from_directory
    return werkzeug.utils.send_from_directory(  # type: ignore[return-value]
  File "/Users/guggarisathvik/groundnut_mill/.venv/lib/python3.9/site-packages/werkzeug/utils.py", line 575, in send_from_directory
    raise NotFound()
werkzeug.exceptions.NotFound: 404 Not Found: The requested URL was not found on the server. If you entered the URL manually please check your spelling and try again.
2025-05-06 16:10:17,451 - app - ERROR - [__init__.py:47] - Unhandled exception: 404 Not Found: The requested URL was not found on the server. If you entered the URL manually please check your spelling and try again.
Traceback (most recent call last):
  File "/Users/guggarisathvik/groundnut_mill/.venv/lib/python3.9/site-packages/flask/app.py", line 917, in full_dispatch_request
    rv = self.dispatch_request()
  File "/Users/guggarisathvik/groundnut_mill/.venv/lib/python3.9/site-packages/flask/app.py", line 902, in dispatch_request
    return self.ensure_sync(self.view_functions[rule.endpoint])(**view_args)  # type: ignore[no-any-return]
  File "/Users/guggarisathvik/groundnut_mill/.venv/lib/python3.9/site-packages/flask/app.py", line 278, in <lambda>
    view_func=lambda **kw: self_ref().send_static_file(**kw),  # type: ignore # noqa: B950
  File "/Users/guggarisathvik/groundnut_mill/.venv/lib/python3.9/site-packages/flask/app.py", line 326, in send_static_file
    return send_from_directory(
  File "/Users/guggarisathvik/groundnut_mill/.venv/lib/python3.9/site-packages/flask/helpers.py", line 565, in send_from_directory
    return werkzeug.utils.send_from_directory(  # type: ignore[return-value]
  File "/Users/guggarisathvik/groundnut_mill/.venv/lib/python3.9/site-packages/werkzeug/utils.py", line 575, in send_from_directory
    raise NotFound()
werkzeug.exceptions.NotFound: 404 Not Found: The requested URL was not found on the server. If you entered the URL manually please check your spelling and try again.
2025-05-06 16:10:54,392 - app - ERROR - [sale_routes.py:26] - Error retrieving sales: type object 'Sale' has no attribute 'created_at'
2025-05-06 16:10:54,397 - app - ERROR - [__init__.py:47] - Unhandled exception: 404 Not Found: The requested URL was not found on the server. If you entered the URL manually please check your spelling and try again.
Traceback (most recent call last):
  File "/Users/guggarisathvik/groundnut_mill/.venv/lib/python3.9/site-packages/flask/app.py", line 917, in full_dispatch_request
    rv = self.dispatch_request()
  File "/Users/guggarisathvik/groundnut_mill/.venv/lib/python3.9/site-packages/flask/app.py", line 902, in dispatch_request
    return self.ensure_sync(self.view_functions[rule.endpoint])(**view_args)  # type: ignore[no-any-return]
  File "/Users/guggarisathvik/groundnut_mill/.venv/lib/python3.9/site-packages/flask/app.py", line 278, in <lambda>
    view_func=lambda **kw: self_ref().send_static_file(**kw),  # type: ignore # noqa: B950
  File "/Users/guggarisathvik/groundnut_mill/.venv/lib/python3.9/site-packages/flask/app.py", line 326, in send_static_file
    return send_from_directory(
  File "/Users/guggarisathvik/groundnut_mill/.venv/lib/python3.9/site-packages/flask/helpers.py", line 565, in send_from_directory
    return werkzeug.utils.send_from_directory(  # type: ignore[return-value]
  File "/Users/guggarisathvik/groundnut_mill/.venv/lib/python3.9/site-packages/werkzeug/utils.py", line 575, in send_from_directory
    raise NotFound()
werkzeug.exceptions.NotFound: 404 Not Found: The requested URL was not found on the server. If you entered the URL manually please check your spelling and try again.
2025-05-06 16:10:54,439 - app - ERROR - [__init__.py:47] - Unhandled exception: 404 Not Found: The requested URL was not found on the server. If you entered the URL manually please check your spelling and try again.
Traceback (most recent call last):
  File "/Users/guggarisathvik/groundnut_mill/.venv/lib/python3.9/site-packages/flask/app.py", line 917, in full_dispatch_request
    rv = self.dispatch_request()
  File "/Users/guggarisathvik/groundnut_mill/.venv/lib/python3.9/site-packages/flask/app.py", line 902, in dispatch_request
    return self.ensure_sync(self.view_functions[rule.endpoint])(**view_args)  # type: ignore[no-any-return]
  File "/Users/guggarisathvik/groundnut_mill/.venv/lib/python3.9/site-packages/flask/app.py", line 278, in <lambda>
    view_func=lambda **kw: self_ref().send_static_file(**kw),  # type: ignore # noqa: B950
  File "/Users/guggarisathvik/groundnut_mill/.venv/lib/python3.9/site-packages/flask/app.py", line 326, in send_static_file
    return send_from_directory(
  File "/Users/guggarisathvik/groundnut_mill/.venv/lib/python3.9/site-packages/flask/helpers.py", line 565, in send_from_directory
    return werkzeug.utils.send_from_directory(  # type: ignore[return-value]
  File "/Users/guggarisathvik/groundnut_mill/.venv/lib/python3.9/site-packages/werkzeug/utils.py", line 575, in send_from_directory
    raise NotFound()
werkzeug.exceptions.NotFound: 404 Not Found: The requested URL was not found on the server. If you entered the URL manually please check your spelling and try again.
2025-05-06 16:13:02,635 - flask-app - INFO - [__init__.py:22] - Starting Flask application...
2025-05-06 16:13:05,234 - app - ERROR - [sale_routes.py:26] - Error retrieving sales: name 'sales' is not defined
2025-05-06 16:13:05,305 - app - ERROR - [__init__.py:47] - Unhandled exception: 404 Not Found: The requested URL was not found on the server. If you entered the URL manually please check your spelling and try again.
Traceback (most recent call last):
  File "/Users/guggarisathvik/groundnut_mill/.venv/lib/python3.9/site-packages/flask/app.py", line 917, in full_dispatch_request
    rv = self.dispatch_request()
  File "/Users/guggarisathvik/groundnut_mill/.venv/lib/python3.9/site-packages/flask/app.py", line 902, in dispatch_request
    return self.ensure_sync(self.view_functions[rule.endpoint])(**view_args)  # type: ignore[no-any-return]
  File "/Users/guggarisathvik/groundnut_mill/.venv/lib/python3.9/site-packages/flask/app.py", line 278, in <lambda>
    view_func=lambda **kw: self_ref().send_static_file(**kw),  # type: ignore # noqa: B950
  File "/Users/guggarisathvik/groundnut_mill/.venv/lib/python3.9/site-packages/flask/app.py", line 326, in send_static_file
    return send_from_directory(
  File "/Users/guggarisathvik/groundnut_mill/.venv/lib/python3.9/site-packages/flask/helpers.py", line 565, in send_from_directory
    return werkzeug.utils.send_from_directory(  # type: ignore[return-value]
  File "/Users/guggarisathvik/groundnut_mill/.venv/lib/python3.9/site-packages/werkzeug/utils.py", line 575, in send_from_directory
    raise NotFound()
werkzeug.exceptions.NotFound: 404 Not Found: The requested URL was not found on the server. If you entered the URL manually please check your spelling and try again.
2025-05-06 16:13:07,499 - app - ERROR - [sale_routes.py:26] - Error retrieving sales: name 'sales' is not defined
2025-05-06 16:13:07,548 - app - ERROR - [__init__.py:47] - Unhandled exception: 404 Not Found: The requested URL was not found on the server. If you entered the URL manually please check your spelling and try again.
Traceback (most recent call last):
  File "/Users/guggarisathvik/groundnut_mill/.venv/lib/python3.9/site-packages/flask/app.py", line 917, in full_dispatch_request
    rv = self.dispatch_request()
  File "/Users/guggarisathvik/groundnut_mill/.venv/lib/python3.9/site-packages/flask/app.py", line 902, in dispatch_request
    return self.ensure_sync(self.view_functions[rule.endpoint])(**view_args)  # type: ignore[no-any-return]
  File "/Users/guggarisathvik/groundnut_mill/.venv/lib/python3.9/site-packages/flask/app.py", line 278, in <lambda>
    view_func=lambda **kw: self_ref().send_static_file(**kw),  # type: ignore # noqa: B950
  File "/Users/guggarisathvik/groundnut_mill/.venv/lib/python3.9/site-packages/flask/app.py", line 326, in send_static_file
    return send_from_directory(
  File "/Users/guggarisathvik/groundnut_mill/.venv/lib/python3.9/site-packages/flask/helpers.py", line 565, in send_from_directory
    return werkzeug.utils.send_from_directory(  # type: ignore[return-value]
  File "/Users/guggarisathvik/groundnut_mill/.venv/lib/python3.9/site-packages/werkzeug/utils.py", line 575, in send_from_directory
    raise NotFound()
werkzeug.exceptions.NotFound: 404 Not Found: The requested URL was not found on the server. If you entered the URL manually please check your spelling and try again.
2025-05-06 16:13:41,782 - flask-app - INFO - [__init__.py:22] - Starting Flask application...
2025-05-06 16:13:45,318 - app - ERROR - [__init__.py:47] - Unhandled exception: 404 Not Found: The requested URL was not found on the server. If you entered the URL manually please check your spelling and try again.
Traceback (most recent call last):
  File "/Users/guggarisathvik/groundnut_mill/.venv/lib/python3.9/site-packages/flask/app.py", line 917, in full_dispatch_request
    rv = self.dispatch_request()
  File "/Users/guggarisathvik/groundnut_mill/.venv/lib/python3.9/site-packages/flask/app.py", line 902, in dispatch_request
    return self.ensure_sync(self.view_functions[rule.endpoint])(**view_args)  # type: ignore[no-any-return]
  File "/Users/guggarisathvik/groundnut_mill/.venv/lib/python3.9/site-packages/flask/app.py", line 278, in <lambda>
    view_func=lambda **kw: self_ref().send_static_file(**kw),  # type: ignore # noqa: B950
  File "/Users/guggarisathvik/groundnut_mill/.venv/lib/python3.9/site-packages/flask/app.py", line 326, in send_static_file
    return send_from_directory(
  File "/Users/guggarisathvik/groundnut_mill/.venv/lib/python3.9/site-packages/flask/helpers.py", line 565, in send_from_directory
    return werkzeug.utils.send_from_directory(  # type: ignore[return-value]
  File "/Users/guggarisathvik/groundnut_mill/.venv/lib/python3.9/site-packages/werkzeug/utils.py", line 575, in send_from_directory
    raise NotFound()
werkzeug.exceptions.NotFound: 404 Not Found: The requested URL was not found on the server. If you entered the URL manually please check your spelling and try again.
2025-05-06 16:14:17,846 - flask-app - INFO - [__init__.py:22] - Starting Flask application...
2025-05-06 16:14:47,919 - flask-app - INFO - [__init__.py:22] - Starting Flask application...
2025-05-06 16:16:09,101 - flask-app - INFO - [__init__.py:22] - Starting Flask application...
2025-05-06 16:23:51,648 - flask-app - INFO - [__init__.py:22] - Starting Flask application...
2025-05-06 16:24:47,959 - flask-app - INFO - [__init__.py:22] - Starting Flask application...
2025-05-06 16:42:39,493 - flask-app - INFO - [__init__.py:22] - Starting Flask application...
2025-05-06 16:42:40,202 - flask-app - INFO - [__init__.py:22] - Starting Flask application...
2025-05-06 16:42:42,847 - app - ERROR - [__init__.py:47] - Unhandled exception: 404 Not Found: The requested URL was not found on the server. If you entered the URL manually please check your spelling and try again.
Traceback (most recent call last):
  File "/Users/guggarisathvik/groundnut_mill/.venv/lib/python3.9/site-packages/flask/app.py", line 917, in full_dispatch_request
    rv = self.dispatch_request()
  File "/Users/guggarisathvik/groundnut_mill/.venv/lib/python3.9/site-packages/flask/app.py", line 902, in dispatch_request
    return self.ensure_sync(self.view_functions[rule.endpoint])(**view_args)  # type: ignore[no-any-return]
  File "/Users/guggarisathvik/groundnut_mill/.venv/lib/python3.9/site-packages/flask/app.py", line 278, in <lambda>
    view_func=lambda **kw: self_ref().send_static_file(**kw),  # type: ignore # noqa: B950
  File "/Users/guggarisathvik/groundnut_mill/.venv/lib/python3.9/site-packages/flask/app.py", line 326, in send_static_file
    return send_from_directory(
  File "/Users/guggarisathvik/groundnut_mill/.venv/lib/python3.9/site-packages/flask/helpers.py", line 565, in send_from_directory
    return werkzeug.utils.send_from_directory(  # type: ignore[return-value]
  File "/Users/guggarisathvik/groundnut_mill/.venv/lib/python3.9/site-packages/werkzeug/utils.py", line 575, in send_from_directory
    raise NotFound()
werkzeug.exceptions.NotFound: 404 Not Found: The requested URL was not found on the server. If you entered the URL manually please check your spelling and try again.
2025-05-06 16:42:42,978 - app - ERROR - [__init__.py:47] - Unhandled exception: 404 Not Found: The requested URL was not found on the server. If you entered the URL manually please check your spelling and try again.
Traceback (most recent call last):
  File "/Users/guggarisathvik/groundnut_mill/.venv/lib/python3.9/site-packages/flask/app.py", line 917, in full_dispatch_request
    rv = self.dispatch_request()
  File "/Users/guggarisathvik/groundnut_mill/.venv/lib/python3.9/site-packages/flask/app.py", line 902, in dispatch_request
    return self.ensure_sync(self.view_functions[rule.endpoint])(**view_args)  # type: ignore[no-any-return]
  File "/Users/guggarisathvik/groundnut_mill/.venv/lib/python3.9/site-packages/flask/app.py", line 278, in <lambda>
    view_func=lambda **kw: self_ref().send_static_file(**kw),  # type: ignore # noqa: B950
  File "/Users/guggarisathvik/groundnut_mill/.venv/lib/python3.9/site-packages/flask/app.py", line 326, in send_static_file
    return send_from_directory(
  File "/Users/guggarisathvik/groundnut_mill/.venv/lib/python3.9/site-packages/flask/helpers.py", line 565, in send_from_directory
    return werkzeug.utils.send_from_directory(  # type: ignore[return-value]
  File "/Users/guggarisathvik/groundnut_mill/.venv/lib/python3.9/site-packages/werkzeug/utils.py", line 575, in send_from_directory
    raise NotFound()
werkzeug.exceptions.NotFound: 404 Not Found: The requested URL was not found on the server. If you entered the URL manually please check your spelling and try again.
2025-05-06 16:42:44,180 - app - ERROR - [__init__.py:47] - Unhandled exception: 404 Not Found: The requested URL was not found on the server. If you entered the URL manually please check your spelling and try again.
Traceback (most recent call last):
  File "/Users/guggarisathvik/groundnut_mill/.venv/lib/python3.9/site-packages/flask/app.py", line 917, in full_dispatch_request
    rv = self.dispatch_request()
  File "/Users/guggarisathvik/groundnut_mill/.venv/lib/python3.9/site-packages/flask/app.py", line 902, in dispatch_request
    return self.ensure_sync(self.view_functions[rule.endpoint])(**view_args)  # type: ignore[no-any-return]
  File "/Users/guggarisathvik/groundnut_mill/.venv/lib/python3.9/site-packages/flask/app.py", line 278, in <lambda>
    view_func=lambda **kw: self_ref().send_static_file(**kw),  # type: ignore # noqa: B950
  File "/Users/guggarisathvik/groundnut_mill/.venv/lib/python3.9/site-packages/flask/app.py", line 326, in send_static_file
    return send_from_directory(
  File "/Users/guggarisathvik/groundnut_mill/.venv/lib/python3.9/site-packages/flask/helpers.py", line 565, in send_from_directory
    return werkzeug.utils.send_from_directory(  # type: ignore[return-value]
  File "/Users/guggarisathvik/groundnut_mill/.venv/lib/python3.9/site-packages/werkzeug/utils.py", line 575, in send_from_directory
    raise NotFound()
werkzeug.exceptions.NotFound: 404 Not Found: The requested URL was not found on the server. If you entered the URL manually please check your spelling and try again.
2025-05-06 16:42:44,233 - app - ERROR - [__init__.py:47] - Unhandled exception: 404 Not Found: The requested URL was not found on the server. If you entered the URL manually please check your spelling and try again.
Traceback (most recent call last):
  File "/Users/guggarisathvik/groundnut_mill/.venv/lib/python3.9/site-packages/flask/app.py", line 917, in full_dispatch_request
    rv = self.dispatch_request()
  File "/Users/guggarisathvik/groundnut_mill/.venv/lib/python3.9/site-packages/flask/app.py", line 902, in dispatch_request
    return self.ensure_sync(self.view_functions[rule.endpoint])(**view_args)  # type: ignore[no-any-return]
  File "/Users/guggarisathvik/groundnut_mill/.venv/lib/python3.9/site-packages/flask/app.py", line 278, in <lambda>
    view_func=lambda **kw: self_ref().send_static_file(**kw),  # type: ignore # noqa: B950
  File "/Users/guggarisathvik/groundnut_mill/.venv/lib/python3.9/site-packages/flask/app.py", line 326, in send_static_file
    return send_from_directory(
  File "/Users/guggarisathvik/groundnut_mill/.venv/lib/python3.9/site-packages/flask/helpers.py", line 565, in send_from_directory
    return werkzeug.utils.send_from_directory(  # type: ignore[return-value]
  File "/Users/guggarisathvik/groundnut_mill/.venv/lib/python3.9/site-packages/werkzeug/utils.py", line 575, in send_from_directory
    raise NotFound()
werkzeug.exceptions.NotFound: 404 Not Found: The requested URL was not found on the server. If you entered the URL manually please check your spelling and try again.
2025-05-06 16:42:46,004 - app - ERROR - [__init__.py:47] - Unhandled exception: 404 Not Found: The requested URL was not found on the server. If you entered the URL manually please check your spelling and try again.
Traceback (most recent call last):
  File "/Users/guggarisathvik/groundnut_mill/.venv/lib/python3.9/site-packages/flask/app.py", line 917, in full_dispatch_request
    rv = self.dispatch_request()
  File "/Users/guggarisathvik/groundnut_mill/.venv/lib/python3.9/site-packages/flask/app.py", line 902, in dispatch_request
    return self.ensure_sync(self.view_functions[rule.endpoint])(**view_args)  # type: ignore[no-any-return]
  File "/Users/guggarisathvik/groundnut_mill/.venv/lib/python3.9/site-packages/flask/app.py", line 278, in <lambda>
    view_func=lambda **kw: self_ref().send_static_file(**kw),  # type: ignore # noqa: B950
  File "/Users/guggarisathvik/groundnut_mill/.venv/lib/python3.9/site-packages/flask/app.py", line 326, in send_static_file
    return send_from_directory(
  File "/Users/guggarisathvik/groundnut_mill/.venv/lib/python3.9/site-packages/flask/helpers.py", line 565, in send_from_directory
    return werkzeug.utils.send_from_directory(  # type: ignore[return-value]
  File "/Users/guggarisathvik/groundnut_mill/.venv/lib/python3.9/site-packages/werkzeug/utils.py", line 575, in send_from_directory
    raise NotFound()
werkzeug.exceptions.NotFound: 404 Not Found: The requested URL was not found on the server. If you entered the URL manually please check your spelling and try again.
2025-05-06 16:42:46,065 - app - ERROR - [__init__.py:47] - Unhandled exception: 404 Not Found: The requested URL was not found on the server. If you entered the URL manually please check your spelling and try again.
Traceback (most recent call last):
  File "/Users/guggarisathvik/groundnut_mill/.venv/lib/python3.9/site-packages/flask/app.py", line 917, in full_dispatch_request
    rv = self.dispatch_request()
  File "/Users/guggarisathvik/groundnut_mill/.venv/lib/python3.9/site-packages/flask/app.py", line 902, in dispatch_request
    return self.ensure_sync(self.view_functions[rule.endpoint])(**view_args)  # type: ignore[no-any-return]
  File "/Users/guggarisathvik/groundnut_mill/.venv/lib/python3.9/site-packages/flask/app.py", line 278, in <lambda>
    view_func=lambda **kw: self_ref().send_static_file(**kw),  # type: ignore # noqa: B950
  File "/Users/guggarisathvik/groundnut_mill/.venv/lib/python3.9/site-packages/flask/app.py", line 326, in send_static_file
    return send_from_directory(
  File "/Users/guggarisathvik/groundnut_mill/.venv/lib/python3.9/site-packages/flask/helpers.py", line 565, in send_from_directory
    return werkzeug.utils.send_from_directory(  # type: ignore[return-value]
  File "/Users/guggarisathvik/groundnut_mill/.venv/lib/python3.9/site-packages/werkzeug/utils.py", line 575, in send_from_directory
    raise NotFound()
werkzeug.exceptions.NotFound: 404 Not Found: The requested URL was not found on the server. If you entered the URL manually please check your spelling and try again.
2025-05-06 16:42:53,975 - app - ERROR - [__init__.py:47] - Unhandled exception: 404 Not Found: The requested URL was not found on the server. If you entered the URL manually please check your spelling and try again.
Traceback (most recent call last):
  File "/Users/guggarisathvik/groundnut_mill/.venv/lib/python3.9/site-packages/flask/app.py", line 917, in full_dispatch_request
    rv = self.dispatch_request()
  File "/Users/guggarisathvik/groundnut_mill/.venv/lib/python3.9/site-packages/flask/app.py", line 902, in dispatch_request
    return self.ensure_sync(self.view_functions[rule.endpoint])(**view_args)  # type: ignore[no-any-return]
  File "/Users/guggarisathvik/groundnut_mill/.venv/lib/python3.9/site-packages/flask/app.py", line 278, in <lambda>
    view_func=lambda **kw: self_ref().send_static_file(**kw),  # type: ignore # noqa: B950
  File "/Users/guggarisathvik/groundnut_mill/.venv/lib/python3.9/site-packages/flask/app.py", line 326, in send_static_file
    return send_from_directory(
  File "/Users/guggarisathvik/groundnut_mill/.venv/lib/python3.9/site-packages/flask/helpers.py", line 565, in send_from_directory
    return werkzeug.utils.send_from_directory(  # type: ignore[return-value]
  File "/Users/guggarisathvik/groundnut_mill/.venv/lib/python3.9/site-packages/werkzeug/utils.py", line 575, in send_from_directory
    raise NotFound()
werkzeug.exceptions.NotFound: 404 Not Found: The requested URL was not found on the server. If you entered the URL manually please check your spelling and try again.
2025-05-06 16:42:54,021 - app - ERROR - [__init__.py:47] - Unhandled exception: 404 Not Found: The requested URL was not found on the server. If you entered the URL manually please check your spelling and try again.
Traceback (most recent call last):
  File "/Users/guggarisathvik/groundnut_mill/.venv/lib/python3.9/site-packages/flask/app.py", line 917, in full_dispatch_request
    rv = self.dispatch_request()
  File "/Users/guggarisathvik/groundnut_mill/.venv/lib/python3.9/site-packages/flask/app.py", line 902, in dispatch_request
    return self.ensure_sync(self.view_functions[rule.endpoint])(**view_args)  # type: ignore[no-any-return]
  File "/Users/guggarisathvik/groundnut_mill/.venv/lib/python3.9/site-packages/flask/app.py", line 278, in <lambda>
    view_func=lambda **kw: self_ref().send_static_file(**kw),  # type: ignore # noqa: B950
  File "/Users/guggarisathvik/groundnut_mill/.venv/lib/python3.9/site-packages/flask/app.py", line 326, in send_static_file
    return send_from_directory(
  File "/Users/guggarisathvik/groundnut_mill/.venv/lib/python3.9/site-packages/flask/helpers.py", line 565, in send_from_directory
    return werkzeug.utils.send_from_directory(  # type: ignore[return-value]
  File "/Users/guggarisathvik/groundnut_mill/.venv/lib/python3.9/site-packages/werkzeug/utils.py", line 575, in send_from_directory
    raise NotFound()
werkzeug.exceptions.NotFound: 404 Not Found: The requested URL was not found on the server. If you entered the URL manually please check your spelling and try again.
2025-05-06 16:42:56,726 - app - ERROR - [__init__.py:47] - Unhandled exception: 404 Not Found: The requested URL was not found on the server. If you entered the URL manually please check your spelling and try again.
Traceback (most recent call last):
  File "/Users/guggarisathvik/groundnut_mill/.venv/lib/python3.9/site-packages/flask/app.py", line 917, in full_dispatch_request
    rv = self.dispatch_request()
  File "/Users/guggarisathvik/groundnut_mill/.venv/lib/python3.9/site-packages/flask/app.py", line 902, in dispatch_request
    return self.ensure_sync(self.view_functions[rule.endpoint])(**view_args)  # type: ignore[no-any-return]
  File "/Users/guggarisathvik/groundnut_mill/.venv/lib/python3.9/site-packages/flask/app.py", line 278, in <lambda>
    view_func=lambda **kw: self_ref().send_static_file(**kw),  # type: ignore # noqa: B950
  File "/Users/guggarisathvik/groundnut_mill/.venv/lib/python3.9/site-packages/flask/app.py", line 326, in send_static_file
    return send_from_directory(
  File "/Users/guggarisathvik/groundnut_mill/.venv/lib/python3.9/site-packages/flask/helpers.py", line 565, in send_from_directory
    return werkzeug.utils.send_from_directory(  # type: ignore[return-value]
  File "/Users/guggarisathvik/groundnut_mill/.venv/lib/python3.9/site-packages/werkzeug/utils.py", line 575, in send_from_directory
    raise NotFound()
werkzeug.exceptions.NotFound: 404 Not Found: The requested URL was not found on the server. If you entered the URL manually please check your spelling and try again.
2025-05-06 16:42:56,784 - app - ERROR - [__init__.py:47] - Unhandled exception: 404 Not Found: The requested URL was not found on the server. If you entered the URL manually please check your spelling and try again.
Traceback (most recent call last):
  File "/Users/guggarisathvik/groundnut_mill/.venv/lib/python3.9/site-packages/flask/app.py", line 917, in full_dispatch_request
    rv = self.dispatch_request()
  File "/Users/guggarisathvik/groundnut_mill/.venv/lib/python3.9/site-packages/flask/app.py", line 902, in dispatch_request
    return self.ensure_sync(self.view_functions[rule.endpoint])(**view_args)  # type: ignore[no-any-return]
  File "/Users/guggarisathvik/groundnut_mill/.venv/lib/python3.9/site-packages/flask/app.py", line 278, in <lambda>
    view_func=lambda **kw: self_ref().send_static_file(**kw),  # type: ignore # noqa: B950
  File "/Users/guggarisathvik/groundnut_mill/.venv/lib/python3.9/site-packages/flask/app.py", line 326, in send_static_file
    return send_from_directory(
  File "/Users/guggarisathvik/groundnut_mill/.venv/lib/python3.9/site-packages/flask/helpers.py", line 565, in send_from_directory
    return werkzeug.utils.send_from_directory(  # type: ignore[return-value]
  File "/Users/guggarisathvik/groundnut_mill/.venv/lib/python3.9/site-packages/werkzeug/utils.py", line 575, in send_from_directory
    raise NotFound()
werkzeug.exceptions.NotFound: 404 Not Found: The requested URL was not found on the server. If you entered the URL manually please check your spelling and try again.
2025-05-06 16:42:57,852 - app - ERROR - [__init__.py:47] - Unhandled exception: 404 Not Found: The requested URL was not found on the server. If you entered the URL manually please check your spelling and try again.
Traceback (most recent call last):
  File "/Users/guggarisathvik/groundnut_mill/.venv/lib/python3.9/site-packages/flask/app.py", line 917, in full_dispatch_request
    rv = self.dispatch_request()
  File "/Users/guggarisathvik/groundnut_mill/.venv/lib/python3.9/site-packages/flask/app.py", line 902, in dispatch_request
    return self.ensure_sync(self.view_functions[rule.endpoint])(**view_args)  # type: ignore[no-any-return]
  File "/Users/guggarisathvik/groundnut_mill/.venv/lib/python3.9/site-packages/flask/app.py", line 278, in <lambda>
    view_func=lambda **kw: self_ref().send_static_file(**kw),  # type: ignore # noqa: B950
  File "/Users/guggarisathvik/groundnut_mill/.venv/lib/python3.9/site-packages/flask/app.py", line 326, in send_static_file
    return send_from_directory(
  File "/Users/guggarisathvik/groundnut_mill/.venv/lib/python3.9/site-packages/flask/helpers.py", line 565, in send_from_directory
    return werkzeug.utils.send_from_directory(  # type: ignore[return-value]
  File "/Users/guggarisathvik/groundnut_mill/.venv/lib/python3.9/site-packages/werkzeug/utils.py", line 575, in send_from_directory
    raise NotFound()
werkzeug.exceptions.NotFound: 404 Not Found: The requested URL was not found on the server. If you entered the URL manually please check your spelling and try again.
2025-05-06 16:42:57,916 - app - ERROR - [__init__.py:47] - Unhandled exception: 404 Not Found: The requested URL was not found on the server. If you entered the URL manually please check your spelling and try again.
Traceback (most recent call last):
  File "/Users/guggarisathvik/groundnut_mill/.venv/lib/python3.9/site-packages/flask/app.py", line 917, in full_dispatch_request
    rv = self.dispatch_request()
  File "/Users/guggarisathvik/groundnut_mill/.venv/lib/python3.9/site-packages/flask/app.py", line 902, in dispatch_request
    return self.ensure_sync(self.view_functions[rule.endpoint])(**view_args)  # type: ignore[no-any-return]
  File "/Users/guggarisathvik/groundnut_mill/.venv/lib/python3.9/site-packages/flask/app.py", line 278, in <lambda>
    view_func=lambda **kw: self_ref().send_static_file(**kw),  # type: ignore # noqa: B950
  File "/Users/guggarisathvik/groundnut_mill/.venv/lib/python3.9/site-packages/flask/app.py", line 326, in send_static_file
    return send_from_directory(
  File "/Users/guggarisathvik/groundnut_mill/.venv/lib/python3.9/site-packages/flask/helpers.py", line 565, in send_from_directory
    return werkzeug.utils.send_from_directory(  # type: ignore[return-value]
  File "/Users/guggarisathvik/groundnut_mill/.venv/lib/python3.9/site-packages/werkzeug/utils.py", line 575, in send_from_directory
    raise NotFound()
werkzeug.exceptions.NotFound: 404 Not Found: The requested URL was not found on the server. If you entered the URL manually please check your spelling and try again.
2025-05-06 16:42:58,544 - app - ERROR - [__init__.py:47] - Unhandled exception: 404 Not Found: The requested URL was not found on the server. If you entered the URL manually please check your spelling and try again.
Traceback (most recent call last):
  File "/Users/guggarisathvik/groundnut_mill/.venv/lib/python3.9/site-packages/flask/app.py", line 917, in full_dispatch_request
    rv = self.dispatch_request()
  File "/Users/guggarisathvik/groundnut_mill/.venv/lib/python3.9/site-packages/flask/app.py", line 902, in dispatch_request
    return self.ensure_sync(self.view_functions[rule.endpoint])(**view_args)  # type: ignore[no-any-return]
  File "/Users/guggarisathvik/groundnut_mill/.venv/lib/python3.9/site-packages/flask/app.py", line 278, in <lambda>
    view_func=lambda **kw: self_ref().send_static_file(**kw),  # type: ignore # noqa: B950
  File "/Users/guggarisathvik/groundnut_mill/.venv/lib/python3.9/site-packages/flask/app.py", line 326, in send_static_file
    return send_from_directory(
  File "/Users/guggarisathvik/groundnut_mill/.venv/lib/python3.9/site-packages/flask/helpers.py", line 565, in send_from_directory
    return werkzeug.utils.send_from_directory(  # type: ignore[return-value]
  File "/Users/guggarisathvik/groundnut_mill/.venv/lib/python3.9/site-packages/werkzeug/utils.py", line 575, in send_from_directory
    raise NotFound()
werkzeug.exceptions.NotFound: 404 Not Found: The requested URL was not found on the server. If you entered the URL manually please check your spelling and try again.
2025-05-06 16:42:58,618 - app - ERROR - [__init__.py:47] - Unhandled exception: 404 Not Found: The requested URL was not found on the server. If you entered the URL manually please check your spelling and try again.
Traceback (most recent call last):
  File "/Users/guggarisathvik/groundnut_mill/.venv/lib/python3.9/site-packages/flask/app.py", line 917, in full_dispatch_request
    rv = self.dispatch_request()
  File "/Users/guggarisathvik/groundnut_mill/.venv/lib/python3.9/site-packages/flask/app.py", line 902, in dispatch_request
    return self.ensure_sync(self.view_functions[rule.endpoint])(**view_args)  # type: ignore[no-any-return]
  File "/Users/guggarisathvik/groundnut_mill/.venv/lib/python3.9/site-packages/flask/app.py", line 278, in <lambda>
    view_func=lambda **kw: self_ref().send_static_file(**kw),  # type: ignore # noqa: B950
  File "/Users/guggarisathvik/groundnut_mill/.venv/lib/python3.9/site-packages/flask/app.py", line 326, in send_static_file
    return send_from_directory(
  File "/Users/guggarisathvik/groundnut_mill/.venv/lib/python3.9/site-packages/flask/helpers.py", line 565, in send_from_directory
    return werkzeug.utils.send_from_directory(  # type: ignore[return-value]
  File "/Users/guggarisathvik/groundnut_mill/.venv/lib/python3.9/site-packages/werkzeug/utils.py", line 575, in send_from_directory
    raise NotFound()
werkzeug.exceptions.NotFound: 404 Not Found: The requested URL was not found on the server. If you entered the URL manually please check your spelling and try again.
2025-05-06 16:52:44,715 - app - ERROR - [__init__.py:47] - Unhandled exception: 'AnonymousUserMixin' object has no attribute 'username'
Traceback (most recent call last):
  File "/Users/guggarisathvik/groundnut_mill/.venv/lib/python3.9/site-packages/flask/app.py", line 917, in full_dispatch_request
    rv = self.dispatch_request()
  File "/Users/guggarisathvik/groundnut_mill/.venv/lib/python3.9/site-packages/flask/app.py", line 902, in dispatch_request
    return self.ensure_sync(self.view_functions[rule.endpoint])(**view_args)  # type: ignore[no-any-return]
  File "/Users/guggarisathvik/groundnut_mill/.venv/lib/python3.9/site-packages/flask_login/utils.py", line 290, in decorated_view
    return current_app.ensure_sync(func)(*args, **kwargs)
  File "/Users/guggarisathvik/groundnut_mill/app/routes/auth.py", line 33, in logout
    current_app.logger.info(f"User {current_user.username} logged out successfully.")
AttributeError: 'AnonymousUserMixin' object has no attribute 'username'
2025-05-06 16:54:07,922 - flask-app - INFO - [__init__.py:22] - Starting Flask application...
2025-05-06 16:54:13,727 - app - ERROR - [__init__.py:47] - Unhandled exception: 404 Not Found: The requested URL was not found on the server. If you entered the URL manually please check your spelling and try again.
Traceback (most recent call last):
  File "/Users/guggarisathvik/groundnut_mill/.venv/lib/python3.9/site-packages/flask/app.py", line 917, in full_dispatch_request
    rv = self.dispatch_request()
  File "/Users/guggarisathvik/groundnut_mill/.venv/lib/python3.9/site-packages/flask/app.py", line 902, in dispatch_request
    return self.ensure_sync(self.view_functions[rule.endpoint])(**view_args)  # type: ignore[no-any-return]
  File "/Users/guggarisathvik/groundnut_mill/.venv/lib/python3.9/site-packages/flask/app.py", line 278, in <lambda>
    view_func=lambda **kw: self_ref().send_static_file(**kw),  # type: ignore # noqa: B950
  File "/Users/guggarisathvik/groundnut_mill/.venv/lib/python3.9/site-packages/flask/app.py", line 326, in send_static_file
    return send_from_directory(
  File "/Users/guggarisathvik/groundnut_mill/.venv/lib/python3.9/site-packages/flask/helpers.py", line 565, in send_from_directory
    return werkzeug.utils.send_from_directory(  # type: ignore[return-value]
  File "/Users/guggarisathvik/groundnut_mill/.venv/lib/python3.9/site-packages/werkzeug/utils.py", line 575, in send_from_directory
    raise NotFound()
werkzeug.exceptions.NotFound: 404 Not Found: The requested URL was not found on the server. If you entered the URL manually please check your spelling and try again.
2025-05-06 16:54:25,756 - app - INFO - [auth.py:18] - User admin logged in successfully.
2025-05-06 16:54:26,130 - app - ERROR - [__init__.py:47] - Unhandled exception: 404 Not Found: The requested URL was not found on the server. If you entered the URL manually please check your spelling and try again.
Traceback (most recent call last):
  File "/Users/guggarisathvik/groundnut_mill/.venv/lib/python3.9/site-packages/flask/app.py", line 917, in full_dispatch_request
    rv = self.dispatch_request()
  File "/Users/guggarisathvik/groundnut_mill/.venv/lib/python3.9/site-packages/flask/app.py", line 902, in dispatch_request
    return self.ensure_sync(self.view_functions[rule.endpoint])(**view_args)  # type: ignore[no-any-return]
  File "/Users/guggarisathvik/groundnut_mill/.venv/lib/python3.9/site-packages/flask/app.py", line 278, in <lambda>
    view_func=lambda **kw: self_ref().send_static_file(**kw),  # type: ignore # noqa: B950
  File "/Users/guggarisathvik/groundnut_mill/.venv/lib/python3.9/site-packages/flask/app.py", line 326, in send_static_file
    return send_from_directory(
  File "/Users/guggarisathvik/groundnut_mill/.venv/lib/python3.9/site-packages/flask/helpers.py", line 565, in send_from_directory
    return werkzeug.utils.send_from_directory(  # type: ignore[return-value]
  File "/Users/guggarisathvik/groundnut_mill/.venv/lib/python3.9/site-packages/werkzeug/utils.py", line 575, in send_from_directory
    raise NotFound()
werkzeug.exceptions.NotFound: 404 Not Found: The requested URL was not found on the server. If you entered the URL manually please check your spelling and try again.
2025-05-06 16:56:37,481 - flask-app - INFO - [__init__.py:22] - Starting Flask application...
2025-05-06 16:56:38,116 - flask-app - INFO - [__init__.py:22] - Starting Flask application...
2025-05-06 16:56:41,374 - app - ERROR - [__init__.py:47] - Unhandled exception: 404 Not Found: The requested URL was not found on the server. If you entered the URL manually please check your spelling and try again.
Traceback (most recent call last):
  File "/Users/guggarisathvik/groundnut_mill/.venv/lib/python3.9/site-packages/flask/app.py", line 917, in full_dispatch_request
    rv = self.dispatch_request()
  File "/Users/guggarisathvik/groundnut_mill/.venv/lib/python3.9/site-packages/flask/app.py", line 902, in dispatch_request
    return self.ensure_sync(self.view_functions[rule.endpoint])(**view_args)  # type: ignore[no-any-return]
  File "/Users/guggarisathvik/groundnut_mill/.venv/lib/python3.9/site-packages/flask/app.py", line 278, in <lambda>
    view_func=lambda **kw: self_ref().send_static_file(**kw),  # type: ignore # noqa: B950
  File "/Users/guggarisathvik/groundnut_mill/.venv/lib/python3.9/site-packages/flask/app.py", line 326, in send_static_file
    return send_from_directory(
  File "/Users/guggarisathvik/groundnut_mill/.venv/lib/python3.9/site-packages/flask/helpers.py", line 565, in send_from_directory
    return werkzeug.utils.send_from_directory(  # type: ignore[return-value]
  File "/Users/guggarisathvik/groundnut_mill/.venv/lib/python3.9/site-packages/werkzeug/utils.py", line 575, in send_from_directory
    raise NotFound()
werkzeug.exceptions.NotFound: 404 Not Found: The requested URL was not found on the server. If you entered the URL manually please check your spelling and try again.
2025-05-06 17:18:12,541 - flask-app - INFO - [__init__.py:25] - Starting Flask application...
2025-05-06 17:29:26,979 - app - ERROR - [__init__.py:50] - Unhandled exception: 404 Not Found: The requested URL was not found on the server. If you entered the URL manually please check your spelling and try again.
Traceback (most recent call last):
  File "/Users/guggarisathvik/groundnut_mill/.venv/lib/python3.9/site-packages/flask/app.py", line 917, in full_dispatch_request
    rv = self.dispatch_request()
  File "/Users/guggarisathvik/groundnut_mill/.venv/lib/python3.9/site-packages/flask/app.py", line 902, in dispatch_request
    return self.ensure_sync(self.view_functions[rule.endpoint])(**view_args)  # type: ignore[no-any-return]
  File "/Users/guggarisathvik/groundnut_mill/.venv/lib/python3.9/site-packages/flask/app.py", line 278, in <lambda>
    view_func=lambda **kw: self_ref().send_static_file(**kw),  # type: ignore # noqa: B950
  File "/Users/guggarisathvik/groundnut_mill/.venv/lib/python3.9/site-packages/flask/app.py", line 326, in send_static_file
    return send_from_directory(
  File "/Users/guggarisathvik/groundnut_mill/.venv/lib/python3.9/site-packages/flask/helpers.py", line 565, in send_from_directory
    return werkzeug.utils.send_from_directory(  # type: ignore[return-value]
  File "/Users/guggarisathvik/groundnut_mill/.venv/lib/python3.9/site-packages/werkzeug/utils.py", line 575, in send_from_directory
    raise NotFound()
werkzeug.exceptions.NotFound: 404 Not Found: The requested URL was not found on the server. If you entered the URL manually please check your spelling and try again.
2025-05-06 17:29:28,335 - app - ERROR - [__init__.py:50] - Unhandled exception: 404 Not Found: The requested URL was not found on the server. If you entered the URL manually please check your spelling and try again.
Traceback (most recent call last):
  File "/Users/guggarisathvik/groundnut_mill/.venv/lib/python3.9/site-packages/flask/app.py", line 917, in full_dispatch_request
    rv = self.dispatch_request()
  File "/Users/guggarisathvik/groundnut_mill/.venv/lib/python3.9/site-packages/flask/app.py", line 902, in dispatch_request
    return self.ensure_sync(self.view_functions[rule.endpoint])(**view_args)  # type: ignore[no-any-return]
  File "/Users/guggarisathvik/groundnut_mill/.venv/lib/python3.9/site-packages/flask/app.py", line 278, in <lambda>
    view_func=lambda **kw: self_ref().send_static_file(**kw),  # type: ignore # noqa: B950
  File "/Users/guggarisathvik/groundnut_mill/.venv/lib/python3.9/site-packages/flask/app.py", line 326, in send_static_file
    return send_from_directory(
  File "/Users/guggarisathvik/groundnut_mill/.venv/lib/python3.9/site-packages/flask/helpers.py", line 565, in send_from_directory
    return werkzeug.utils.send_from_directory(  # type: ignore[return-value]
  File "/Users/guggarisathvik/groundnut_mill/.venv/lib/python3.9/site-packages/werkzeug/utils.py", line 575, in send_from_directory
    raise NotFound()
werkzeug.exceptions.NotFound: 404 Not Found: The requested URL was not found on the server. If you entered the URL manually please check your spelling and try again.
2025-05-06 17:33:23,300 - flask-app - INFO - [__init__.py:25] - Starting Flask application...
2025-05-06 17:33:23,946 - flask-app - INFO - [__init__.py:25] - Starting Flask application...
2025-05-06 17:33:31,734 - app - ERROR - [__init__.py:50] - Unhandled exception: 404 Not Found: The requested URL was not found on the server. If you entered the URL manually please check your spelling and try again.
Traceback (most recent call last):
  File "/Users/guggarisathvik/groundnut_mill/.venv/lib/python3.9/site-packages/flask/app.py", line 917, in full_dispatch_request
    rv = self.dispatch_request()
  File "/Users/guggarisathvik/groundnut_mill/.venv/lib/python3.9/site-packages/flask/app.py", line 902, in dispatch_request
    return self.ensure_sync(self.view_functions[rule.endpoint])(**view_args)  # type: ignore[no-any-return]
  File "/Users/guggarisathvik/groundnut_mill/.venv/lib/python3.9/site-packages/flask/app.py", line 278, in <lambda>
    view_func=lambda **kw: self_ref().send_static_file(**kw),  # type: ignore # noqa: B950
  File "/Users/guggarisathvik/groundnut_mill/.venv/lib/python3.9/site-packages/flask/app.py", line 326, in send_static_file
    return send_from_directory(
  File "/Users/guggarisathvik/groundnut_mill/.venv/lib/python3.9/site-packages/flask/helpers.py", line 565, in send_from_directory
    return werkzeug.utils.send_from_directory(  # type: ignore[return-value]
  File "/Users/guggarisathvik/groundnut_mill/.venv/lib/python3.9/site-packages/werkzeug/utils.py", line 575, in send_from_directory
    raise NotFound()
werkzeug.exceptions.NotFound: 404 Not Found: The requested URL was not found on the server. If you entered the URL manually please check your spelling and try again.
2025-05-06 17:35:52,806 - app - ERROR - [__init__.py:50] - Unhandled exception: 404 Not Found: The requested URL was not found on the server. If you entered the URL manually please check your spelling and try again.
Traceback (most recent call last):
  File "/Users/guggarisathvik/groundnut_mill/.venv/lib/python3.9/site-packages/flask/app.py", line 917, in full_dispatch_request
    rv = self.dispatch_request()
  File "/Users/guggarisathvik/groundnut_mill/.venv/lib/python3.9/site-packages/flask/app.py", line 902, in dispatch_request
    return self.ensure_sync(self.view_functions[rule.endpoint])(**view_args)  # type: ignore[no-any-return]
  File "/Users/guggarisathvik/groundnut_mill/.venv/lib/python3.9/site-packages/flask/app.py", line 278, in <lambda>
    view_func=lambda **kw: self_ref().send_static_file(**kw),  # type: ignore # noqa: B950
  File "/Users/guggarisathvik/groundnut_mill/.venv/lib/python3.9/site-packages/flask/app.py", line 326, in send_static_file
    return send_from_directory(
  File "/Users/guggarisathvik/groundnut_mill/.venv/lib/python3.9/site-packages/flask/helpers.py", line 565, in send_from_directory
    return werkzeug.utils.send_from_directory(  # type: ignore[return-value]
  File "/Users/guggarisathvik/groundnut_mill/.venv/lib/python3.9/site-packages/werkzeug/utils.py", line 575, in send_from_directory
    raise NotFound()
werkzeug.exceptions.NotFound: 404 Not Found: The requested URL was not found on the server. If you entered the URL manually please check your spelling and try again.
2025-05-06 17:44:18,380 - flask-app - INFO - [__init__.py:25] - Starting Flask application...
2025-05-06 17:44:29,796 - app - ERROR - [__init__.py:50] - Unhandled exception: 404 Not Found: The requested URL was not found on the server. If you entered the URL manually please check your spelling and try again.
Traceback (most recent call last):
  File "/Users/guggarisathvik/groundnut_mill/.venv/lib/python3.9/site-packages/flask/app.py", line 917, in full_dispatch_request
    rv = self.dispatch_request()
  File "/Users/guggarisathvik/groundnut_mill/.venv/lib/python3.9/site-packages/flask/app.py", line 902, in dispatch_request
    return self.ensure_sync(self.view_functions[rule.endpoint])(**view_args)  # type: ignore[no-any-return]
  File "/Users/guggarisathvik/groundnut_mill/.venv/lib/python3.9/site-packages/flask/app.py", line 278, in <lambda>
    view_func=lambda **kw: self_ref().send_static_file(**kw),  # type: ignore # noqa: B950
  File "/Users/guggarisathvik/groundnut_mill/.venv/lib/python3.9/site-packages/flask/app.py", line 326, in send_static_file
    return send_from_directory(
  File "/Users/guggarisathvik/groundnut_mill/.venv/lib/python3.9/site-packages/flask/helpers.py", line 565, in send_from_directory
    return werkzeug.utils.send_from_directory(  # type: ignore[return-value]
  File "/Users/guggarisathvik/groundnut_mill/.venv/lib/python3.9/site-packages/werkzeug/utils.py", line 575, in send_from_directory
    raise NotFound()
werkzeug.exceptions.NotFound: 404 Not Found: The requested URL was not found on the server. If you entered the URL manually please check your spelling and try again.
2025-05-06 17:54:25,642 - app - INFO - [auth.py:18] - User admin logged in successfully.
2025-05-06 17:54:35,138 - app - ERROR - [__init__.py:50] - Unhandled exception: 404 Not Found: The requested URL was not found on the server. If you entered the URL manually please check your spelling and try again.
Traceback (most recent call last):
  File "/Users/guggarisathvik/groundnut_mill/.venv/lib/python3.9/site-packages/flask/app.py", line 917, in full_dispatch_request
    rv = self.dispatch_request()
  File "/Users/guggarisathvik/groundnut_mill/.venv/lib/python3.9/site-packages/flask/app.py", line 902, in dispatch_request
    return self.ensure_sync(self.view_functions[rule.endpoint])(**view_args)  # type: ignore[no-any-return]
  File "/Users/guggarisathvik/groundnut_mill/.venv/lib/python3.9/site-packages/flask/app.py", line 278, in <lambda>
    view_func=lambda **kw: self_ref().send_static_file(**kw),  # type: ignore # noqa: B950
  File "/Users/guggarisathvik/groundnut_mill/.venv/lib/python3.9/site-packages/flask/app.py", line 326, in send_static_file
    return send_from_directory(
  File "/Users/guggarisathvik/groundnut_mill/.venv/lib/python3.9/site-packages/flask/helpers.py", line 565, in send_from_directory
    return werkzeug.utils.send_from_directory(  # type: ignore[return-value]
  File "/Users/guggarisathvik/groundnut_mill/.venv/lib/python3.9/site-packages/werkzeug/utils.py", line 575, in send_from_directory
    raise NotFound()
werkzeug.exceptions.NotFound: 404 Not Found: The requested URL was not found on the server. If you entered the URL manually please check your spelling and try again.
2025-05-07 21:49:03,588 - app - ERROR - [__init__.py:50] - Unhandled exception: 404 Not Found: The requested URL was not found on the server. If you entered the URL manually please check your spelling and try again.
Traceback (most recent call last):
  File "/Users/guggarisathvik/groundnut_mill/.venv/lib/python3.9/site-packages/flask/app.py", line 917, in full_dispatch_request
    rv = self.dispatch_request()
  File "/Users/guggarisathvik/groundnut_mill/.venv/lib/python3.9/site-packages/flask/app.py", line 902, in dispatch_request
    return self.ensure_sync(self.view_functions[rule.endpoint])(**view_args)  # type: ignore[no-any-return]
  File "/Users/guggarisathvik/groundnut_mill/.venv/lib/python3.9/site-packages/flask/app.py", line 278, in <lambda>
    view_func=lambda **kw: self_ref().send_static_file(**kw),  # type: ignore # noqa: B950
  File "/Users/guggarisathvik/groundnut_mill/.venv/lib/python3.9/site-packages/flask/app.py", line 326, in send_static_file
    return send_from_directory(
  File "/Users/guggarisathvik/groundnut_mill/.venv/lib/python3.9/site-packages/flask/helpers.py", line 565, in send_from_directory
    return werkzeug.utils.send_from_directory(  # type: ignore[return-value]
  File "/Users/guggarisathvik/groundnut_mill/.venv/lib/python3.9/site-packages/werkzeug/utils.py", line 575, in send_from_directory
    raise NotFound()
werkzeug.exceptions.NotFound: 404 Not Found: The requested URL was not found on the server. If you entered the URL manually please check your spelling and try again.
2025-05-07 21:49:06,632 - app - INFO - [machinery_routes.py:138] - Machinery deleted: 4
2025-05-07 21:49:21,647 - app - INFO - [machinery_routes.py:68] - Expense added for machinery ID 3
2025-05-07 21:51:08,669 - app - ERROR - [__init__.py:50] - Unhandled exception: 404 Not Found: The requested URL was not found on the server. If you entered the URL manually please check your spelling and try again.
Traceback (most recent call last):
  File "/Users/guggarisathvik/groundnut_mill/.venv/lib/python3.9/site-packages/flask/app.py", line 917, in full_dispatch_request
    rv = self.dispatch_request()
  File "/Users/guggarisathvik/groundnut_mill/.venv/lib/python3.9/site-packages/flask/app.py", line 902, in dispatch_request
    return self.ensure_sync(self.view_functions[rule.endpoint])(**view_args)  # type: ignore[no-any-return]
  File "/Users/guggarisathvik/groundnut_mill/.venv/lib/python3.9/site-packages/flask/app.py", line 278, in <lambda>
    view_func=lambda **kw: self_ref().send_static_file(**kw),  # type: ignore # noqa: B950
  File "/Users/guggarisathvik/groundnut_mill/.venv/lib/python3.9/site-packages/flask/app.py", line 326, in send_static_file
    return send_from_directory(
  File "/Users/guggarisathvik/groundnut_mill/.venv/lib/python3.9/site-packages/flask/helpers.py", line 565, in send_from_directory
    return werkzeug.utils.send_from_directory(  # type: ignore[return-value]
  File "/Users/guggarisathvik/groundnut_mill/.venv/lib/python3.9/site-packages/werkzeug/utils.py", line 575, in send_from_directory
    raise NotFound()
werkzeug.exceptions.NotFound: 404 Not Found: The requested URL was not found on the server. If you entered the URL manually please check your spelling and try again.
2025-05-07 21:51:11,178 - app - ERROR - [__init__.py:50] - Unhandled exception: 404 Not Found: The requested URL was not found on the server. If you entered the URL manually please check your spelling and try again.
Traceback (most recent call last):
  File "/Users/guggarisathvik/groundnut_mill/.venv/lib/python3.9/site-packages/flask/app.py", line 917, in full_dispatch_request
    rv = self.dispatch_request()
  File "/Users/guggarisathvik/groundnut_mill/.venv/lib/python3.9/site-packages/flask/app.py", line 902, in dispatch_request
    return self.ensure_sync(self.view_functions[rule.endpoint])(**view_args)  # type: ignore[no-any-return]
  File "/Users/guggarisathvik/groundnut_mill/.venv/lib/python3.9/site-packages/flask/app.py", line 278, in <lambda>
    view_func=lambda **kw: self_ref().send_static_file(**kw),  # type: ignore # noqa: B950
  File "/Users/guggarisathvik/groundnut_mill/.venv/lib/python3.9/site-packages/flask/app.py", line 326, in send_static_file
    return send_from_directory(
  File "/Users/guggarisathvik/groundnut_mill/.venv/lib/python3.9/site-packages/flask/helpers.py", line 565, in send_from_directory
    return werkzeug.utils.send_from_directory(  # type: ignore[return-value]
  File "/Users/guggarisathvik/groundnut_mill/.venv/lib/python3.9/site-packages/werkzeug/utils.py", line 575, in send_from_directory
    raise NotFound()
werkzeug.exceptions.NotFound: 404 Not Found: The requested URL was not found on the server. If you entered the URL manually please check your spelling and try again.
2025-05-07 21:51:38,082 - app - INFO - [machinery_routes.py:68] - Expense added for machinery ID 3
2025-05-07 21:56:27,944 - flask-app - INFO - [__init__.py:25] - Starting Flask application...
2025-05-07 21:56:31,762 - app - ERROR - [__init__.py:50] - Unhandled exception: Could not build url for endpoint 'machinery.delete_expense' with values ['id']. Did you forget to specify values ['expense_id', 'machinery_id']?
Traceback (most recent call last):
  File "/Users/guggarisathvik/groundnut_mill/.venv/lib/python3.9/site-packages/flask/app.py", line 917, in full_dispatch_request
    rv = self.dispatch_request()
  File "/Users/guggarisathvik/groundnut_mill/.venv/lib/python3.9/site-packages/flask/app.py", line 902, in dispatch_request
    return self.ensure_sync(self.view_functions[rule.endpoint])(**view_args)  # type: ignore[no-any-return]
  File "/Users/guggarisathvik/groundnut_mill/.venv/lib/python3.9/site-packages/flask_login/utils.py", line 290, in decorated_view
    return current_app.ensure_sync(func)(*args, **kwargs)
  File "/Users/guggarisathvik/groundnut_mill/app/routes/machinery_routes.py", line 16, in list_machines
    return render_template("machinery/list.html", machines=machines)
  File "/Users/guggarisathvik/groundnut_mill/.venv/lib/python3.9/site-packages/flask/templating.py", line 150, in render_template
    return _render(app, template, context)
  File "/Users/guggarisathvik/groundnut_mill/.venv/lib/python3.9/site-packages/flask/templating.py", line 131, in _render
    rv = template.render(context)
  File "/Users/guggarisathvik/groundnut_mill/.venv/lib/python3.9/site-packages/jinja2/environment.py", line 1295, in render
    self.environment.handle_exception()
  File "/Users/guggarisathvik/groundnut_mill/.venv/lib/python3.9/site-packages/jinja2/environment.py", line 942, in handle_exception
    raise rewrite_traceback_stack(source=source)
  File "/Users/guggarisathvik/groundnut_mill/app/templates/machinery/list.html", line 1, in top-level template code
    {% extends "base.html" %}
  File "/Users/guggarisathvik/groundnut_mill/app/templates/base.html", line 83, in top-level template code
    {% block content %}{% endblock %}
  File "/Users/guggarisathvik/groundnut_mill/app/templates/machinery/list.html", line 70, in block 'content'
    <form action="{{ url_for('machinery.delete_expense', id=m.id) }}" method="POST" style="display:inline;">
  File "/Users/guggarisathvik/groundnut_mill/.venv/lib/python3.9/site-packages/flask/app.py", line 1121, in url_for
    return self.handle_url_build_error(error, endpoint, values)
  File "/Users/guggarisathvik/groundnut_mill/.venv/lib/python3.9/site-packages/flask/app.py", line 1110, in url_for
    rv = url_adapter.build(  # type: ignore[union-attr]
  File "/Users/guggarisathvik/groundnut_mill/.venv/lib/python3.9/site-packages/werkzeug/routing/map.py", line 924, in build
    raise BuildError(endpoint, values, method, self)
werkzeug.routing.exceptions.BuildError: Could not build url for endpoint 'machinery.delete_expense' with values ['id']. Did you forget to specify values ['expense_id', 'machinery_id']?
2025-05-07 21:56:34,389 - app - ERROR - [__init__.py:50] - Unhandled exception: Could not build url for endpoint 'machinery.delete_expense' with values ['id']. Did you forget to specify values ['expense_id', 'machinery_id']?
Traceback (most recent call last):
  File "/Users/guggarisathvik/groundnut_mill/.venv/lib/python3.9/site-packages/flask/app.py", line 917, in full_dispatch_request
    rv = self.dispatch_request()
  File "/Users/guggarisathvik/groundnut_mill/.venv/lib/python3.9/site-packages/flask/app.py", line 902, in dispatch_request
    return self.ensure_sync(self.view_functions[rule.endpoint])(**view_args)  # type: ignore[no-any-return]
  File "/Users/guggarisathvik/groundnut_mill/.venv/lib/python3.9/site-packages/flask_login/utils.py", line 290, in decorated_view
    return current_app.ensure_sync(func)(*args, **kwargs)
  File "/Users/guggarisathvik/groundnut_mill/app/routes/machinery_routes.py", line 16, in list_machines
    return render_template("machinery/list.html", machines=machines)
  File "/Users/guggarisathvik/groundnut_mill/.venv/lib/python3.9/site-packages/flask/templating.py", line 150, in render_template
    return _render(app, template, context)
  File "/Users/guggarisathvik/groundnut_mill/.venv/lib/python3.9/site-packages/flask/templating.py", line 131, in _render
    rv = template.render(context)
  File "/Users/guggarisathvik/groundnut_mill/.venv/lib/python3.9/site-packages/jinja2/environment.py", line 1295, in render
    self.environment.handle_exception()
  File "/Users/guggarisathvik/groundnut_mill/.venv/lib/python3.9/site-packages/jinja2/environment.py", line 942, in handle_exception
    raise rewrite_traceback_stack(source=source)
  File "/Users/guggarisathvik/groundnut_mill/app/templates/machinery/list.html", line 1, in top-level template code
    {% extends "base.html" %}
  File "/Users/guggarisathvik/groundnut_mill/app/templates/base.html", line 83, in top-level template code
    {% block content %}{% endblock %}
  File "/Users/guggarisathvik/groundnut_mill/app/templates/machinery/list.html", line 70, in block 'content'
    <form action="{{ url_for('machinery.delete_expense', id=m.id) }}" method="POST" style="display:inline;">
  File "/Users/guggarisathvik/groundnut_mill/.venv/lib/python3.9/site-packages/flask/app.py", line 1121, in url_for
    return self.handle_url_build_error(error, endpoint, values)
  File "/Users/guggarisathvik/groundnut_mill/.venv/lib/python3.9/site-packages/flask/app.py", line 1110, in url_for
    rv = url_adapter.build(  # type: ignore[union-attr]
  File "/Users/guggarisathvik/groundnut_mill/.venv/lib/python3.9/site-packages/werkzeug/routing/map.py", line 924, in build
    raise BuildError(endpoint, values, method, self)
werkzeug.routing.exceptions.BuildError: Could not build url for endpoint 'machinery.delete_expense' with values ['id']. Did you forget to specify values ['expense_id', 'machinery_id']?
2025-05-07 22:00:31,496 - app - ERROR - [__init__.py:50] - Unhandled exception: Could not build url for endpoint 'machinery.delete_expense' with values ['id']. Did you forget to specify values ['expense_id', 'machinery_id']?
Traceback (most recent call last):
  File "/Users/guggarisathvik/groundnut_mill/.venv/lib/python3.9/site-packages/flask/app.py", line 917, in full_dispatch_request
    rv = self.dispatch_request()
  File "/Users/guggarisathvik/groundnut_mill/.venv/lib/python3.9/site-packages/flask/app.py", line 902, in dispatch_request
    return self.ensure_sync(self.view_functions[rule.endpoint])(**view_args)  # type: ignore[no-any-return]
  File "/Users/guggarisathvik/groundnut_mill/.venv/lib/python3.9/site-packages/flask_login/utils.py", line 290, in decorated_view
    return current_app.ensure_sync(func)(*args, **kwargs)
  File "/Users/guggarisathvik/groundnut_mill/app/routes/machinery_routes.py", line 16, in list_machines
    return render_template("machinery/list.html", machines=machines)
  File "/Users/guggarisathvik/groundnut_mill/.venv/lib/python3.9/site-packages/flask/templating.py", line 150, in render_template
    return _render(app, template, context)
  File "/Users/guggarisathvik/groundnut_mill/.venv/lib/python3.9/site-packages/flask/templating.py", line 131, in _render
    rv = template.render(context)
  File "/Users/guggarisathvik/groundnut_mill/.venv/lib/python3.9/site-packages/jinja2/environment.py", line 1295, in render
    self.environment.handle_exception()
  File "/Users/guggarisathvik/groundnut_mill/.venv/lib/python3.9/site-packages/jinja2/environment.py", line 942, in handle_exception
    raise rewrite_traceback_stack(source=source)
  File "/Users/guggarisathvik/groundnut_mill/app/templates/machinery/list.html", line 1, in top-level template code
    {% extends "base.html" %}
  File "/Users/guggarisathvik/groundnut_mill/app/templates/base.html", line 83, in top-level template code
    {% block content %}{% endblock %}
  File "/Users/guggarisathvik/groundnut_mill/app/templates/machinery/list.html", line 70, in block 'content'
    <form action="{{ url_for('machinery.delete_expense', machindery_id=m.id) }}" method="POST" style="display:inline;">
  File "/Users/guggarisathvik/groundnut_mill/.venv/lib/python3.9/site-packages/flask/app.py", line 1121, in url_for
    return self.handle_url_build_error(error, endpoint, values)
  File "/Users/guggarisathvik/groundnut_mill/.venv/lib/python3.9/site-packages/flask/app.py", line 1110, in url_for
    rv = url_adapter.build(  # type: ignore[union-attr]
  File "/Users/guggarisathvik/groundnut_mill/.venv/lib/python3.9/site-packages/werkzeug/routing/map.py", line 924, in build
    raise BuildError(endpoint, values, method, self)
werkzeug.routing.exceptions.BuildError: Could not build url for endpoint 'machinery.delete_expense' with values ['id']. Did you forget to specify values ['expense_id', 'machinery_id']?
2025-05-07 22:00:39,159 - app - INFO - [machinery_routes.py:68] - Expense added for machinery ID 3
2025-05-07 22:00:39,194 - app - ERROR - [__init__.py:50] - Unhandled exception: Could not build url for endpoint 'machinery.delete_expense' with values ['id']. Did you forget to specify values ['expense_id', 'machinery_id']?
Traceback (most recent call last):
  File "/Users/guggarisathvik/groundnut_mill/.venv/lib/python3.9/site-packages/flask/app.py", line 917, in full_dispatch_request
    rv = self.dispatch_request()
  File "/Users/guggarisathvik/groundnut_mill/.venv/lib/python3.9/site-packages/flask/app.py", line 902, in dispatch_request
    return self.ensure_sync(self.view_functions[rule.endpoint])(**view_args)  # type: ignore[no-any-return]
  File "/Users/guggarisathvik/groundnut_mill/.venv/lib/python3.9/site-packages/flask_login/utils.py", line 290, in decorated_view
    return current_app.ensure_sync(func)(*args, **kwargs)
  File "/Users/guggarisathvik/groundnut_mill/app/routes/machinery_routes.py", line 16, in list_machines
    return render_template("machinery/list.html", machines=machines)
  File "/Users/guggarisathvik/groundnut_mill/.venv/lib/python3.9/site-packages/flask/templating.py", line 150, in render_template
    return _render(app, template, context)
  File "/Users/guggarisathvik/groundnut_mill/.venv/lib/python3.9/site-packages/flask/templating.py", line 131, in _render
    rv = template.render(context)
  File "/Users/guggarisathvik/groundnut_mill/.venv/lib/python3.9/site-packages/jinja2/environment.py", line 1295, in render
    self.environment.handle_exception()
  File "/Users/guggarisathvik/groundnut_mill/.venv/lib/python3.9/site-packages/jinja2/environment.py", line 942, in handle_exception
    raise rewrite_traceback_stack(source=source)
  File "/Users/guggarisathvik/groundnut_mill/app/templates/machinery/list.html", line 1, in top-level template code
    {% extends "base.html" %}
  File "/Users/guggarisathvik/groundnut_mill/app/templates/base.html", line 83, in top-level template code
    {% block content %}{% endblock %}
  File "/Users/guggarisathvik/groundnut_mill/app/templates/machinery/list.html", line 70, in block 'content'
    <form action="{{ url_for('machinery.delete_expense', machindery_id=m.id) }}" method="POST" style="display:inline;">
  File "/Users/guggarisathvik/groundnut_mill/.venv/lib/python3.9/site-packages/flask/app.py", line 1121, in url_for
    return self.handle_url_build_error(error, endpoint, values)
  File "/Users/guggarisathvik/groundnut_mill/.venv/lib/python3.9/site-packages/flask/app.py", line 1110, in url_for
    rv = url_adapter.build(  # type: ignore[union-attr]
  File "/Users/guggarisathvik/groundnut_mill/.venv/lib/python3.9/site-packages/werkzeug/routing/map.py", line 924, in build
    raise BuildError(endpoint, values, method, self)
werkzeug.routing.exceptions.BuildError: Could not build url for endpoint 'machinery.delete_expense' with values ['id']. Did you forget to specify values ['expense_id', 'machinery_id']?
2025-05-08 08:23:46,001 - app - ERROR - [__init__.py:50] - Unhandled exception: 404 Not Found: The requested URL was not found on the server. If you entered the URL manually please check your spelling and try again.
Traceback (most recent call last):
  File "/Users/guggarisathvik/groundnut_mill/.venv/lib/python3.9/site-packages/flask/app.py", line 917, in full_dispatch_request
    rv = self.dispatch_request()
  File "/Users/guggarisathvik/groundnut_mill/.venv/lib/python3.9/site-packages/flask/app.py", line 902, in dispatch_request
    return self.ensure_sync(self.view_functions[rule.endpoint])(**view_args)  # type: ignore[no-any-return]
  File "/Users/guggarisathvik/groundnut_mill/.venv/lib/python3.9/site-packages/flask/app.py", line 278, in <lambda>
    view_func=lambda **kw: self_ref().send_static_file(**kw),  # type: ignore # noqa: B950
  File "/Users/guggarisathvik/groundnut_mill/.venv/lib/python3.9/site-packages/flask/app.py", line 326, in send_static_file
    return send_from_directory(
  File "/Users/guggarisathvik/groundnut_mill/.venv/lib/python3.9/site-packages/flask/helpers.py", line 565, in send_from_directory
    return werkzeug.utils.send_from_directory(  # type: ignore[return-value]
  File "/Users/guggarisathvik/groundnut_mill/.venv/lib/python3.9/site-packages/werkzeug/utils.py", line 575, in send_from_directory
    raise NotFound()
werkzeug.exceptions.NotFound: 404 Not Found: The requested URL was not found on the server. If you entered the URL manually please check your spelling and try again.
2025-05-08 08:23:59,435 - flask-app - INFO - [__init__.py:25] - Starting Flask application...
2025-05-08 08:24:03,524 - app - ERROR - [__init__.py:50] - Unhandled exception: 404 Not Found: The requested URL was not found on the server. If you entered the URL manually please check your spelling and try again.
Traceback (most recent call last):
  File "/Users/guggarisathvik/groundnut_mill/.venv/lib/python3.9/site-packages/flask/app.py", line 917, in full_dispatch_request
    rv = self.dispatch_request()
  File "/Users/guggarisathvik/groundnut_mill/.venv/lib/python3.9/site-packages/flask/app.py", line 902, in dispatch_request
    return self.ensure_sync(self.view_functions[rule.endpoint])(**view_args)  # type: ignore[no-any-return]
  File "/Users/guggarisathvik/groundnut_mill/.venv/lib/python3.9/site-packages/flask/app.py", line 278, in <lambda>
    view_func=lambda **kw: self_ref().send_static_file(**kw),  # type: ignore # noqa: B950
  File "/Users/guggarisathvik/groundnut_mill/.venv/lib/python3.9/site-packages/flask/app.py", line 326, in send_static_file
    return send_from_directory(
  File "/Users/guggarisathvik/groundnut_mill/.venv/lib/python3.9/site-packages/flask/helpers.py", line 565, in send_from_directory
    return werkzeug.utils.send_from_directory(  # type: ignore[return-value]
  File "/Users/guggarisathvik/groundnut_mill/.venv/lib/python3.9/site-packages/werkzeug/utils.py", line 575, in send_from_directory
    raise NotFound()
werkzeug.exceptions.NotFound: 404 Not Found: The requested URL was not found on the server. If you entered the URL manually please check your spelling and try again.
2025-05-08 08:24:04,980 - app - ERROR - [__init__.py:50] - Unhandled exception: 404 Not Found: The requested URL was not found on the server. If you entered the URL manually please check your spelling and try again.
Traceback (most recent call last):
  File "/Users/guggarisathvik/groundnut_mill/.venv/lib/python3.9/site-packages/flask/app.py", line 917, in full_dispatch_request
    rv = self.dispatch_request()
  File "/Users/guggarisathvik/groundnut_mill/.venv/lib/python3.9/site-packages/flask/app.py", line 902, in dispatch_request
    return self.ensure_sync(self.view_functions[rule.endpoint])(**view_args)  # type: ignore[no-any-return]
  File "/Users/guggarisathvik/groundnut_mill/.venv/lib/python3.9/site-packages/flask/app.py", line 278, in <lambda>
    view_func=lambda **kw: self_ref().send_static_file(**kw),  # type: ignore # noqa: B950
  File "/Users/guggarisathvik/groundnut_mill/.venv/lib/python3.9/site-packages/flask/app.py", line 326, in send_static_file
    return send_from_directory(
  File "/Users/guggarisathvik/groundnut_mill/.venv/lib/python3.9/site-packages/flask/helpers.py", line 565, in send_from_directory
    return werkzeug.utils.send_from_directory(  # type: ignore[return-value]
  File "/Users/guggarisathvik/groundnut_mill/.venv/lib/python3.9/site-packages/werkzeug/utils.py", line 575, in send_from_directory
    raise NotFound()
werkzeug.exceptions.NotFound: 404 Not Found: The requested URL was not found on the server. If you entered the URL manually please check your spelling and try again.
2025-05-08 08:24:11,969 - app - ERROR - [__init__.py:50] - Unhandled exception: Could not build url for endpoint 'machinery.delete_expense' with values ['expense_id', 'machindery_id']. Did you forget to specify values ['machinery_id']?
Traceback (most recent call last):
  File "/Users/guggarisathvik/groundnut_mill/.venv/lib/python3.9/site-packages/flask/app.py", line 917, in full_dispatch_request
    rv = self.dispatch_request()
  File "/Users/guggarisathvik/groundnut_mill/.venv/lib/python3.9/site-packages/flask/app.py", line 902, in dispatch_request
    return self.ensure_sync(self.view_functions[rule.endpoint])(**view_args)  # type: ignore[no-any-return]
  File "/Users/guggarisathvik/groundnut_mill/.venv/lib/python3.9/site-packages/flask_login/utils.py", line 290, in decorated_view
    return current_app.ensure_sync(func)(*args, **kwargs)
  File "/Users/guggarisathvik/groundnut_mill/app/routes/machinery_routes.py", line 16, in list_machines
    return render_template("machinery/list.html", machines=machines)
  File "/Users/guggarisathvik/groundnut_mill/.venv/lib/python3.9/site-packages/flask/templating.py", line 150, in render_template
    return _render(app, template, context)
  File "/Users/guggarisathvik/groundnut_mill/.venv/lib/python3.9/site-packages/flask/templating.py", line 131, in _render
    rv = template.render(context)
  File "/Users/guggarisathvik/groundnut_mill/.venv/lib/python3.9/site-packages/jinja2/environment.py", line 1295, in render
    self.environment.handle_exception()
  File "/Users/guggarisathvik/groundnut_mill/.venv/lib/python3.9/site-packages/jinja2/environment.py", line 942, in handle_exception
    raise rewrite_traceback_stack(source=source)
  File "/Users/guggarisathvik/groundnut_mill/app/templates/machinery/list.html", line 1, in top-level template code
    {% extends "base.html" %}
  File "/Users/guggarisathvik/groundnut_mill/app/templates/base.html", line 83, in top-level template code
    {% block content %}{% endblock %}
  File "/Users/guggarisathvik/groundnut_mill/app/templates/machinery/list.html", line 70, in block 'content'
    <form action="{{ url_for('machinery.delete_expense', machindery_id=m.id, expense_id=e.id) }}" method="POST" style="display:inline;">
  File "/Users/guggarisathvik/groundnut_mill/.venv/lib/python3.9/site-packages/flask/app.py", line 1121, in url_for
    return self.handle_url_build_error(error, endpoint, values)
  File "/Users/guggarisathvik/groundnut_mill/.venv/lib/python3.9/site-packages/flask/app.py", line 1110, in url_for
    rv = url_adapter.build(  # type: ignore[union-attr]
  File "/Users/guggarisathvik/groundnut_mill/.venv/lib/python3.9/site-packages/werkzeug/routing/map.py", line 924, in build
    raise BuildError(endpoint, values, method, self)
werkzeug.routing.exceptions.BuildError: Could not build url for endpoint 'machinery.delete_expense' with values ['expense_id', 'machindery_id']. Did you forget to specify values ['machinery_id']?
2025-05-08 08:24:11,980 - app - ERROR - [__init__.py:50] - Unhandled exception: 404 Not Found: The requested URL was not found on the server. If you entered the URL manually please check your spelling and try again.
Traceback (most recent call last):
  File "/Users/guggarisathvik/groundnut_mill/.venv/lib/python3.9/site-packages/flask/app.py", line 917, in full_dispatch_request
    rv = self.dispatch_request()
  File "/Users/guggarisathvik/groundnut_mill/.venv/lib/python3.9/site-packages/flask/app.py", line 902, in dispatch_request
    return self.ensure_sync(self.view_functions[rule.endpoint])(**view_args)  # type: ignore[no-any-return]
  File "/Users/guggarisathvik/groundnut_mill/.venv/lib/python3.9/site-packages/flask/app.py", line 278, in <lambda>
    view_func=lambda **kw: self_ref().send_static_file(**kw),  # type: ignore # noqa: B950
  File "/Users/guggarisathvik/groundnut_mill/.venv/lib/python3.9/site-packages/flask/app.py", line 326, in send_static_file
    return send_from_directory(
  File "/Users/guggarisathvik/groundnut_mill/.venv/lib/python3.9/site-packages/flask/helpers.py", line 565, in send_from_directory
    return werkzeug.utils.send_from_directory(  # type: ignore[return-value]
  File "/Users/guggarisathvik/groundnut_mill/.venv/lib/python3.9/site-packages/werkzeug/utils.py", line 575, in send_from_directory
    raise NotFound()
werkzeug.exceptions.NotFound: 404 Not Found: The requested URL was not found on the server. If you entered the URL manually please check your spelling and try again.
2025-05-08 08:24:14,622 - app - ERROR - [__init__.py:50] - Unhandled exception: Could not build url for endpoint 'machinery.delete_expense' with values ['expense_id', 'machindery_id']. Did you forget to specify values ['machinery_id']?
Traceback (most recent call last):
  File "/Users/guggarisathvik/groundnut_mill/.venv/lib/python3.9/site-packages/flask/app.py", line 917, in full_dispatch_request
    rv = self.dispatch_request()
  File "/Users/guggarisathvik/groundnut_mill/.venv/lib/python3.9/site-packages/flask/app.py", line 902, in dispatch_request
    return self.ensure_sync(self.view_functions[rule.endpoint])(**view_args)  # type: ignore[no-any-return]
  File "/Users/guggarisathvik/groundnut_mill/.venv/lib/python3.9/site-packages/flask_login/utils.py", line 290, in decorated_view
    return current_app.ensure_sync(func)(*args, **kwargs)
  File "/Users/guggarisathvik/groundnut_mill/app/routes/machinery_routes.py", line 16, in list_machines
    return render_template("machinery/list.html", machines=machines)
  File "/Users/guggarisathvik/groundnut_mill/.venv/lib/python3.9/site-packages/flask/templating.py", line 150, in render_template
    return _render(app, template, context)
  File "/Users/guggarisathvik/groundnut_mill/.venv/lib/python3.9/site-packages/flask/templating.py", line 131, in _render
    rv = template.render(context)
  File "/Users/guggarisathvik/groundnut_mill/.venv/lib/python3.9/site-packages/jinja2/environment.py", line 1295, in render
    self.environment.handle_exception()
  File "/Users/guggarisathvik/groundnut_mill/.venv/lib/python3.9/site-packages/jinja2/environment.py", line 942, in handle_exception
    raise rewrite_traceback_stack(source=source)
  File "/Users/guggarisathvik/groundnut_mill/app/templates/machinery/list.html", line 1, in top-level template code
    {% extends "base.html" %}
  File "/Users/guggarisathvik/groundnut_mill/app/templates/base.html", line 83, in top-level template code
    {% block content %}{% endblock %}
  File "/Users/guggarisathvik/groundnut_mill/app/templates/machinery/list.html", line 70, in block 'content'
    <form action="{{ url_for('machinery.delete_expense', machindery_id=m.id, expense_id=e.id) }}" method="POST" style="display:inline;">
  File "/Users/guggarisathvik/groundnut_mill/.venv/lib/python3.9/site-packages/flask/app.py", line 1121, in url_for
    return self.handle_url_build_error(error, endpoint, values)
  File "/Users/guggarisathvik/groundnut_mill/.venv/lib/python3.9/site-packages/flask/app.py", line 1110, in url_for
    rv = url_adapter.build(  # type: ignore[union-attr]
  File "/Users/guggarisathvik/groundnut_mill/.venv/lib/python3.9/site-packages/werkzeug/routing/map.py", line 924, in build
    raise BuildError(endpoint, values, method, self)
werkzeug.routing.exceptions.BuildError: Could not build url for endpoint 'machinery.delete_expense' with values ['expense_id', 'machindery_id']. Did you forget to specify values ['machinery_id']?
2025-05-08 08:24:14,628 - app - ERROR - [__init__.py:50] - Unhandled exception: 404 Not Found: The requested URL was not found on the server. If you entered the URL manually please check your spelling and try again.
Traceback (most recent call last):
  File "/Users/guggarisathvik/groundnut_mill/.venv/lib/python3.9/site-packages/flask/app.py", line 917, in full_dispatch_request
    rv = self.dispatch_request()
  File "/Users/guggarisathvik/groundnut_mill/.venv/lib/python3.9/site-packages/flask/app.py", line 902, in dispatch_request
    return self.ensure_sync(self.view_functions[rule.endpoint])(**view_args)  # type: ignore[no-any-return]
  File "/Users/guggarisathvik/groundnut_mill/.venv/lib/python3.9/site-packages/flask/app.py", line 278, in <lambda>
    view_func=lambda **kw: self_ref().send_static_file(**kw),  # type: ignore # noqa: B950
  File "/Users/guggarisathvik/groundnut_mill/.venv/lib/python3.9/site-packages/flask/app.py", line 326, in send_static_file
    return send_from_directory(
  File "/Users/guggarisathvik/groundnut_mill/.venv/lib/python3.9/site-packages/flask/helpers.py", line 565, in send_from_directory
    return werkzeug.utils.send_from_directory(  # type: ignore[return-value]
  File "/Users/guggarisathvik/groundnut_mill/.venv/lib/python3.9/site-packages/werkzeug/utils.py", line 575, in send_from_directory
    raise NotFound()
werkzeug.exceptions.NotFound: 404 Not Found: The requested URL was not found on the server. If you entered the URL manually please check your spelling and try again.
2025-05-08 08:29:34,822 - flask-app - INFO - [__init__.py:25] - Starting Flask application...
2025-05-08 08:29:41,906 - app - ERROR - [__init__.py:50] - Unhandled exception: 404 Not Found: The requested URL was not found on the server. If you entered the URL manually please check your spelling and try again.
Traceback (most recent call last):
  File "/Users/guggarisathvik/groundnut_mill/.venv/lib/python3.9/site-packages/flask/app.py", line 917, in full_dispatch_request
    rv = self.dispatch_request()
  File "/Users/guggarisathvik/groundnut_mill/.venv/lib/python3.9/site-packages/flask/app.py", line 902, in dispatch_request
    return self.ensure_sync(self.view_functions[rule.endpoint])(**view_args)  # type: ignore[no-any-return]
  File "/Users/guggarisathvik/groundnut_mill/.venv/lib/python3.9/site-packages/flask/app.py", line 278, in <lambda>
    view_func=lambda **kw: self_ref().send_static_file(**kw),  # type: ignore # noqa: B950
  File "/Users/guggarisathvik/groundnut_mill/.venv/lib/python3.9/site-packages/flask/app.py", line 326, in send_static_file
    return send_from_directory(
  File "/Users/guggarisathvik/groundnut_mill/.venv/lib/python3.9/site-packages/flask/helpers.py", line 565, in send_from_directory
    return werkzeug.utils.send_from_directory(  # type: ignore[return-value]
  File "/Users/guggarisathvik/groundnut_mill/.venv/lib/python3.9/site-packages/werkzeug/utils.py", line 575, in send_from_directory
    raise NotFound()
werkzeug.exceptions.NotFound: 404 Not Found: The requested URL was not found on the server. If you entered the URL manually please check your spelling and try again.
2025-05-08 08:35:52,542 - flask-app - INFO - [__init__.py:25] - Starting Flask application...
2025-05-08 08:35:59,586 - app - ERROR - [__init__.py:50] - Unhandled exception: 404 Not Found: The requested URL was not found on the server. If you entered the URL manually please check your spelling and try again.
Traceback (most recent call last):
  File "/Users/guggarisathvik/groundnut_mill/.venv/lib/python3.9/site-packages/flask/app.py", line 917, in full_dispatch_request
    rv = self.dispatch_request()
  File "/Users/guggarisathvik/groundnut_mill/.venv/lib/python3.9/site-packages/flask/app.py", line 902, in dispatch_request
    return self.ensure_sync(self.view_functions[rule.endpoint])(**view_args)  # type: ignore[no-any-return]
  File "/Users/guggarisathvik/groundnut_mill/.venv/lib/python3.9/site-packages/flask/app.py", line 278, in <lambda>
    view_func=lambda **kw: self_ref().send_static_file(**kw),  # type: ignore # noqa: B950
  File "/Users/guggarisathvik/groundnut_mill/.venv/lib/python3.9/site-packages/flask/app.py", line 326, in send_static_file
    return send_from_directory(
  File "/Users/guggarisathvik/groundnut_mill/.venv/lib/python3.9/site-packages/flask/helpers.py", line 565, in send_from_directory
    return werkzeug.utils.send_from_directory(  # type: ignore[return-value]
  File "/Users/guggarisathvik/groundnut_mill/.venv/lib/python3.9/site-packages/werkzeug/utils.py", line 575, in send_from_directory
    raise NotFound()
werkzeug.exceptions.NotFound: 404 Not Found: The requested URL was not found on the server. If you entered the URL manually please check your spelling and try again.
2025-05-08 09:06:07,346 - app - ERROR - [__init__.py:50] - Unhandled exception: 404 Not Found: The requested URL was not found on the server. If you entered the URL manually please check your spelling and try again.
Traceback (most recent call last):
  File "/Users/guggarisathvik/groundnut_mill/.venv/lib/python3.9/site-packages/flask/app.py", line 917, in full_dispatch_request
    rv = self.dispatch_request()
  File "/Users/guggarisathvik/groundnut_mill/.venv/lib/python3.9/site-packages/flask/app.py", line 902, in dispatch_request
    return self.ensure_sync(self.view_functions[rule.endpoint])(**view_args)  # type: ignore[no-any-return]
  File "/Users/guggarisathvik/groundnut_mill/.venv/lib/python3.9/site-packages/flask/app.py", line 278, in <lambda>
    view_func=lambda **kw: self_ref().send_static_file(**kw),  # type: ignore # noqa: B950
  File "/Users/guggarisathvik/groundnut_mill/.venv/lib/python3.9/site-packages/flask/app.py", line 326, in send_static_file
    return send_from_directory(
  File "/Users/guggarisathvik/groundnut_mill/.venv/lib/python3.9/site-packages/flask/helpers.py", line 565, in send_from_directory
    return werkzeug.utils.send_from_directory(  # type: ignore[return-value]
  File "/Users/guggarisathvik/groundnut_mill/.venv/lib/python3.9/site-packages/werkzeug/utils.py", line 575, in send_from_directory
    raise NotFound()
werkzeug.exceptions.NotFound: 404 Not Found: The requested URL was not found on the server. If you entered the URL manually please check your spelling and try again.
2025-05-08 09:06:12,962 - app - ERROR - [__init__.py:50] - Unhandled exception: machinery/expense_list.html
Traceback (most recent call last):
  File "/Users/guggarisathvik/groundnut_mill/.venv/lib/python3.9/site-packages/flask/app.py", line 917, in full_dispatch_request
    rv = self.dispatch_request()
  File "/Users/guggarisathvik/groundnut_mill/.venv/lib/python3.9/site-packages/flask/app.py", line 902, in dispatch_request
    return self.ensure_sync(self.view_functions[rule.endpoint])(**view_args)  # type: ignore[no-any-return]
  File "/Users/guggarisathvik/groundnut_mill/.venv/lib/python3.9/site-packages/flask_login/utils.py", line 290, in decorated_view
    return current_app.ensure_sync(func)(*args, **kwargs)
  File "/Users/guggarisathvik/groundnut_mill/app/routes/machinery_routes.py", line 195, in list_expenses
    return render_template("machinery/expense_list.html", machine=machine, expenses=expenses)
  File "/Users/guggarisathvik/groundnut_mill/.venv/lib/python3.9/site-packages/flask/templating.py", line 149, in render_template
    template = app.jinja_env.get_or_select_template(template_name_or_list)
  File "/Users/guggarisathvik/groundnut_mill/.venv/lib/python3.9/site-packages/jinja2/environment.py", line 1087, in get_or_select_template
    return self.get_template(template_name_or_list, parent, globals)
  File "/Users/guggarisathvik/groundnut_mill/.venv/lib/python3.9/site-packages/jinja2/environment.py", line 1016, in get_template
    return self._load_template(name, globals)
  File "/Users/guggarisathvik/groundnut_mill/.venv/lib/python3.9/site-packages/jinja2/environment.py", line 975, in _load_template
    template = self.loader.load(self, name, self.make_globals(globals))
  File "/Users/guggarisathvik/groundnut_mill/.venv/lib/python3.9/site-packages/jinja2/loaders.py", line 126, in load
    source, filename, uptodate = self.get_source(environment, name)
  File "/Users/guggarisathvik/groundnut_mill/.venv/lib/python3.9/site-packages/flask/templating.py", line 65, in get_source
    return self._get_source_fast(environment, template)
  File "/Users/guggarisathvik/groundnut_mill/.venv/lib/python3.9/site-packages/flask/templating.py", line 99, in _get_source_fast
    raise TemplateNotFound(template)
jinja2.exceptions.TemplateNotFound: machinery/expense_list.html
2025-05-08 09:07:20,719 - flask-app - INFO - [__init__.py:25] - Starting Flask application...
2025-05-08 09:07:36,022 - app - ERROR - [__init__.py:50] - Unhandled exception: 404 Not Found: The requested URL was not found on the server. If you entered the URL manually please check your spelling and try again.
Traceback (most recent call last):
  File "/Users/guggarisathvik/groundnut_mill/.venv/lib/python3.9/site-packages/flask/app.py", line 917, in full_dispatch_request
    rv = self.dispatch_request()
  File "/Users/guggarisathvik/groundnut_mill/.venv/lib/python3.9/site-packages/flask/app.py", line 902, in dispatch_request
    return self.ensure_sync(self.view_functions[rule.endpoint])(**view_args)  # type: ignore[no-any-return]
  File "/Users/guggarisathvik/groundnut_mill/.venv/lib/python3.9/site-packages/flask/app.py", line 278, in <lambda>
    view_func=lambda **kw: self_ref().send_static_file(**kw),  # type: ignore # noqa: B950
  File "/Users/guggarisathvik/groundnut_mill/.venv/lib/python3.9/site-packages/flask/app.py", line 326, in send_static_file
    return send_from_directory(
  File "/Users/guggarisathvik/groundnut_mill/.venv/lib/python3.9/site-packages/flask/helpers.py", line 565, in send_from_directory
    return werkzeug.utils.send_from_directory(  # type: ignore[return-value]
  File "/Users/guggarisathvik/groundnut_mill/.venv/lib/python3.9/site-packages/werkzeug/utils.py", line 575, in send_from_directory
    raise NotFound()
werkzeug.exceptions.NotFound: 404 Not Found: The requested URL was not found on the server. If you entered the URL manually please check your spelling and try again.
2025-05-08 09:10:08,228 - app - INFO - [machinery_routes.py:68] - Expense added for machinery ID 3
2025-05-08 09:10:47,088 - app - ERROR - [__init__.py:50] - Unhandled exception: 404 Not Found: The requested URL was not found on the server. If you entered the URL manually please check your spelling and try again.
Traceback (most recent call last):
  File "/Users/guggarisathvik/groundnut_mill/.venv/lib/python3.9/site-packages/flask/app.py", line 917, in full_dispatch_request
    rv = self.dispatch_request()
  File "/Users/guggarisathvik/groundnut_mill/.venv/lib/python3.9/site-packages/flask/app.py", line 902, in dispatch_request
    return self.ensure_sync(self.view_functions[rule.endpoint])(**view_args)  # type: ignore[no-any-return]
  File "/Users/guggarisathvik/groundnut_mill/.venv/lib/python3.9/site-packages/flask/app.py", line 278, in <lambda>
    view_func=lambda **kw: self_ref().send_static_file(**kw),  # type: ignore # noqa: B950
  File "/Users/guggarisathvik/groundnut_mill/.venv/lib/python3.9/site-packages/flask/app.py", line 326, in send_static_file
    return send_from_directory(
  File "/Users/guggarisathvik/groundnut_mill/.venv/lib/python3.9/site-packages/flask/helpers.py", line 565, in send_from_directory
    return werkzeug.utils.send_from_directory(  # type: ignore[return-value]
  File "/Users/guggarisathvik/groundnut_mill/.venv/lib/python3.9/site-packages/werkzeug/utils.py", line 575, in send_from_directory
    raise NotFound()
werkzeug.exceptions.NotFound: 404 Not Found: The requested URL was not found on the server. If you entered the URL manually please check your spelling and try again.
2025-05-08 09:12:58,288 - flask-app - INFO - [__init__.py:25] - Starting Flask application...
2025-05-08 09:13:14,039 - app - INFO - [machinery_routes.py:68] - Expense added for machinery ID 3
2025-05-08 09:13:22,469 - app - ERROR - [__init__.py:50] - Unhandled exception: 'Machinery' object is not iterable
Traceback (most recent call last):
  File "/Users/guggarisathvik/groundnut_mill/.venv/lib/python3.9/site-packages/flask/app.py", line 917, in full_dispatch_request
    rv = self.dispatch_request()
  File "/Users/guggarisathvik/groundnut_mill/.venv/lib/python3.9/site-packages/flask/app.py", line 902, in dispatch_request
    return self.ensure_sync(self.view_functions[rule.endpoint])(**view_args)  # type: ignore[no-any-return]
  File "/Users/guggarisathvik/groundnut_mill/.venv/lib/python3.9/site-packages/flask_login/utils.py", line 290, in decorated_view
    return current_app.ensure_sync(func)(*args, **kwargs)
  File "/Users/guggarisathvik/groundnut_mill/app/routes/machinery_routes.py", line 195, in list_expenses
    return render_template("machinery/list.html", machines=machines)
  File "/Users/guggarisathvik/groundnut_mill/.venv/lib/python3.9/site-packages/flask/templating.py", line 150, in render_template
    return _render(app, template, context)
  File "/Users/guggarisathvik/groundnut_mill/.venv/lib/python3.9/site-packages/flask/templating.py", line 131, in _render
    rv = template.render(context)
  File "/Users/guggarisathvik/groundnut_mill/.venv/lib/python3.9/site-packages/jinja2/environment.py", line 1295, in render
    self.environment.handle_exception()
  File "/Users/guggarisathvik/groundnut_mill/.venv/lib/python3.9/site-packages/jinja2/environment.py", line 942, in handle_exception
    raise rewrite_traceback_stack(source=source)
  File "/Users/guggarisathvik/groundnut_mill/app/templates/machinery/list.html", line 1, in top-level template code
    {% extends "base.html" %}
  File "/Users/guggarisathvik/groundnut_mill/app/templates/base.html", line 83, in top-level template code
    {% block content %}{% endblock %}
  File "/Users/guggarisathvik/groundnut_mill/app/templates/machinery/list.html", line 14, in block 'content'
    {% for m in machines %}
TypeError: 'Machinery' object is not iterable
2025-05-08 09:20:43,197 - flask-app - INFO - [__init__.py:25] - Starting Flask application...
2025-05-08 09:21:15,116 - app - INFO - [machinery_routes.py:68] - Expense added for machinery ID 3
2025-05-08 09:21:42,100 - app - ERROR - [__init__.py:50] - Unhandled exception: 404 Not Found: The requested URL was not found on the server. If you entered the URL manually please check your spelling and try again.
Traceback (most recent call last):
  File "/Users/guggarisathvik/groundnut_mill/.venv/lib/python3.9/site-packages/flask/app.py", line 917, in full_dispatch_request
    rv = self.dispatch_request()
  File "/Users/guggarisathvik/groundnut_mill/.venv/lib/python3.9/site-packages/flask/app.py", line 902, in dispatch_request
    return self.ensure_sync(self.view_functions[rule.endpoint])(**view_args)  # type: ignore[no-any-return]
  File "/Users/guggarisathvik/groundnut_mill/.venv/lib/python3.9/site-packages/flask/app.py", line 278, in <lambda>
    view_func=lambda **kw: self_ref().send_static_file(**kw),  # type: ignore # noqa: B950
  File "/Users/guggarisathvik/groundnut_mill/.venv/lib/python3.9/site-packages/flask/app.py", line 326, in send_static_file
    return send_from_directory(
  File "/Users/guggarisathvik/groundnut_mill/.venv/lib/python3.9/site-packages/flask/helpers.py", line 565, in send_from_directory
    return werkzeug.utils.send_from_directory(  # type: ignore[return-value]
  File "/Users/guggarisathvik/groundnut_mill/.venv/lib/python3.9/site-packages/werkzeug/utils.py", line 575, in send_from_directory
    raise NotFound()
werkzeug.exceptions.NotFound: 404 Not Found: The requested URL was not found on the server. If you entered the URL manually please check your spelling and try again.
2025-05-08 09:21:42,788 - app - ERROR - [__init__.py:50] - Unhandled exception: 404 Not Found: The requested URL was not found on the server. If you entered the URL manually please check your spelling and try again.
Traceback (most recent call last):
  File "/Users/guggarisathvik/groundnut_mill/.venv/lib/python3.9/site-packages/flask/app.py", line 917, in full_dispatch_request
    rv = self.dispatch_request()
  File "/Users/guggarisathvik/groundnut_mill/.venv/lib/python3.9/site-packages/flask/app.py", line 902, in dispatch_request
    return self.ensure_sync(self.view_functions[rule.endpoint])(**view_args)  # type: ignore[no-any-return]
  File "/Users/guggarisathvik/groundnut_mill/.venv/lib/python3.9/site-packages/flask/app.py", line 278, in <lambda>
    view_func=lambda **kw: self_ref().send_static_file(**kw),  # type: ignore # noqa: B950
  File "/Users/guggarisathvik/groundnut_mill/.venv/lib/python3.9/site-packages/flask/app.py", line 326, in send_static_file
    return send_from_directory(
  File "/Users/guggarisathvik/groundnut_mill/.venv/lib/python3.9/site-packages/flask/helpers.py", line 565, in send_from_directory
    return werkzeug.utils.send_from_directory(  # type: ignore[return-value]
  File "/Users/guggarisathvik/groundnut_mill/.venv/lib/python3.9/site-packages/werkzeug/utils.py", line 575, in send_from_directory
    raise NotFound()
werkzeug.exceptions.NotFound: 404 Not Found: The requested URL was not found on the server. If you entered the URL manually please check your spelling and try again.
2025-05-08 09:21:45,058 - app - ERROR - [__init__.py:50] - Unhandled exception: 404 Not Found: The requested URL was not found on the server. If you entered the URL manually please check your spelling and try again.
Traceback (most recent call last):
  File "/Users/guggarisathvik/groundnut_mill/.venv/lib/python3.9/site-packages/flask/app.py", line 917, in full_dispatch_request
    rv = self.dispatch_request()
  File "/Users/guggarisathvik/groundnut_mill/.venv/lib/python3.9/site-packages/flask/app.py", line 902, in dispatch_request
    return self.ensure_sync(self.view_functions[rule.endpoint])(**view_args)  # type: ignore[no-any-return]
  File "/Users/guggarisathvik/groundnut_mill/.venv/lib/python3.9/site-packages/flask/app.py", line 278, in <lambda>
    view_func=lambda **kw: self_ref().send_static_file(**kw),  # type: ignore # noqa: B950
  File "/Users/guggarisathvik/groundnut_mill/.venv/lib/python3.9/site-packages/flask/app.py", line 326, in send_static_file
    return send_from_directory(
  File "/Users/guggarisathvik/groundnut_mill/.venv/lib/python3.9/site-packages/flask/helpers.py", line 565, in send_from_directory
    return werkzeug.utils.send_from_directory(  # type: ignore[return-value]
  File "/Users/guggarisathvik/groundnut_mill/.venv/lib/python3.9/site-packages/werkzeug/utils.py", line 575, in send_from_directory
    raise NotFound()
werkzeug.exceptions.NotFound: 404 Not Found: The requested URL was not found on the server. If you entered the URL manually please check your spelling and try again.
2025-05-08 09:27:23,739 - app - ERROR - [__init__.py:50] - Unhandled exception: 404 Not Found: The requested URL was not found on the server. If you entered the URL manually please check your spelling and try again.
Traceback (most recent call last):
  File "/Users/guggarisathvik/groundnut_mill/.venv/lib/python3.9/site-packages/flask/app.py", line 917, in full_dispatch_request
    rv = self.dispatch_request()
  File "/Users/guggarisathvik/groundnut_mill/.venv/lib/python3.9/site-packages/flask/app.py", line 902, in dispatch_request
    return self.ensure_sync(self.view_functions[rule.endpoint])(**view_args)  # type: ignore[no-any-return]
  File "/Users/guggarisathvik/groundnut_mill/.venv/lib/python3.9/site-packages/flask/app.py", line 278, in <lambda>
    view_func=lambda **kw: self_ref().send_static_file(**kw),  # type: ignore # noqa: B950
  File "/Users/guggarisathvik/groundnut_mill/.venv/lib/python3.9/site-packages/flask/app.py", line 326, in send_static_file
    return send_from_directory(
  File "/Users/guggarisathvik/groundnut_mill/.venv/lib/python3.9/site-packages/flask/helpers.py", line 565, in send_from_directory
    return werkzeug.utils.send_from_directory(  # type: ignore[return-value]
  File "/Users/guggarisathvik/groundnut_mill/.venv/lib/python3.9/site-packages/werkzeug/utils.py", line 575, in send_from_directory
    raise NotFound()
werkzeug.exceptions.NotFound: 404 Not Found: The requested URL was not found on the server. If you entered the URL manually please check your spelling and try again.
2025-05-08 09:27:46,072 - app - ERROR - [__init__.py:50] - Unhandled exception: 404 Not Found: The requested URL was not found on the server. If you entered the URL manually please check your spelling and try again.
Traceback (most recent call last):
  File "/Users/guggarisathvik/groundnut_mill/.venv/lib/python3.9/site-packages/flask/app.py", line 917, in full_dispatch_request
    rv = self.dispatch_request()
  File "/Users/guggarisathvik/groundnut_mill/.venv/lib/python3.9/site-packages/flask/app.py", line 902, in dispatch_request
    return self.ensure_sync(self.view_functions[rule.endpoint])(**view_args)  # type: ignore[no-any-return]
  File "/Users/guggarisathvik/groundnut_mill/.venv/lib/python3.9/site-packages/flask/app.py", line 278, in <lambda>
    view_func=lambda **kw: self_ref().send_static_file(**kw),  # type: ignore # noqa: B950
  File "/Users/guggarisathvik/groundnut_mill/.venv/lib/python3.9/site-packages/flask/app.py", line 326, in send_static_file
    return send_from_directory(
  File "/Users/guggarisathvik/groundnut_mill/.venv/lib/python3.9/site-packages/flask/helpers.py", line 565, in send_from_directory
    return werkzeug.utils.send_from_directory(  # type: ignore[return-value]
  File "/Users/guggarisathvik/groundnut_mill/.venv/lib/python3.9/site-packages/werkzeug/utils.py", line 575, in send_from_directory
    raise NotFound()
werkzeug.exceptions.NotFound: 404 Not Found: The requested URL was not found on the server. If you entered the URL manually please check your spelling and try again.
2025-05-08 09:28:17,463 - app - ERROR - [__init__.py:50] - Unhandled exception: 404 Not Found: The requested URL was not found on the server. If you entered the URL manually please check your spelling and try again.
Traceback (most recent call last):
  File "/Users/guggarisathvik/groundnut_mill/.venv/lib/python3.9/site-packages/flask/app.py", line 917, in full_dispatch_request
    rv = self.dispatch_request()
  File "/Users/guggarisathvik/groundnut_mill/.venv/lib/python3.9/site-packages/flask/app.py", line 902, in dispatch_request
    return self.ensure_sync(self.view_functions[rule.endpoint])(**view_args)  # type: ignore[no-any-return]
  File "/Users/guggarisathvik/groundnut_mill/.venv/lib/python3.9/site-packages/flask/app.py", line 278, in <lambda>
    view_func=lambda **kw: self_ref().send_static_file(**kw),  # type: ignore # noqa: B950
  File "/Users/guggarisathvik/groundnut_mill/.venv/lib/python3.9/site-packages/flask/app.py", line 326, in send_static_file
    return send_from_directory(
  File "/Users/guggarisathvik/groundnut_mill/.venv/lib/python3.9/site-packages/flask/helpers.py", line 565, in send_from_directory
    return werkzeug.utils.send_from_directory(  # type: ignore[return-value]
  File "/Users/guggarisathvik/groundnut_mill/.venv/lib/python3.9/site-packages/werkzeug/utils.py", line 575, in send_from_directory
    raise NotFound()
werkzeug.exceptions.NotFound: 404 Not Found: The requested URL was not found on the server. If you entered the URL manually please check your spelling and try again.
2025-05-08 09:28:21,040 - app - ERROR - [__init__.py:50] - Unhandled exception: 404 Not Found: The requested URL was not found on the server. If you entered the URL manually please check your spelling and try again.
Traceback (most recent call last):
  File "/Users/guggarisathvik/groundnut_mill/.venv/lib/python3.9/site-packages/flask/app.py", line 917, in full_dispatch_request
    rv = self.dispatch_request()
  File "/Users/guggarisathvik/groundnut_mill/.venv/lib/python3.9/site-packages/flask/app.py", line 902, in dispatch_request
    return self.ensure_sync(self.view_functions[rule.endpoint])(**view_args)  # type: ignore[no-any-return]
  File "/Users/guggarisathvik/groundnut_mill/.venv/lib/python3.9/site-packages/flask/app.py", line 278, in <lambda>
    view_func=lambda **kw: self_ref().send_static_file(**kw),  # type: ignore # noqa: B950
  File "/Users/guggarisathvik/groundnut_mill/.venv/lib/python3.9/site-packages/flask/app.py", line 326, in send_static_file
    return send_from_directory(
  File "/Users/guggarisathvik/groundnut_mill/.venv/lib/python3.9/site-packages/flask/helpers.py", line 565, in send_from_directory
    return werkzeug.utils.send_from_directory(  # type: ignore[return-value]
  File "/Users/guggarisathvik/groundnut_mill/.venv/lib/python3.9/site-packages/werkzeug/utils.py", line 575, in send_from_directory
    raise NotFound()
werkzeug.exceptions.NotFound: 404 Not Found: The requested URL was not found on the server. If you entered the URL manually please check your spelling and try again.
2025-05-08 09:28:42,810 - app - ERROR - [__init__.py:50] - Unhandled exception: 404 Not Found: The requested URL was not found on the server. If you entered the URL manually please check your spelling and try again.
Traceback (most recent call last):
  File "/Users/guggarisathvik/groundnut_mill/.venv/lib/python3.9/site-packages/flask/app.py", line 917, in full_dispatch_request
    rv = self.dispatch_request()
  File "/Users/guggarisathvik/groundnut_mill/.venv/lib/python3.9/site-packages/flask/app.py", line 902, in dispatch_request
    return self.ensure_sync(self.view_functions[rule.endpoint])(**view_args)  # type: ignore[no-any-return]
  File "/Users/guggarisathvik/groundnut_mill/.venv/lib/python3.9/site-packages/flask/app.py", line 278, in <lambda>
    view_func=lambda **kw: self_ref().send_static_file(**kw),  # type: ignore # noqa: B950
  File "/Users/guggarisathvik/groundnut_mill/.venv/lib/python3.9/site-packages/flask/app.py", line 326, in send_static_file
    return send_from_directory(
  File "/Users/guggarisathvik/groundnut_mill/.venv/lib/python3.9/site-packages/flask/helpers.py", line 565, in send_from_directory
    return werkzeug.utils.send_from_directory(  # type: ignore[return-value]
  File "/Users/guggarisathvik/groundnut_mill/.venv/lib/python3.9/site-packages/werkzeug/utils.py", line 575, in send_from_directory
    raise NotFound()
werkzeug.exceptions.NotFound: 404 Not Found: The requested URL was not found on the server. If you entered the URL manually please check your spelling and try again.
